Workbook
Name ＳＥ: リスト!$R$2:$R$15
Name ＳＥ_蟹: リスト!$R$2:$R$16
Name ＳＰＥ: リスト!$AR$2:$AR$24
Name SPE_蟹: リスト!$AR$1:$AR$25
Name カルマ: リスト!$AH$2:$AH$58
Name カルマ_蟹: リスト!$AI$2:$AI$63
Name 技系統: リスト!$N$12:$N$21
Name 技系統_蟹: リスト!$O$12:$O$23
Name 攻撃スタイル: リスト!$C$3:$C$5
Name 身体タイプ: リスト!$F$2:$F$8
Name 身体タイプ_蟹: リスト!$G$2:$G$9
Name 能力タイプ: リスト!$A$3:$A$8
Name 能力分類: リスト!$A$3:$A$8
Name 付加効果: リスト!$P$2:$P$47
Name 付加効果_蟹: リスト!$Q$2:$Q$64

Sheet リスト
A1: 能力タイプ | C1: 活性タイプ | D1: 活性 | F1: 身体タイプ | G1: 身体タイプ_蟹 | H1: 所属 | K1: 判定ダイス | N1: 発動系統 | P1: 付加効果 | Q1: 付加効果_蟹 | R1: ＳＥ | Z1: 特殊武装 | AA1: スペック | AD1: ライフ＆ライフ | AF1: スタンス＆トゥルー | AH1: カルマ | AI1: カルマ_蟹 | AK1: 崩壊症状 | AM1: 消費アイテム | AR1: ＳＰＥ | AS1: 使用回数 | AU1: カルマ | AV1: 使用回数 | AW1: 使用回数（蟹）
A2: － | C2: － | D2: － | F2: － | G2: － | H2: － | K2: １Ｄ６ | N2: － | P2: － | Q2: － | R2: － | T2: － | V2: 0 | X2: － | Z2: － | AD2: － | AF2: － | AH2: － | AI2: － | AK2: － | AM2: － | AQ2: － | AR2: － | AS2: 0 | AU2: － | AV2: 0 | AW2: 0
A3: ノーマル | C3: 覚醒型 | D3: ＋１ | F3: ナチュラル | G3: ナチュラル | H3: 司法機関グングニル | K3: ２Ｄ６ | N3: 攻撃発動 | P3: 強化【行】 | Q3: 強化【行】 | R3: トラップ | T3: 攻撃型 | V3: 1 | X3: 力技 | Z3: アタッチメント／S0 | AA3: 0 | AD3: 異形 | AF3: 正義 | AH3: 昇華者【リバーサー】 | AI3: 昇華者【リバーサー】 | AK3: 聴覚崩壊 | AM3: マグタフ／1Rd | AQ3: 行為発動 | AR3: 奇跡 | AS3: 1 | AU3: 昇華者【リバーサー】 | AV3: 1 | AW3: 1
A4: サイキッカー | C4: 増強型 | D4: ＋２ | F4: コーディネーター | G4: コーディネーター | H4: 民主機構オルレアン | K4: ３Ｄ６ | N4: 精神発動 | P4: 強化【攻】 | Q4: 強化【攻】 | R4: チャージ | T4: 速度型 | V4: 2 | Z4: ロケットランチャー／S4 | AA4: 4 | AD4: 暴走 | AF4: 中庸 | AH4: 駆け出し【ルーキー】 | AI4: 駆け出し【ルーキー】 | AK4: 視覚崩壊 | AM4: マグタフＥＸ／1Rd | AQ4: チェイン発動 | AR4: 悪運 | AS4: 1 | AU4: 駆け出し【ルーキー】 | AV4: 1 | AW4: 1
A5: エスパー | C5: 反応型 | D5: ＋３ | F5: サイボーグ | G5: サイボーグ | H5: 抑制機構テセウス | N5: 防御発動 | P5: 強化【防】 | Q5: 強化【防】 | R5: ドレイン | T5: 探索型 | V5: 3 | X5: － | Z5: パイルバンカー／S3 | AA5: 3 | AD5: 崩壊 | AF5: 悪徳 | AH5: 新鋭【ニューフェイス】 | AI5: 新鋭【ニューフェイス】 | AK5: 言語崩壊 | AM5: マグタフＺ／2Rd | AQ5: キャラ特性 | AR5: 闘志 | AS5: 1 | AU5: 新鋭【ニューフェイス】 | AV5: 1 | AW5: 1
A6: トランサー | C6: 感覚型 | F6: ハイブリッド | G6: ハイブリッド | H6: ルーン企業連 | N6: 付加発動 | P6: 強化【抵】 | Q6: 強化【抵】 | R6: ブレイク | V6: 4 | X6: 威圧 | Z6: 荷電粒子砲／S3 | AA6: 3 | AD6: 恩恵 | AF6: 優柔不断 | AH6: 初心【ビギナーズラック】 | AI6: 初心【ビギナーズラック】 | AK6: 身体崩壊 | AM6: トランス／1Rd | AQ6: オリジナル特性 | AR6: リベンジ | AS6: 0 | AU6: 初心【ビギナーズラック】 | AV6: 2 | AW6: 2
A7: クリエイター | C7: 回復型 | F7: アンドロイド | G7: アンドロイド | H7: チーム世紀末覇者 | K7: 幸運ボーナス | N7: 行為発動 | P7: 強化【命】 | Q7: 強化【命】 | R7: ペネトレイション | V7: 5 | Z7: 手榴弾／S3 | AA7: 3 | AD7: 実験 | AF7: 唯我独尊 | AH7: 失敗談【ミステイク】 | AI7: 失敗談【ミステイク】 | AK7: 精神崩壊 | AM7: ライズ／2Rd | AQ7: SPE/奇跡 | AR7: リテイク | AS7: 2 | AU7: 失敗談【ミステイク】 | AV7: 1 | AW7: 1
A8: アンノウン | F8: ロボット | G8: ロボット | H8: スヴァルトアルフ | K8: -2 | N8: ＡＥ【重撃】 | P8: 強化【回】 | Q8: 強化【回】 | R8: オールレンジ | V8: 6 | X8: － | Z8: トラップボム／S3 | AA8: 3 | AD8: 才能 | AF8: 天真爛漫 | AH8: 伏兵【ダークホース】 | AI8: 伏兵【ダークホース】 | AK8: 記憶崩壊 | AM8: ネクスト／3Rd | AQ8: SPE/悪運 | AR8: 逆転 | AS8: 2 | AU8: 伏兵【ダークホース】 | AV8: 1 | AW8: 1
G9: ミュータント | H9: フリーランス | K9: -1 | P9: 強化【技】 | Q9: 強化【技】 | R9: コンティニュー | V9: 7 | X9: 観察眼 | Z9: レールガン／S3 | AA9: 3 | AD9: 喪失 | AF9: 家族 | AH9: 調律者【バランサー】 | AI9: 調律者【バランサー】 | AM9: ユートピア／1Rd | AQ9: SPE/闘志 | AR9: 絆 | AS9: 0 | AU9: 調律者【バランサー】 | AV9: 1 | AW9: 2
K10: 0 | P10: 強化【解】 | Q10: 強化【解】 | R10: テリトリー | V10: 8 | Z10: ドリル／S3 | AA10: 3 | AD10: 復讐 | AF10: 友情 | AH10: 崩壊者【ディケイド】 | AI10: 崩壊者【ディケイド】 | AM10: パンドラ／1Rd | AQ10: SPE/リベンジ | AR10: 激励 | AS10: 3 | AU10: 崩壊者【ディケイド】 | AV10: 1 | AW10: 2
K11: 1 | N11: 技系統 | O11: 技系統_蟹 | P11: 減衰【行】 | Q11: 減衰【行】 | R11: リスク | V11: 9 | X11: － | Z11: ブラスター／S2 | AA11: 2 | AD11: 逃亡 | AF11: 愛 | AH11: 喪失者【ミッシング】 | AI11: 喪失者【ミッシング】 | AM11: マグタフ黒／4Rd | AQ11: SPE/リテイク | AR11: 不屈 | AS11: 1 | AU11: 喪失者【ミッシング】 | AV11: 1 | AW11: 2
A12: 暴走症状 | C12: 次回追加 | F12: 容姿 | H12: 在住エリア | K12: 2 | N12: － | O12: － | P12: 減衰【攻】 | Q12: 減衰【攻】 | R12: オート | V12: 10 | X12: 察知 | Z12: 高周波ブレード／S2 | AA12: 2 | AD12: 傷病 | AF12: 仁義 | AH12: 突然変異【アナザー】 | AI12: 突然変異【アナザー】 | AM12: 使い捨てランチャー／10Rd | AQ12: SPE/逆転 | AR12: 瞑想 | AS12: 2 | AU12: 突然変異【アナザー】 | AV12: 0 | AW12: 0
A13: － | C13: － | D13: 0 | F13: － | H13: － | K13: 3 | N13: 攻撃 | O13: 攻撃 | P13: 減衰【防】 | Q13: 減衰【防】 | R13: セミオート | V13: 11 | Z13: 火炎放射器／S2 | AA13: 2 | AD13: 贖罪 | AF13: 礼節 | AH13: 覚醒者【アクトレイザー】 | AI13: 覚醒者【アクトレイザー】 | AM13: 違法グレネード／4Rd | AQ13: SPE/絆 | AR13: 鎮静 | AS13: 1 | AU13: 覚醒者【アクトレイザー】 | AV13: 1 | AW13: 1
A14: 制御異常 | C14: 生還者（補正なし） | D14: 0 | F14: Ｓ | H14: 上層【アースガルズ】 | N14: 回復 | O14: 回復 | P14: 減衰【抵】 | Q14: 減衰【抵】 | R14: リフレクション | V14: 12 | X14: － | Z14: 電子ドラッグ／S2 | AA14: 2 | AD14: 裏切り | AF14: 誇り | AH14: 探索者【シャープネス】 | AI14: 探索者【シャープネス】 | AM14: ＥＣＭ【Ｐ】／4Rd | AQ14: SPE/激励 | AR14: 精神凌駕 | AS14: 1 | AU14: 探索者【シャープネス】 | AV14: 1 | AW14: 1
A15: 過負荷 | C15: 初期暴走率＋５％ | D15: 5 | F15: Ａ | H15: 中層【ミズガルズ】 | N15: 防御 | O15: 防御 | P15: 減衰【命】 | Q15: 減衰【命】 | R15: パーフェクト | X15: 知識 | Z15: スタンガン／S1 | AA15: 1 | AD15: 名声 | AF15: 男性的 | AH15: 修羅【アタッカー】 | AI15: 修羅【アタッカー】 | AM15: ＥＣＭ【Ｅ】／4Rd | AQ15: SPE/不屈 | AR15: 愛 | AS15: 2 | AU15: 修羅【アタッカー】 | AV15: 1 | AW15: 1
A16: 聴覚異常 | C16: 初期暴走率＋１０％ | D16: 10 | F16: Ｂ | H16: 下層【ヘルヘイム】 | N16: 補正 | O16: 補正 | P16: 減衰【回】 | Q16: 減衰【回】 | R16: シンクロニティ | Z16: ワイヤートラップ／S1 | AA16: 1 | AD16: 悪名 | AF16: 中性的 | AH16: 寵愛【アイドル】 | AI16: 寵愛【アイドル】 | AM16: ＥＣＭ【Ｔ】／4Rd | AQ16: SPE/瞑想 | AR16: 瞬動 | AS16: 1 | AU16: 寵愛【アイドル】 | AV16: 1 | AW16: 1
A17: 視覚異常 | C17: 初期暴走率＋１５％ | D17: 15 | F17: Ｃ | H17: 不明 | N17: 状態異常 | O17: 状態異常 | P17: 減衰【技】 | Q17: 減衰【技】 | X17: － | Z17: フラッシュガン／S2 | AA17: 2 | AD17: 孤独 | AF17: 女性的 | AH17: 英雄【ブレイブ】 | AI17: 英雄【ブレイブ】 | AM17: ＥＣＭ【Ｃ】／4Rd | AQ17: SPE/鎮静 | AR17: 限界突破 | AS17: 1 | AU17: 英雄【ブレイブ】 | AV17: 1 | AW17: 1
A18: 身体異常 | C18: 初期暴走率＋２０％ | D18: 20 | F18: Ｄ | N18: 創造 | O18: 創造 | P18: 減衰【解】 | Q18: 減衰【解】 | X18: 技術 | Z18: 増強アンプル／S1 | AA18: 1 | AD18: 義理の家族 | AF18: 一途 | AH18: 凡骨【ナチュラルボーン】 | AI18: 凡骨【ナチュラルボーン】 | AM18: パイル予備弾／2Rd | AQ18: SPE/精神凌駕 | AR18: 防衛本能 | AS18: 2 | AU18: 凡骨【ナチュラルボーン】 | AV18: 1 | AW18: 1
A19: 能力異常 | C19: 暴走崩壊者 | D19: 0 | F19: Ｅ | N19: 性質 | O19: 性質 | P19: 回復 | Q19: 回復 | Z19: 強化シナプス／S1 | AA19: 1 | AD19: 機械化 | AF19: 好色 | AH19: 殺し屋【ザ・キラー】 | AI19: 殺人者【ザ・キラー】 | AM19: 荷電粒子予備弾／2Rd | AQ19: SPE/愛 | AR19: 共鳴 | AS19: 0 | AU19: 殺し屋【ザ・キラー】 | AV19: 1 | AW19: 1
A20: 言語異常 | N20: 限定 | O20: 限定 | P20: 拡張 | Q20: 拡張 | X20: － | Z20: スモーク／S1 | AA20: 1 | AD20: 被害者 | AF20: 同性愛 | AH20: 武器屋【マスター】 | AI20: 武器屋【マスター】 | AM20: スタン予備弾／2Rd | AQ20: SPE/瞬動 | AR20: パージ | AS20: 0 | AU20: 武器屋【マスター】 | AV20: 1 | AW20: 1
A21: 記憶異常 | C21: 持ち越し抑制ダイス | N21: その他 | O21: 晩成 | P21: 制限 | Q21: 制限 | X21: 隠密 | Z21: サイキックジャミング／S1 | AA21: 1 | AD21: 成功 | AF21: 倹約 | AH21: 守護者【イージス】 | AI21: 守護者【イージス】 | AM21: フラッシュ予備弾／2Rd | AQ21: SPE/限界突破 | AR21: 奥義 | AS21: 0 | AU21: 守護者【イージス】 | AV21: 1 | AW21: 1
A22: 精神異常 | C22: － | O22: 喚装 | P22: 幸運 | Q22: 幸運 | Z22: 神経ジャマー／S1 | AA22: 1 | AD22: 没落 | AF22: 几帳面 | AH22: 反撃者【リベリオン】 | AI22: 反撃者【リベリオン】 | AM22: バーサーカー／1Rd | AQ22: SPE/防衛本能 | AR22: 大器 | AS22: 0 | AU22: 反撃者【リベリオン】 | AV22: 1 | AW22: 1
A23: 忘我 | C23: 1 | O23: その他 | P23: 追加【命】 | Q23: 追加【命】 | X23: － | Z23: トランスキャンセラー／S1 | AA23: 1 | AD23: 権力 | AF23: 独立 | AH23: 影の者【アサシン】 | AI23: 影の者【アサシン】 | AM23: ハイウェイ ／1Rd | AQ23: SPE/共鳴 | AR23: 熟練 | AS23: 0 | AU23: 影の者【アサシン】 | AV23: 2 | AW23: 2
C24: 2 | P24: 追加【回】 | Q24: 追加【回】 | X24: 俊敏 | Z24: クリエイトノイザー／S1 | AA24: 1 | AD24: 勤労 | AF24: 物欲 | AH24: 癒し手【ヒーラー】 | AI24: 癒し手【ヒーラー】 | AM24: 煙幕 ／1Rd | AQ24: SPE/パージ | AR24: エキスパート | AS24: 0 | AU24: 癒し手【ヒーラー】 | AV24: 0 | AW24: 0
C25: 3 | P25: 追加【技】 | Q25: 追加【技】 | Z25: アーマー／S1 | AA25: 1 | AD25: 無名 | AF25: リーダーシップ | AH25: 使役者【ブリーダー】 | AI25: 使役者【ブリーダー】 | AQ25: SPE/奥義 | AR25: 切札 | AS25: 1 | AU25: 使役者【ブリーダー】 | AV25: 1 | AW25: 1
C26: 4 | P26: 追加【解】 | Q26: 追加【解】 | X26: － | Z26: ブラックボックス／S1 | AA26: 1 | AD26: 裏社会 | AF26: 慎重 | AH26: 不幸【アンラッキー】 | AI26: 不幸【アンラッキー】 | AM26: ネクスト（蟹）／2Rd | AQ26: SPE/大器 | AU26: 不幸【アンラッキー】 | AV26: 1 | AW26: 1
C27: 5 | P27: 混乱 | Q27: 混乱 | X27: 話術 | Z27: パワードスーツ／S1 | AA27: 1 | AD27: 平凡 | AF27: 豪胆 | AH27: 抗体【ワクチン】 | AI27: 抗体【ワクチン】 | AM27: 使い捨てランチャー（蟹）／7Rd | AQ27: SPE/熟練 | AU27: 抗体【ワクチン】 | AV27: 1 | AW27: 1
P28: 複製 | Q28: 複製 | Z28: スキャンスコープ／S1 | AA28: 1 | AD28: 商人 | AF28: ポジティブ | AH28: 愚者【トラブルメイカー】 | AI28: 愚者【トラブルメイカー】 | AM28: マキシマム（蟹）／4Rd | AQ28: SPE/エキスパート | AU28: 愚者【トラブルメイカー】 | AV28: 2 | AW28: 2
A29: - | P29: 制止 | Q29: 制止 | X29: － | Z29: 高感度センサー／S1 | AA29: 1 | AD29: 犯罪 | AF29: 自由 | AH29: 不死身【アンデッド】 | AI29: 不死身【アンデッド】 | AM29: 世界樹の朝露（蟹）／10Rd | AQ29: SPE/切り札 | AU29: 不死身【アンデッド】 | AV29: 1 | AW29: 1
A30: ＰＣ | P30: 継続 | Q30: 継続 | X30: 読心 | Z30: 高演算電脳／S1 | AA30: 1 | AD30: 技術者 | AF30: お人好し | AH30: 奉仕者【トレーダー】 | AI30: 奉仕者【トレーダー】 | AM30: ＥＣＭ【U】／4Rd | AQ30: K/昇華者 | AU30: 奉仕者【トレーダー】 | AV30: 1 | AW30: 1
A31: ＮＰＣ | P31: 操作 | Q31: 操作 | Z31: 高性能マニピュレーター／S1 | AA31: 1 | AD31: 宗教 | AF31: 目立ちたがり | AH31: 闇商人【ディーラー】 | AI31: 闇商人【ディーラー】 | AQ31: K/駆け出し | AU31: 闇商人【ディーラー】 | AV31: 1 | AW31: 1
A32: 親愛 | B32: 他に代えがたいほど友情を感じている。最早家族のような存在である。 | P32: 創造 | Q32: 創造 | X32: － | Z32: 光学迷彩／S1 | AA32: 1 | AD32: 芸術 | AF32: 友好 | AH32: 破壊者【デストロイヤー】 | AI32: 破壊者【デストロイヤー】 | AQ32: K/新鋭 | AU32: 破壊者【デストロイヤー】 | AV32: 1 | AW32: 1
A33: 敬愛 | B33: ただ仲が良いということではなく、一人の人間として敬意を払っている。 | P33: 性質【威力】 | Q33: 性質【増強】 | X33: 閃き | Z33: 高出力ブースター／S1 | AA33: 1 | AD33: 忠誠 | AF33: 臆病 | AH33: 職人【プロフェッショナル】 | AI33: 職人【プロフェッショナル】 | AQ33: K/初心 | AU33: 職人【プロフェッショナル】 | AV33: 1 | AW33: 1
A34: 友人 | B34: 知り合いの中でも特に仲が良い。友達。 | P34: 性質【反応】 | Q34: 性質【反応】 | Z34: 心拍スカウター／S1 | AA34: 1 | AD34: 野心 | AF34: ネガティブ | AH34: 鷹の目【ホークアイ】 | AI34: 鷹の目【ホークアイ】 | AQ34: K/失敗談 | AU34: 鷹の目【ホークアイ】 | AV34: 2 | AW34: 2
A35: 好感 | P35: 性質【耐性】 | Q35: 性質【感覚】 | X35: － | AD35: 秘密 | AF35: 寂しがり屋 | AH35: 幻影【ファントム】 | AI35: 幻影【ファントム】 | AQ35: K/伏兵 | AU35: 幻影【ファントム】 | AV35: 2 | AW35: 2
A36: 普通 | B36: 知り合い。顔見知り。 | P36: 性質【感覚】 | Q36: 性質【幸運】 | X36: 幸運 | Z36: ジェットハンマー（蟹）／S4 | AA36: 4 | AD36: 探求 | AF36: 嫉妬 | AH36: 無血開城【ピースメイカー】 | AI36: 無血開城【ピースメイカー】 | AQ36: K/調律者 | AU36: 無血開城【ピースメイカー】 | AV36: 1 | AW36: 1
A37: 反感 | P37: 性質【幸運】 | Q37: 限定耐性 | Z37: 毒電波発生装置（蟹）／S2 | AA37: 2 | AD37: 武道 | AF37: 疑心 | AH37: 人外【レジェンド】 | AI37: 人外【レジェンド】 | AQ37: K/崩壊者 | AU37: 人外【レジェンド】 | AV37: 0 | AW37: 0
A38: 嫌悪 | B38: 正直、あまり一緒にいたくはない。 | P38: 限定耐性 | Q38: 限定無効 | Z38: ショックバトン（蟹）／S2 | AA38: 2 | AD38: 研究 | AF38: 虚偽 | AH38: 希少種【レア】 | AI38: 希少種【レア】 | AQ38: K/喪失者 | AU38: 希少種【レア】 | AV38: 2 | AW38: 2
A39: 憎悪 | B39: 敵対的な心理を明確に抱いている。 | P39: 限定無効 | Q39: 限定吸収 | Z39: 逆位相発生装置（蟹）／S1 | AA39: 1 | AD39: 恋愛 | AF39: 温厚 | AH39: 勇猛【ベルセルク】 | AI39: 勇猛【ベルセルク】 | AQ39: K/突然変異 | AU39: 勇猛【ベルセルク】 | AV39: 1 | AW39: 1
A40: 殺意 | B40: 殺したいほど憎い相手。 | P40: 限定吸収 | Q40: 貫通無効 | Z40: 擬態ホログラム（蟹）／S1 | AA40: 1 | AD40: 友人 | AF40: 慈愛 | AH40: 魔性【フェロモン】 | AI40: 魔性【フェロモン】 | AQ40: K/覚醒者 | AU40: 魔性【フェロモン】 | AV40: 2 | AW40: 2
...

Sheet キャラシート
B2: キャラクター名 | I2: 環境 | J2: ＰＬ名 | N2: 次回セッション | T2: ※先にこちらの欄を入力する事で左欄にある程度数値が自動反映されます
I3: 蟹 | N3: 次回状態 | P3: － | AC3: 基礎技能値 | AF3: 運ボーナス | AG3: 基礎技能値 | AJ3: 運ボーナス
N4: 持ち越し因子ダイス | P4: － | U4: →手入力 | W4: →選択入力 | Y4: →自動反映 | AA4: →反映結果 | AC4: 力技 | AE4: =(AA10*2) -> 8 | AF4: =IF(AA16<18,IF(AA16<14,IF(AA16<10,IF(AA16<5,IF(AA16<3,"-2","-1"),0),"+1"),"+2"),"+3") -> -1 | AG4: 隠密 | AI4: =AA14+AA15 -> 8 | AJ4: =IF(AA16<18,IF(AA16<14,IF(AA16<10,IF(AA16<5,IF(AA16<3,"-2","-1"),0),"+1"),"+2"),"+3") -> -1
B5: 性別 | D5: 年齢 | F5: 身長 | H5: 容姿 | J5: カルマ | N5: 崩壊深度 | P5: － | AC5: 威圧 | AE5: =AA10+AA11 -> 8 | AF5: =IF(AA16<18,IF(AA16<14,IF(AA16<10,IF(AA16<5,IF(AA16<3,"-2","-1"),0),"+1"),"+2"),"+3") -> -1 | AG5: 俊敏 | AI5: =(AA15*2) -> 8 | AJ5: =IF(AA16<18,IF(AA16<14,IF(AA16<10,IF(AA16<5,IF(AA16<3,"-2","-1"),0),"+1"),"+2"),"+3") -> -1
H6: － | J6: － | N6: 後遺症 | P6: － | T6: ▼ステータス計算 | AC6: 観察眼 | AE6: =ROUNDDOWN((AA55/2),0)+AA12 -> 7 | AF6: =IF(AA16<18,IF(AA16<14,IF(AA16<10,IF(AA16<5,IF(AA16<3,"-2","-1"),0),"+1"),"+2"),"+3") -> -1 | AG6: 話術 | AI6: =AA14+AA12 -> 8 | AJ6: =IF(AA16<18,IF(AA16<14,IF(AA16<10,IF(AA16<5,IF(AA16<3,"-2","-1"),0),"+1"),"+2"),"+3") -> -1
B7: 職業 | J7: 所属 | K7: － | N7: － | P7: － | T7: 能力タイプ | V7: =C10 -> － | X7: 身体タイプ | Z7: =F10 -> － | AC7: 察知 | AE7: =ROUNDDOWN((AA55/2),0)+AA15 -> 7 | AF7: =IF(AA16<18,IF(AA16<14,IF(AA16<10,IF(AA16<5,IF(AA16<3,"-2","-1"),0),"+1"),"+2"),"+3") -> -1 | AG7: 読心 | AI7: =ROUNDDOWN((AA55/2),0)+AA13 -> 7 | AJ7: =IF(AA16<18,IF(AA16<14,IF(AA16<10,IF(AA16<5,IF(AA16<3,"-2","-1"),0),"+1"),"+2"),"+3") -> -1
J8: 在住エリア | K8: － | N8: － | P8: － | T8: 基礎パラメーター | AA8: 総パラ | AC8: 知識 | AE8: =(AA12*2) -> 8 | AF8: =IF(AA16<18,IF(AA16<14,IF(AA16<10,IF(AA16<5,IF(AA16<3,"-2","-1"),0),"+1"),"+2"),"+3") -> -1 | AG8: 閃き | AI8: =ROUNDDOWN((AA55/2),0)+AA16 -> 7 | AJ8: =IF(AA16<18,IF(AA16<14,IF(AA16<10,IF(AA16<5,IF(AA16<3,"-2","-1"),0),"+1"),"+2"),"+3") -> -1
U9: 基礎pt | V9: フリーpt | W9: 計① | X9: 能力者付与pt | Y9: ノーマル付与pt | Z9: 身体付与pt | AA9: ①＋② | AC9: 技術 | AE9: =AA14+AA13 -> 8 | AF9: =IF(AA16<18,IF(AA16<14,IF(AA16<10,IF(AA16<5,IF(AA16<3,"-2","-1"),0),"+1"),"+2"),"+3") -> -1 | AG9: 幸運 | AI9: =(AA16*2) -> 8 | AJ9: =IF(AA16<18,IF(AA16<14,IF(AA16<10,IF(AA16<5,IF(AA16<3,"-2","-1"),0),"+1"),"+2"),"+3") -> -1
B10: 能力タイプ | C10: － | E10: 身体タイプ | F10: － | J10: ライフパス | T10: 筋力 | U10: 4 | W10: =SUM(U10:V10) -> 4 | X10: =IF(C10="トランサー",2,0) -> 0 | Z10: =IF(F10="サイボーグ",1,0) -> 0 | AA10: =W10+AA24+SUM(X10:Z10)-T70 -> 4
J11: ライフ＆ライフ | L11: － | N11: スタンス | P11: － | T11: 耐久 | U11: 4 | W11: =SUM(U11:V11) -> 4 | X11: =IF(C10="サイキッカー",1,0) -> 0 | Z11: =IF(F10="ロボット",1,0) -> 0 | AA11: =W11+AA25+SUM(X11:Z11)-U70 -> 4
L12: － | N12: トゥルー | P12: － | T12: 知力 | U12: 4 | W12: =SUM(U12:V12) -> 4 | X12: =IF(C10="エスパー",1,0)+IF(C10="アンノウン",1,0) -> 0 | Z12: =IF(F10="コーディネーター",1,0) -> 0 | AA12: =W12+AA26+SUM(X12:Z12)-V70 -> 4 | AC12: パラメーター基準値
B13: ＳＰＥ | C13: － | E13: 活性タイプ | F13: － | J13: キャライメージ | O13: エキスパ | P13: - | Q13: - | T13: 精神 | U13: 4 | W13: =SUM(U13:V13) -> 4 | X13: =IF(C10="エスパー",2,0)+IF(C10="クリエイター",1,0) -> 0 | Z13: =IF(F10="ナチュラル",1,0) -> 0 | AA13: =W13+AA27+SUM(X13:Z13)-W70 -> 4 | AC13: 無能 | AD13: 貧弱 | AE13: 常人 | AG13: 秀才 | AI13: 達人 | AJ13: 天才
O14: 探索技能 | Q14: ＳＰＥ補正 | T14: 器用 | U14: 4 | W14: =SUM(U14:V14) -> 4 | X14: =IF(C10="クリエイター",2,0) -> 0 | Z14: =IF(F10="ハイブリッド",1,0) -> 0 | AA14: =W14+AA28+SUM(X14:Z14)-X70 -> 4 | AC14: 1～２ | AD14: ３～４ | AE14: ５～９ | AG14: １０～１３ | AI14: １４～１７ | AJ14: １８～
O15: 力技 | P15: =ROUNDDOWN((AE4+AF4)/2,0) -> 3 | T15: 敏捷 | U15: 4 | W15: =SUM(U15:V15) -> 4 | X15: =IF(C10="サイキッカー",2,0)+IF(C10="トランサー",1,0) -> 0 | Z15: =IF(F10="アンドロイド",1,0) -> 0 | AA15: =W15+AA29+SUM(X15:Z15)-Y70 -> 4
B16: ステータス | F16: パラメーター | O16: 威圧 | P16: =ROUNDDOWN((AE5+AF5)/2,0) -> 3 | T16: 運 | U16: 4 | W16: =SUM(U16:V16) -> 4 | X16: =IF(C10="アンノウン",2,0) -> 0 | Z16: =IF(SUM(Z10:Z15)=0,IF(F10="－",0,1),0) -> 0 | AA16: =W16+AA30+SUM(X16:Z16)-Z70 -> 4
B17: HP | D17: =ABS(AA49) -> 12 | F17: 筋力 | H17: =AA10 -> 4 | O17: 観察眼 | P17: =ROUNDDOWN((AE6+AF6)/2,0) -> 3 | T17: 計 | U17: =SUM(U10:U16) -> 28 | V17: =SUM(V10:V16) -> 0 | W17: =SUM(W10:W16) -> 28 | X17: =SUM(X10:X16) -> 0 | Y17: =SUM(Y10:Y16) -> 0 | Z17: =SUM(Z10:Z16) -> 0 | AA17: =SUM(AA10:AA16) -> 28 | AC17: 運ボーナス
F18: 耐久 | H18: =AA11 -> 4 | O18: 察知 | P18: =ROUNDDOWN((AE7+AF7)/2,0) -> 3 | U18: =28-U17 -> 0 | V18: =10-V17 -> 10 | X18: =IF(I3="バニラ",3-X17,0) -> 0 | Y18: =IF(C10="ノーマル",3-Y17,0) -> 0 | Z18: =IF(I3="バニラ",1-Z17,0) -> 0 | AA18: =47-AA17 -> 19 | AC18: 運１～２ | AE18: ― | AH18: 基礎技能値－２
B19: PP | D19: =ABS(AA50) -> 18 | F19: 知力 | H19: =AA12 -> 4 | O19: 知識 | P19: =ROUNDDOWN((AE8+AF8)/2,0) -> 3 | U19: ↑フリーpt入力計↑ 計①がゼロ以下はＮＧ | X19: ↑身体・能力タイプｐｔ↑ | AC19: 運３～４ | AE19: ― | AH19: 基礎技能値－１
F20: 精神 | H20: =AA13 -> 4 | O20: 技術 | P20: =ROUNDDOWN((AE9+AF9)/2,0) -> 3 | X20: =IF(I3="バニラ","ノーマルは手入力","追加フリーptを入力してね") -> 追加フリーptを入力してね | AC20: 運５～９ | AE20: ― | AH20: ―
B21: 暴走率 | D21: =AA51 -> 16 | F21: 器用 | H21: =AA14 -> 4 | O21: 隠密 | P21: =ROUNDDOWN((AI4+AJ4)/2,0) -> 3 | AC21: 運１０～１３ | AE21: ― | AH21: 基礎技能値+１
F22: 敏捷 | H22: =AA15 -> 4 | O22: 俊敏 | P22: =ROUNDDOWN((AI5+AJ5)/2,0) -> 3 | T22: キャラ特性付与パラメーター | Z22: キャラpt | AA22: =5+IF(C10="ノーマル",1,0) -> 5 | AC22: 運１４～１７ | AE22: 命中・回避判定ダイス＋１Ｄ６ | AH22: 基礎技能値+２
B23: 防御力 | D23: =AA52 -> 2 | F23: 運 | H23: =AA16 -> 4 | O23: 話術 | P23: =ROUNDDOWN((AI6+AJ6)/2,0) -> 3 | T23: キャラ特性 | U23: - | V23: - | W23: - | X23: - | Y23: - | Z23: - | AA23: 計② | AC23: 運１８～２０ | AE23: 命中・回避判定ダイス＋１Ｄ６ | AH23: 基礎技能値+３
O24: 読心 | P24: =ROUNDDOWN((AI7+AJ7)/2,0) -> 3 | T24: =T10 -> 筋力 | AA24: =SUM(U24:Z24) -> 0
B25: 精神抵抗 | D25: =AA53 -> 2 | F25: 能力精度 | H25: =AA58 -> 4 | O25: 閃き | P25: =ROUNDDOWN((AI8+AJ8)/2,0) -> 3 | T25: =T11 -> 耐久 | AA25: =SUM(U25:Z25) -> 0
O26: 幸運 | P26: =ROUNDDOWN((AI9+AJ9)/2,0) -> 3 | T26: =T12 -> 知力 | AA26: =SUM(U26:Z26) -> 0
B27: 行動値 | D27: =AA54 -> 5 | F27: 発動スペック | H27: =AA59 -> 2 | O27: キャラ特性 | T27: =T13 -> 精神 | AA27: =SUM(U27:Z27) -> 0 | AC27: ◆ 探索技能補足説明 ◆
O28: =U23 -> - | T28: =T14 -> 器用 | AA28: =SUM(U28:Z28) -> 0
O29: =V23 -> - | T29: =T15 -> 敏捷 | AA29: =SUM(U29:Z29) -> 0 | AC29: 技能名 | AE29: 説明
B30: 命中・回避 | F30: 攻撃力 | O30: =W23 -> - | T30: =T16 -> 運 | AA30: =SUM(U30:Z30) -> 0 | AC30: 力技 | AE30: 物を動かす、ドアを破るなど、力で物事を突破する際に必要な判定技能。
B31: ＳＳ | C31: =AA55 -> 6 | D31: =IF(AA16<14,1,2) -> 1 | F31: 格闘 | G31: =V38 -> 0 | H31: =W38 -> 0 | O31: =X23 -> - | T31: 消費pt | U31: =SUM(U24:U30) -> 0 | V31: =SUM(V24:V30) -> 0 | W31: =SUM(W24:W30) -> 0 | X31: =SUM(X24:X30) -> 0 | Y31: =SUM(Y24:Y30) -> 0 | Z31: =SUM(Z24:Z30) -> 0 | AA31: =SUM(U31:Z31) -> 0 | AC31: 観察眼 | AE31: 物事・現場を観察し、何かに気づけるかどうかの判定技能。
O32: =Y23 -> - | U32: ↑マイナス入力もOK！↑ | AA32: =AA22-AA31 -> 5 | AC32: 閃き | AE32: 推理・考察時に何かを思い付けるかどうかの判定技能。
B33: 命中力 | C33: =AA56 -> 7 | D33: =IF(AA16<14,1,2) -> 1 | F33: 武器 | G33: =V39 -> 0 | H33: =W39 -> 0 | O33: =Z23 -> - | T33: 攻撃力取得 1D6/3点 固定値１/1点 点移行/2点 | AC33: 察知 | AE33: 突然の出来事・気配等に反応できるか・気づけるかどうかの判定技能。
J34: アライメント | O34: 睡眠回復量 | AC34: 知識 | AE34: 物事・情報・使用方法などについて知っているかどうかの判定技能。
B35: 回避力 | C35: =AA57 -> 7 | D35: =IF(AA16<14,1,2) -> 1 | F35: 能力 | G35: =V40 -> 0 | H35: =W40 -> 0 | J35: － | O35: ＨＰ＆ＰＰ回復量 | Q35: =ROUNDDOWN((AA11/3),0) -> 1 | T35: 取得結果 | X35: 取得点 | AC35: 技術 | AE35: 機械を修理する、鍵開けを行うなど、技術を要求される場合の判定技能。
O36: 暴走率回復量 | Q36: =ROUNDDOWN((AA13/3),0) -> 1 | X36: 格闘点 | Y36: 武器点 | Z36: 能力点 | AC36: 隠密 | AE36: 身を隠す、対象を追跡する、物を隠す際の判定技能。
V37: 取得ダイス | W37: 取得固定値 | X37: =Z63-SUM(X38:X40) -> 3 | Y37: =Z64-SUM(Y38:Y40) -> 7 | Z37: =Z65-SUM(Z38:Z40) -> 7 | AA37: 移行結果 | AC37: 俊敏 | AE37: 逃げる、対象を追いかける、高所からの着地ができるかなどの判定技能。
B38: アイテム | J38: 能力名 | T38: 格闘攻撃 | AA38: =ROUNDDOWN((Y38/2),0)+ROUNDDOWN((Z38/2),0)+(X38) -> 0 | AC38: 威圧 | AE38: 強制的に対象を従わせる、威嚇などで黙らせるなどに必要な判定技能。
B39: 特殊武装 | E39: 消費アイテム／アタッチメント | H39: 所持品 | T39: 武器攻撃 | AA39: =ROUNDDOWN((X39/2),0)+ROUNDDOWN((Z39/2),0)+(Y39) -> 0 | AC39: 話術 | AE39: 説得・言いくるめ・交渉など、話術が必要な際の判定技能。
B40: － | E40: － | T40: 能力攻撃 | AA40: =ROUNDDOWN((X40/2),0)+ROUNDDOWN((Y40/2),0)+(Z40) -> 0 | AC40: 読心 | AE40: 対象が嘘をついているかなど、相手の心情を察する判定技能。
B41: － | E41: － | V41: ↑数値のみ入力でＯＫ | X41: ▼ ▼ ▼ ▼ | AC41: 幸運 | AE41: 運が試される際の判定技能。
...

Sheet 応用技
B2: 能力応用技 ※応用技は最大８個まで | M2: 行為発動・特殊技 ※フレーバーの行為発動や、技組合せのチェイン発動、 ＡＥ・ＳＰＥを演出の特殊技、特殊武装などをフレーバー技として明記したい場合に入力下さい。
B4: 発動スペック | D4: =キャラシート!AA59 -> 2 | E4: 防御発動量 | G4: =ROUNDDOWN((キャラシート!H25)/2,0) -> 2 | H4: 付加補正量 | J4: =ROUNDDOWN((キャラシート!H25)/3,0) -> 1
B5: 特殊武装圧迫分 | D5: =-IFERROR(SUMPRODUCT(N(VALUE(RIGHT(INDEX(キャラシート!B40:B51,ROW(1:12)),1)))),0) -> 0 | E5: 性質系＋晩成系 | G5: =SUMIF(H:H, "性質", J:J)+SUMIF(H:H, "晩成", J:J) -> 0 | H5: 喚装系圧迫分 | J5: =IF(キャラシート!I3="蟹",SUMIF(H:H, "喚装", J:J),0) -> 0
B8: 技名 | G8: 射程 | H8: 技系統 | I8: 消費 | J8: 必要スペック | M8: 技名 | R8: 演出 | T8: 射程 | U8: 消費
G9: － | H9: － | I9: =IF(キャラシート!$I$3="蟹",計算用!C12,計算用!C6) -> 0 | J9: =IF(キャラシート!$I$3="蟹",計算用!D12,計算用!D6) -> 0 | R9: － | T9: －
B11: 発動系統 | E11: 付加効果 | H11: ＳＥ
B12: － | C12: － | D12: － | E12: － | F12: － | G12: － | H12: － | I12: － | J12: － | M12: 効果補足
E13: － | F13: － | G13: － | H13: － | I13: － | J13: －
B14: 効果補足
B17: ※この行には具体的な補正量やトリガー条件などをお書き下さい。 | M17: ※この行には具体的な効果やチェイン発動の組合せをお書き下さい。
B19: 技名 | G19: 射程 | H19: 技系統 | I19: 消費 | J19: 必要スペック | M19: 技名 | R19: 演出 | T19: 射程 | U19: 消費
G20: － | H20: － | I20: =IF(キャラシート!$I$3="蟹",計算用!C24,計算用!C18) -> 0 | J20: =IF(キャラシート!$I$3="蟹",計算用!D24,計算用!D18) -> 0 | R20: － | T20: －
B22: 発動系統 | E22: 付加効果 | H22: ＳＥ
B23: － | C23: － | D23: － | E23: － | F23: － | G23: － | H23: － | I23: － | J23: － | M23: 効果補足
E24: － | F24: － | G24: － | H24: － | I24: － | J24: －
B25: 効果補足
B28: ※この行には具体的な補正量やトリガー条件などをお書き下さい。 | M28: ※この行には具体的な効果やチェイン発動の組合せをお書き下さい。
B30: 技名 | G30: 射程 | H30: 技系統 | I30: 消費 | J30: 必要スペック | M30: 技名 | R30: 演出 | T30: 射程 | U30: 消費
G31: － | H31: － | I31: =IF(キャラシート!$I$3="蟹",計算用!C36,計算用!C30) -> 0 | J31: =IF(キャラシート!$I$3="蟹",計算用!D36,計算用!D30) -> 0 | R31: － | T31: －
B33: 発動系統 | E33: 付加効果 | H33: ＳＥ
B34: － | C34: － | D34: － | E34: － | F34: － | G34: － | H34: － | I34: － | J34: － | M34: 効果補足
E35: － | F35: － | G35: － | H35: － | I35: － | J35: －
B36: 効果補足
B39: ※この行には具体的な補正量やトリガー条件などをお書き下さい。 | M39: ※この行には具体的な効果やチェイン発動の組合せをお書き下さい。
B41: 技名 | G41: 射程 | H41: 技系統 | I41: 消費 | J41: 必要スペック | M41: 技名 | R41: 演出 | T41: 射程 | U41: 消費
G42: － | H42: － | I42: =IF(キャラシート!$I$3="蟹",計算用!C48,計算用!C42) -> 0 | J42: =IF(キャラシート!$I$3="蟹",計算用!D48,計算用!D42) -> 0 | R42: － | T42: －
B44: 発動系統 | E44: 付加効果 | H44: ＳＥ
B45: － | C45: － | D45: － | E45: － | F45: － | G45: － | H45: － | I45: － | J45: － | M45: 効果補足
E46: － | F46: － | G46: － | H46: － | I46: － | J46: －
B47: 効果補足
B50: ※この行には具体的な補正量やトリガー条件などをお書き下さい。 | M50: ※この行には具体的な効果やチェイン発動の組合せをお書き下さい。
B52: 技名 | G52: 射程 | H52: 技系統 | I52: 消費 | J52: 必要スペック | M52: 技名 | R52: 演出 | T52: 射程 | U52: 消費
G53: － | H53: － | I53: =IF(キャラシート!$I$3="蟹",計算用!C60,計算用!C54) -> 0 | J53: =IF(キャラシート!$I$3="蟹",計算用!D60,計算用!D54) -> 0 | R53: － | T53: －
B55: 発動系統 | E55: 付加効果 | H55: ＳＥ
B56: － | C56: － | D56: － | E56: － | F56: － | G56: － | H56: － | I56: － | J56: － | M56: 効果補足
E57: － | F57: － | G57: － | H57: － | I57: － | J57: －
B58: 効果補足
B61: ※この行には具体的な補正量やトリガー条件などをお書き下さい。 | M61: ※この行には具体的な効果やチェイン発動の組合せをお書き下さい。
B63: 技名 | G63: 射程 | H63: 技系統 | I63: 消費 | J63: 必要スペック | M63: 技名 | R63: 演出 | T63: 射程 | U63: 消費
G64: － | H64: － | I64: =IF(キャラシート!$I$3="蟹",計算用!C72,計算用!C66) -> 0 | J64: =IF(キャラシート!$I$3="蟹",計算用!D72,計算用!D66) -> 0 | R64: － | T64: －
...

Sheet 計算用
B1: 応用技 | AD1: クリーチャー＿１ | AJ1: クリーチャー＿２ | AP1: クリーチャー＿３
B2: 技１ | C2: 消費 | D2: スペック | E2: 強化変数 | F2: 減衰変数 | H2: バニラ表 | S2: カニ表 | AD2: 技１ | AE2: 消費 | AF2: スペック | AG2: 強化変数 | AH2: 減衰変数 | AJ2: 技１ | AK2: 消費 | AL2: スペック | AM2: 強化変数 | AN2: 減衰変数 | AP2: 技１ | AQ2: 消費 | AR2: スペック | AS2: 強化変数 | AT2: 減衰変数
B3: 発動系統 | C3: =IF(応用技!B12="－",0,VLOOKUP(応用技!B12,計算用!$I$6:$K$11,2,FALSE())) +IF(応用技!C12="－",0,VLOOKUP(応用技!C12,計算用!$I$6:$K$11,2,FALSE())) +IF(応用技!D12="－",0,VLOOKUP(応用技!D12,計算用!$I$6:$K$11,2,FALSE())) +COUNTIF(応用技!B12:D12,"防御発動")^2 -> 0 | D3: =IF(VALUE(D4)<0,0,IF(応用技!B12="－",0,VLOOKUP(応用技!B12,$I$6:$K$11,3,FALSE()))) +IF(応用技!C12="－",0,VLOOKUP(応用技!C12,$I$6:$K$11,3,FALSE())) +IF(応用技!D12="－",0,VLOOKUP(応用技!D12,$I$6:$K$11,3,FALSE())) -> 0 | AD3: 発動系統 | AE3: =IF(クリーチャー!P12="－",0,VLOOKUP(クリーチャー!P12,計算用!$I$6:$K$11,2,FALSE()))+IF(クリーチャー!Q12="－",0,VLOOKUP(クリーチャー!Q12,計算用!$I$6:$K$11,2,FALSE()))+IF(クリーチャー!R12="－",0,VLOOKUP(クリーチャー!R12,計算用!$I$6:$K$11,2,FALSE()))+COUNTIF(クリーチャー!P12:R12,"防御発動")^2 -> 0 | AF3: =IF(AF4<0,0,IF(クリーチャー!P12="－",0,VLOOKUP(クリーチャー!P12,$I$6:$K$11,3,FALSE()))+IF(クリーチャー!Q12="－",0,VLOOKUP(クリーチャー!Q12,$I$6:$K$11,3,FALSE()))+IF(クリーチャー!R12="－",0,VLOOKUP(クリーチャー!R12,$I$6:$K$11,3,FALSE()))) -> 0 | AJ3: 発動系統 | AK3: =IF(クリーチャー_2!P12="－",0,VLOOKUP(クリーチャー_2!P12,計算用!$I$6:$K$11,2,FALSE()))+IF(クリーチャー_2!Q12="－",0,VLOOKUP(クリーチャー_2!Q12,計算用!$I$6:$K$11,2,FALSE()))+IF(クリーチャー_2!R12="－",0,VLOOKUP(クリーチャー_2!R12,計算用!$I$6:$K$11,2,FALSE()))+COUNTIF(クリーチャー_2!P12:R12,"防御発動")^2 -> 0 | AL3: =IF(AL4<0,0,IF(クリーチャー_2!P12="－",0,VLOOKUP(クリーチャー_2!P12,$I$6:$K$11,3,FALSE()))+IF(クリーチャー_2!Q12="－",0,VLOOKUP(クリーチャー_2!Q12,$I$6:$K$11,3,FALSE()))+IF(クリーチャー_2!R12="－",0,VLOOKUP(クリーチャー_2!R12,$I$6:$K$11,3,FALSE()))) -> 0 | AP3: 発動系統 | AQ3: =IF(クリーチャー_3!P12="－",0,VLOOKUP(クリーチャー_3!P12,計算用!$I$6:$K$11,2,FALSE()))+IF(クリーチャー_3!Q12="－",0,VLOOKUP(クリーチャー_3!Q12,計算用!$I$6:$K$11,2,FALSE()))+IF(クリーチャー_3!R12="－",0,VLOOKUP(クリーチャー_3!R12,計算用!$I$6:$K$11,2,FALSE()))+COUNTIF(クリーチャー_3!P12:R12,"防御発動")^2 -> 0 | AR3: =IF(AR4<0,0,IF(クリーチャー_3!P12="－",0,VLOOKUP(クリーチャー_3!P12,$I$6:$K$11,3,FALSE()))+IF(クリーチャー_3!Q12="－",0,VLOOKUP(クリーチャー_3!Q12,$I$6:$K$11,3,FALSE()))+IF(クリーチャー_3!R12="－",0,VLOOKUP(クリーチャー_3!R12,$I$6:$K$11,3,FALSE()))) -> 0
B4: 付加効果 | C4: =IF(応用技!E12="－",0,VLOOKUP(応用技!E12,$M$6:$P$49,2,FALSE()))+IF(応用技!F12="－",0,VLOOKUP(応用技!F12,M6:$P$49,2,FALSE()))+IF(応用技!G12="－",0,VLOOKUP(応用技!G12,$M$6:$P$49,2,FALSE()))+IF(応用技!E13="－",0,VLOOKUP(応用技!E13,$M$6:$P$49,2,FALSE()))+IF(応用技!F13="－",0,VLOOKUP(応用技!F13,$M$6:$P$49,2,FALSE()))+IF(応用技!G13="－",0,VLOOKUP(応用技!G13,$M$6:$P$49,2,FALSE()))+_xlfn.IFS(E4>=2,1+2*(E4-1),E4=1,1,E4=0,0)+_xlfn.IFS(F4>=2,1+2*(F4-1),F4=1,1,F4=0,0) -> 0 | D4: =IF(応用技!E12="－",0,VLOOKUP(応用技!E12,$M$6:$P$49,3,FALSE())) +IF(応用技!F12="－",0,VLOOKUP(応用技!F12,$M$6:$P$49,3,FALSE())) +IF(応用技!G12="－",0,VLOOKUP(応用技!G12,$M$6:$P$49,3,FALSE())) +IF(応用技!E13="－",0,VLOOKUP(応用技!E13,$M$6:$P$49,3,FALSE())) +IF(応用技!F13="－",0,VLOOKUP(応用技!F13,$M$6:$P$49,3,FALSE())) +IF(応用技!G13="－",0,VLOOKUP(応用技!G13,$M$6:$P$49,3,FALSE())) -> 0 | E4: =COUNTIFS(応用技!E12:G13,"強化*") -> 0 | F4: =COUNTIFS(応用技!E12:G13,"減衰*") -> 0 | I4: 発動系統 | M4: 付加効果 | T4: 発動系統 | X4: 付加効果 | AD4: 付加効果 | AE4: {=IF(クリーチャー!S12="－",0,VLOOKUP(クリーチャー!S12,$M$6:$P$49,2,FALSE()))+IF(クリーチャー!T12="－",0,VLOOKUP(クリーチャー!T12,M6:$P$49,2,FALSE()))+IF(クリーチャー!U12="－",0,VLOOKUP(クリーチャー!U12,$M$6:$P$49,2,FALSE()))+IF(クリーチャー!S13="－",0,VLOOKUP(クリーチャー!S13,$M$6:$P$49,2,FALSE()))+IF(クリーチャー!T13="－",0,VLOOKUP(クリーチャー!T13,$M$6:$P$49,2,FALSE()))+IF(クリーチャー!U13="－",0,VLOOKUP(クリーチャー!U13,$M$6:$P$49,2,FALSE()))+_xlfn.IFS(AG4>=2,1+2*(AG4-1),AG4=1,1,AG4=0,0)+_xlfn.IFS(AH4>=2,1+2*(AH4-1),AH4=1,1,AH4=0,0)} -> 0 | AF4: =IF(クリーチャー!S12="－",0,VLOOKUP(クリーチャー!S12,$M$6:$P$49,3,FALSE()))+IF(クリーチャー!T12="－",0,VLOOKUP(クリーチャー!T12,$M$6:$P$49,3,FALSE()))+IF(クリーチャー!U12="－",0,VLOOKUP(クリーチャー!U12,$M$6:$P$49,3,FALSE()))+IF(クリーチャー!S13="－",0,VLOOKUP(クリーチャー!S13,$M$6:$P$49,3,FALSE()))+IF(クリーチャー!T13="－",0,VLOOKUP(クリーチャー!T13,$M$6:$P$49,3,FALSE()))+IF(クリーチャー!U13="－",0,VLOOKUP(クリーチャー!U13,$M$6:$P$49,3,FALSE())) -> 0 | AG4: =COUNTIFS(クリーチャー!S12:U13,"強化*") -> 0 | AH4: =COUNTIFS(クリーチャー!S12:U13,"減衰*") -> 0 | AJ4: 付加効果 | AK4: {=IF(クリーチャー_2!S12="－",0,VLOOKUP(クリーチャー_2!S12,$M$6:$P$49,2,FALSE()))+IF(クリーチャー_2!T12="－",0,VLOOKUP(クリーチャー_2!T12,$M$6:$P$49,2,FALSE()))+IF(クリーチャー_2!U12="－",0,VLOOKUP(クリーチャー_2!U12,$M$6:$P$49,2,FALSE()))+IF(クリーチャー_2!S13="－",0,VLOOKUP(クリーチャー_2!S13,$M$6:$P$49,2,FALSE()))+IF(クリーチャー_2!T13="－",0,VLOOKUP(クリーチャー_2!T13,$M$6:$P$49,2,FALSE()))+IF(クリーチャー_2!U13="－",0,VLOOKUP(クリーチャー_2!U13,$M$6:$P$49,2,FALSE()))+_xlfn.IFS(AM4>=2,1+2*(AM4-1),AM4=1,1,AM4=0,0)+_xlfn.IFS(AN4>=2,1+2*(AN4-1),AN4=1,1,AN4=0,0)} -> 0 | AL4: =IF(クリーチャー_2!S12="－",0,VLOOKUP(クリーチャー_2!S12,$M$6:$P$49,3,FALSE()))+IF(クリーチャー_2!T12="－",0,VLOOKUP(クリーチャー_2!T12,$M$6:$P$49,3,FALSE()))+IF(クリーチャー_2!U12="－",0,VLOOKUP(クリーチャー_2!U12,$M$6:$P$49,3,FALSE()))+IF(クリーチャー_2!S13="－",0,VLOOKUP(クリーチャー_2!S13,$M$6:$P$49,3,FALSE()))+IF(クリーチャー_2!T13="－",0,VLOOKUP(クリーチャー_2!T13,$M$6:$P$49,3,FALSE()))+IF(クリーチャー_2!U13="－",0,VLOOKUP(クリーチャー_2!U13,$M$6:$P$49,3,FALSE())) -> 0 | AM4: =COUNTIFS(クリーチャー_2!S12:U13,"強化*") -> 0 | AN4: =COUNTIFS(クリーチャー_2!S12:U13,"減衰*") -> 0 | AP4: 付加効果 | AQ4: {=IF(クリーチャー_3!S12="－",0,VLOOKUP(クリーチャー_3!S12,$M$6:$P$49,2,FALSE()))+IF(クリーチャー_3!T12="－",0,VLOOKUP(クリーチャー_3!T12,M6:$P$49,2,FALSE()))+IF(クリーチャー_3!U12="－",0,VLOOKUP(クリーチャー_3!U12,$M$6:$P$49,2,FALSE()))+IF(クリーチャー_3!S13="－",0,VLOOKUP(クリーチャー_3!S13,$M$6:$P$49,2,FALSE()))+IF(クリーチャー_3!T13="－",0,VLOOKUP(クリーチャー_3!T13,$M$6:$P$49,2,FALSE()))+IF(クリーチャー_3!U13="－",0,VLOOKUP(クリーチャー_3!U13,$M$6:$P$49,2,FALSE()))+_xlfn.IFS(AS4>=2,1+2*(AS4-1),AS4=1,1,AS4=0,0)+_xlfn.IFS(AT4>=2,1+2*(AT4-1),AT4=1,1,AT4=0,0)} -> 0 | AR4: =IF(クリーチャー_3!S12="－",0,VLOOKUP(クリーチャー_3!S12,$M$6:$P$49,3,FALSE()))+IF(クリーチャー_3!T12="－",0,VLOOKUP(クリーチャー_3!T12,$M$6:$P$49,3,FALSE()))+IF(クリーチャー_3!U12="－",0,VLOOKUP(クリーチャー_3!U12,$M$6:$P$49,3,FALSE()))+IF(クリーチャー_3!S13="－",0,VLOOKUP(クリーチャー_3!S13,$M$6:$P$49,3,FALSE()))+IF(クリーチャー_3!T13="－",0,VLOOKUP(クリーチャー_3!T13,$M$6:$P$49,3,FALSE()))+IF(クリーチャー_3!U13="－",0,VLOOKUP(クリーチャー_3!U13,$M$6:$P$49,3,FALSE())) -> 0 | AS4: =COUNTIFS(クリーチャー_3!S12:U13,"強化*") -> 0 | AT4: =COUNTIFS(クリーチャー_3!S12:U13,"減衰*") -> 0
B5: SE | C5: =IF(応用技!H12="－",0,VLOOKUP(応用技!H12,$I$15:$K$27,2,FALSE())) +IF(応用技!I12="－",0,VLOOKUP(応用技!I12,$I$15:$K$27,2,FALSE())) +IF(応用技!J12="－",0,VLOOKUP(応用技!J12,$I$15:$K$27,2,FALSE())) +IF(応用技!H13="－",0,VLOOKUP(応用技!H13,$I$15:$K$27,2,FALSE())) +IF(応用技!I13="－",0,VLOOKUP(応用技!I13,$I$15:$K$27,2,FALSE())) +IF(応用技!J13="－",0,VLOOKUP(応用技!J13,$I$15:$K$27,2,FALSE())) -> 0 | D5: =IF(応用技!H12="－",0,VLOOKUP(応用技!H12,$I$15:$K$27,3,FALSE())) +IF(応用技!I12="－",0,VLOOKUP(応用技!I12,$I$15:$K$27,3,FALSE())) +IF(応用技!J12="－",0,VLOOKUP(応用技!J12,$I$15:$K$27,3,FALSE())) +IF(応用技!H13="－",0,VLOOKUP(応用技!H13,$I$15:$K$27,3,FALSE())) +IF(応用技!I13="－",0,VLOOKUP(応用技!I13,$I$15:$K$27,3,FALSE())) +IF(応用技!J13="－",0,VLOOKUP(応用技!J13,$I$15:$K$27,3,FALSE())) -> 0 | I5: 名称 | J5: 消費 | K5: スペック | M5: 名称 | N5: 消費 | O5: スペック | P5: 特殊 | T5: 名称 | U5: 消費 | V5: スペック | X5: 名称 | Y5: 消費 | Z5: スペック | AA5: 特殊 | AD5: SE | AE5: =IF(クリーチャー!V12="－",0,VLOOKUP(クリーチャー!V12,$I$15:$K$27,2,FALSE()))+IF(クリーチャー!W12="－",0,VLOOKUP(クリーチャー!W12,$I$15:$K$27,2,FALSE()))+IF(クリーチャー!X12="－",0,VLOOKUP(クリーチャー!X12,$I$15:$K$27,2,FALSE()))+IF(クリーチャー!V13="－",0,VLOOKUP(クリーチャー!V13,$I$15:$K$27,2,FALSE()))+IF(クリーチャー!W13="－",0,VLOOKUP(クリーチャー!W13,$I$15:$K$27,2,FALSE()))+IF(クリーチャー!X13="－",0,VLOOKUP(クリーチャー!X13,$I$15:$K$27,2,FALSE())) -> 0 | AF5: =IF(クリーチャー!V12="－",0,VLOOKUP(クリーチャー!V12,$I$15:$K$27,3,FALSE()))+IF(クリーチャー!W12="－",0,VLOOKUP(クリーチャー!W12,$I$15:$K$27,3,FALSE()))+IF(クリーチャー!X12="－",0,VLOOKUP(クリーチャー!X12,$I$15:$K$27,3,FALSE()))+IF(クリーチャー!V13="－",0,VLOOKUP(クリーチャー!V13,$I$15:$K$27,3,FALSE()))+IF(クリーチャー!W13="－",0,VLOOKUP(クリーチャー!W13,$I$15:$K$27,3,FALSE()))+IF(クリーチャー!X13="－",0,VLOOKUP(クリーチャー!X13,$I$15:$K$27,3,FALSE())) -> 0 | AJ5: SE | AK5: =IF(クリーチャー_2!V12="－",0,VLOOKUP(クリーチャー_2!V12,$I$15:$K$27,2,FALSE()))+IF(クリーチャー_2!W12="－",0,VLOOKUP(クリーチャー_2!W12,$I$15:$K$27,2,FALSE()))+IF(クリーチャー_2!X12="－",0,VLOOKUP(クリーチャー_2!X12,$I$15:$K$27,2,FALSE()))+IF(クリーチャー_2!V13="－",0,VLOOKUP(クリーチャー_2!V13,$I$15:$K$27,2,FALSE()))+IF(クリーチャー_2!W13="－",0,VLOOKUP(クリーチャー_2!W13,$I$15:$K$27,2,FALSE()))+IF(クリーチャー_2!X13="－",0,VLOOKUP(クリーチャー_2!X13,$I$15:$K$27,2,FALSE())) -> 0 | AL5: =IF(クリーチャー_2!V12="－",0,VLOOKUP(クリーチャー_2!V12,$I$15:$K$27,3,FALSE()))+IF(クリーチャー_2!W12="－",0,VLOOKUP(クリーチャー_2!W12,$I$15:$K$27,3,FALSE()))+IF(クリーチャー_2!X12="－",0,VLOOKUP(クリーチャー_2!X12,$I$15:$K$27,3,FALSE()))+IF(クリーチャー_2!V13="－",0,VLOOKUP(クリーチャー_2!V13,$I$15:$K$27,3,FALSE()))+IF(クリーチャー_2!W13="－",0,VLOOKUP(クリーチャー_2!W13,$I$15:$K$27,3,FALSE()))+IF(クリーチャー_2!X13="－",0,VLOOKUP(クリーチャー_2!X13,$I$15:$K$27,3,FALSE())) -> 0 | AP5: SE | AQ5: =IF(クリーチャー_3!V12="－",0,VLOOKUP(クリーチャー_3!V12,$I$15:$K$27,2,FALSE()))+IF(クリーチャー_3!W12="－",0,VLOOKUP(クリーチャー_3!W12,$I$15:$K$27,2,FALSE()))+IF(クリーチャー_3!X12="－",0,VLOOKUP(クリーチャー_3!X12,$I$15:$K$27,2,FALSE()))+IF(クリーチャー_3!V13="－",0,VLOOKUP(クリーチャー_3!V13,$I$15:$K$27,2,FALSE()))+IF(クリーチャー_3!W13="－",0,VLOOKUP(クリーチャー_3!W13,$I$15:$K$27,2,FALSE()))+IF(クリーチャー_3!X13="－",0,VLOOKUP(クリーチャー_3!X13,$I$15:$K$27,2,FALSE())) -> 0 | AR5: =IF(クリーチャー_3!V12="－",0,VLOOKUP(クリーチャー_3!V12,$I$15:$K$27,3,FALSE()))+IF(クリーチャー_3!W12="－",0,VLOOKUP(クリーチャー_3!W12,$I$15:$K$27,3,FALSE()))+IF(クリーチャー_3!X12="－",0,VLOOKUP(クリーチャー_3!X12,$I$15:$K$27,3,FALSE()))+IF(クリーチャー_3!V13="－",0,VLOOKUP(クリーチャー_3!V13,$I$15:$K$27,3,FALSE()))+IF(クリーチャー_3!W13="－",0,VLOOKUP(クリーチャー_3!W13,$I$15:$K$27,3,FALSE()))+IF(クリーチャー_3!X13="－",0,VLOOKUP(クリーチャー_3!X13,$I$15:$K$27,3,FALSE())) -> 0
B6: 合計 | C6: {=_xlfn.IFS(COUNTIF(応用技!E12:G13,"創造")>=1,SUM(C3:C5)+1&"～"&SUM(C3:C5)+10, COUNTIF(応用技!E12:G13,"限定*")>=1,"※", COUNTIF(応用技!E12:G13,"影響無効")>=1,"※",TRUE(),SUM(C3:C5))} -> 0 | D6: =SUM(D3:D5) -> 0 | I6: 攻撃発動 | J6: 1 | K6: 1 | M6: 強化【行】 | N6: 0 | O6: 1 | P6: 強化系 | T6: 攻撃発動 | U6: 1 | V6: 1 | X6: 強化【行】 | Y6: 0 | Z6: 1 | AA6: 強化系 | AD6: 合計 | AE6: {=_xlfn.IFS(COUNTIF(クリーチャー!S12:U13,"創造")>=1,SUM(AE3:AE5)+1&"～"&SUM(AE3:AE5)+10,COUNTIF(クリーチャー!S12:U13,"限定*")>=1,"※",COUNTIF(クリーチャー!S12:U13,"影響無効")>=1,"※",TRUE(),SUM(AE3:AE5))} -> 0 | AF6: =SUM(AF3:AF5) -> 0 | AJ6: 合計 | AK6: {=_xlfn.IFS(COUNTIF(クリーチャー_2!S12:U13,"創造")>=1,SUM(AK3:AK5)+1&"～"&SUM(AK3:AK5)+10,COUNTIF(クリーチャー_2!S12:U13,"限定*")>=1,"※",COUNTIF(クリーチャー_2!S12:U13,"影響無効")>=1,"※",TRUE(),SUM(AK3:AK5))} -> 0 | AL6: =SUM(AL3:AL5) -> 0 | AP6: 合計 | AQ6: {=_xlfn.IFS(COUNTIF(クリーチャー_3!S12:U13,"創造")>=1,SUM(AQ3:AQ5)+1&"～"&SUM(AQ3:AQ5)+10,COUNTIF(クリーチャー_3!S12:U13,"限定*")>=1,"※",COUNTIF(クリーチャー_3!S12:U13,"影響無効")>=1,"※",TRUE(),SUM(AQ3:AQ5))} -> 0 | AR6: =SUM(AR3:AR5) -> 0
I7: 精神発動 | J7: 1 | K7: 0 | M7: 強化【攻】 | N7: 0 | O7: 1 | P7: 強化系 | T7: 精神発動 | U7: 1 | V7: 0 | X7: 強化【攻】 | Y7: 0 | Z7: 1 | AA7: 強化系
B8: 技１（蟹） | C8: 消費 | D8: スペック | E8: 強化変数 | F8: 減衰変数 | I8: 防御発動 | J8: 0 | K8: 1 | M8: 強化【防】 | N8: 0 | O8: 1 | P8: 強化系 | T8: 防御発動 | U8: 0 | V8: 1 | X8: 強化【防】 | Y8: 0 | Z8: 1 | AA8: 強化系 | AD8: 技１（蟹） | AE8: 消費 | AF8: スペック | AG8: 強化変数 | AH8: 減衰変数 | AJ8: 技１（蟹） | AK8: 消費 | AL8: スペック | AM8: 強化変数 | AN8: 減衰変数 | AP8: 技１（蟹） | AQ8: 消費 | AR8: スペック | AS8: 強化変数 | AT8: 減衰変数
B9: 発動系統 | C9: =IF(応用技!B12="－",0,VLOOKUP(応用技!B12,計算用!$T$6:$V$11,2,FALSE())) +IF(応用技!C12="－",0,VLOOKUP(応用技!C12,計算用!$T$6:$V$11,2,FALSE())) +IF(応用技!D12="－",0,VLOOKUP(応用技!D12,計算用!$T$6:$V$11,2,FALSE())) +COUNTIF(応用技!B12:D12,"防御発動")^2 -> 0 | D9: =IF(VALUE(D10)<0,0,IF(応用技!B12="－",0,VLOOKUP(応用技!B12,$I$6:$K$11,3,FALSE())) +IF(応用技!C12="－",0,VLOOKUP(応用技!C12,$I$6:$K$11,3,FALSE())) +IF(応用技!D12="－",0,VLOOKUP(応用技!D12,$I$6:$K$11,3,FALSE()))) -> 0 | I9: 付加発動 | J9: 0 | K9: 1 | M9: 強化【抵】 | N9: 0 | O9: 1 | P9: 強化系 | T9: 付加発動 | U9: 0 | V9: 1 | X9: 強化【抵】 | Y9: 0 | Z9: 1 | AA9: 強化系 | AD9: 発動系統 | AE9: =IF(クリーチャー!P12="－",0,VLOOKUP(クリーチャー!P12,計算用!$T$6:$V$11,2,FALSE()))+IF(クリーチャー!Q12="－",0,VLOOKUP(クリーチャー!Q12,計算用!$T$6:$V$11,2,FALSE()))+IF(クリーチャー!R12="－",0,VLOOKUP(クリーチャー!R12,計算用!$T$6:$V$11,2,FALSE()))+COUNTIF(クリーチャー!P12:R12,"防御発動")^2 -> 0 | AF9: =IF(AF4<0,0,IF(クリーチャー!P12="－",0,VLOOKUP(クリーチャー!P12,$T$6:$V$11,3,FALSE()))+IF(クリーチャー!Q12="－",0,VLOOKUP(クリーチャー!Q12,$T$6:$V$11,3,FALSE()))+IF(クリーチャー!R12="－",0,VLOOKUP(クリーチャー!R12,$T$6:$V$11,3,FALSE()))) -> 0 | AJ9: 発動系統 | AK9: =IF(クリーチャー_2!P12="－",0,VLOOKUP(クリーチャー_2!P12,計算用!$T$6:$V$11,2,FALSE()))+IF(クリーチャー_2!Q12="－",0,VLOOKUP(クリーチャー_2!Q12,計算用!$T$6:$V$11,2,FALSE()))+IF(クリーチャー_2!R12="－",0,VLOOKUP(クリーチャー_2!R12,計算用!$T$6:$V$11,2,FALSE())) -> 0 | AL9: =IF(AL10<0,0,IF(クリーチャー_2!P12="－",0,VLOOKUP(クリーチャー_2!P12,$I$6:$K$11,3,FALSE()))+IF(クリーチャー_2!Q12="－",0,VLOOKUP(クリーチャー_2!Q12,$I$6:$K$11,3,FALSE()))+IF(クリーチャー_2!R12="－",0,VLOOKUP(クリーチャー_2!R12,$I$6:$K$11,3,FALSE()))) -> 0 | AP9: 発動系統 | AQ9: =IF(クリーチャー_3!P12="－",0,VLOOKUP(クリーチャー_3!P12,計算用!$T$6:$V$11,2,FALSE()))+IF(クリーチャー_3!Q12="－",0,VLOOKUP(クリーチャー_3!Q12,計算用!$T$6:$V$11,2,FALSE()))+IF(クリーチャー_3!R12="－",0,VLOOKUP(クリーチャー_3!R12,計算用!$T$6:$V$11,2,FALSE()))+COUNTIF(クリーチャー_3!P12:R12,"防御発動")^2 -> 0 | AR9: =IF(AR10<0,0,IF(クリーチャー_3!P12="－",0,VLOOKUP(クリーチャー_3!P12,$I$6:$K$11,3,FALSE()))+IF(クリーチャー_3!Q12="－",0,VLOOKUP(クリーチャー_3!Q12,$I$6:$K$11,3,FALSE()))+IF(クリーチャー_3!R12="－",0,VLOOKUP(クリーチャー_3!R12,$I$6:$K$11,3,FALSE()))) -> 0
B10: 付加効果 | C10: =IF(応用技!E12="－",0,VLOOKUP(応用技!E12,$X$6:$AA$68,2,FALSE())) +IF(応用技!F12="－",0,VLOOKUP(応用技!F12,$X$6:$AA$68,2,FALSE())) +IF(応用技!G12="－",0,VLOOKUP(応用技!G12,$X$6:$AA$68,2,FALSE())) +IF(応用技!E13="－",0,VLOOKUP(応用技!E13,$X$6:$AA$68,2,FALSE())) +IF(応用技!F13="－",0,VLOOKUP(応用技!F13,$X$6:$AA$68,2,FALSE())) +IF(応用技!G13="－",0,VLOOKUP(応用技!G13,$X$6:$AA$68,2,FALSE())) +_xlfn.IFS(E10>=2,1+2*(E10-1),E10=1,1,E10=0,0)+_xlfn.IFS(F10>=2,1+2*(F10-1),F10=1,1,F10=0,0) -> 0 | D10: =IF(応用技!E12="－",0,VLOOKUP(応用技!E12,$X$6:$AA$68,3,FALSE())) +IF(応用技!F12="－",0,VLOOKUP(応用技!F12,$X$6:$AA$68,3,FALSE())) +IF(応用技!G12="－",0,VLOOKUP(応用技!G12,$X$6:$AA$68,3,FALSE())) +IF(応用技!E13="－",0,VLOOKUP(応用技!E13,$X$6:$AA$68,3,FALSE())) +IF(応用技!F13="－",0,VLOOKUP(応用技!F13,$X$6:$AA$68,3,FALSE())) +IF(応用技!G13="－",0,VLOOKUP(応用技!G13,$X$6:$AA$68,3,FALSE())) -> 0 | E10: =COUNTIFS(応用技!E12:G13,"強化*") -> 0 | F10: =COUNTIFS(応用技!E12:G13,"減衰*")+COUNTIFS(応用技!E12:G13,"瞬減*") -> 0 | I10: 行為発動 | J10: 1 | K10: 1 | M10: 強化【命】 | N10: 0 | O10: 1 | P10: 強化系 | T10: 行為発動 | U10: 1 | V10: 1 | X10: 強化【命】 | Y10: 0 | Z10: 1 | AA10: 強化系 | AD10: 付加効果 | AE10: {=IF(クリーチャー!S12="－",0,VLOOKUP(クリーチャー!S12,$X$6:$AA$68,2,FALSE()))+IF(クリーチャー!T12="－",0,VLOOKUP(クリーチャー!T12,X6:$AA$68,2,FALSE()))+IF(クリーチャー!U12="－",0,VLOOKUP(クリーチャー!U12,$X$6:$AA$68,2,FALSE()))+IF(クリーチャー!S13="－",0,VLOOKUP(クリーチャー!S13,$X$6:$AA$68,2,FALSE()))+IF(クリーチャー!T13="－",0,VLOOKUP(クリーチャー!T13,$X$6:$AA$68,2,FALSE()))+IF(クリーチャー!U13="－",0,VLOOKUP(クリーチャー!U13,$X$6:$AA$68,2,FALSE()))+_xlfn.IFS(AG10>=2,1+2*(AG10-1),AG10=1,1,AG10=0,0)+_xlfn.IFS(AH10>=2,1+2*(AH10-1),AH10=1,1,AH10=0,0)} -> 0 | AF10: =IF(クリーチャー!S12="－",0,VLOOKUP(クリーチャー!S12,$X$6:$AA$68,3,FALSE()))+IF(クリーチャー!T12="－",0,VLOOKUP(クリーチャー!T12,$X$6:$AA$68,3,FALSE()))+IF(クリーチャー!U12="－",0,VLOOKUP(クリーチャー!U12,$X$6:$AA$68,3,FALSE()))+IF(クリーチャー!S13="－",0,VLOOKUP(クリーチャー!S13,$X$6:$AA$68,3,FALSE()))+IF(クリーチャー!T13="－",0,VLOOKUP(クリーチャー!T13,$X$6:$AA$68,3,FALSE()))+IF(クリーチャー!U13="－",0,VLOOKUP(クリーチャー!U13,$X$6:$AA$68,3,FALSE())) -> 0 | AG10: =COUNTIFS(クリーチャー!S12:U13,"強化*") -> 0 | AH10: =COUNTIFS(クリーチャー!S12:U13,"減衰*") -> 0 | AJ10: 付加効果 | AK10: {=IF(クリーチャー_2!S12="－",0,VLOOKUP(クリーチャー_2!S12,$X$6:$AA$68,2,FALSE()))+IF(クリーチャー_2!T12="－",0,VLOOKUP(クリーチャー_2!T12,X6:$AA$68,2,FALSE()))+IF(クリーチャー_2!U12="－",0,VLOOKUP(クリーチャー_2!U12,$X$6:$AA$68,2,FALSE()))+IF(クリーチャー_2!S13="－",0,VLOOKUP(クリーチャー_2!S13,$X$6:$AA$68,2,FALSE()))+IF(クリーチャー_2!T13="－",0,VLOOKUP(クリーチャー_2!T13,$X$6:$AA$68,2,FALSE()))+IF(クリーチャー_2!U13="－",0,VLOOKUP(クリーチャー_2!U13,$X$6:$AA$68,2,FALSE()))+_xlfn.IFS(AM10>=2,1+2*(AM10-1),AM10=1,1,AM10=0,0)+_xlfn.IFS(AN10>=2,1+2*(AN10-1),AN10=1,1,AN10=0,0)} -> 0 | AL10: =IF(クリーチャー_2!S12="－",0,VLOOKUP(クリーチャー_2!S12,$X$6:$AA$68,3,FALSE()))+IF(クリーチャー_2!T12="－",0,VLOOKUP(クリーチャー_2!T12,$X$6:$AA$68,3,FALSE()))+IF(クリーチャー_2!U12="－",0,VLOOKUP(クリーチャー_2!U12,$X$6:$AA$68,3,FALSE()))+IF(クリーチャー_2!S13="－",0,VLOOKUP(クリーチャー_2!S13,$X$6:$AA$68,3,FALSE()))+IF(クリーチャー_2!T13="－",0,VLOOKUP(クリーチャー_2!T13,$X$6:$AA$68,3,FALSE()))+IF(クリーチャー_2!U13="－",0,VLOOKUP(クリーチャー_2!U13,$X$6:$AA$68,3,FALSE())) -> 0 | AM10: =COUNTIFS(クリーチャー_2!S12:U13,"強化*") -> 0 | AN10: =COUNTIFS(クリーチャー_2!S12:U13,"減衰*") -> 0 | AP10: 付加効果 | AQ10: {=IF(クリーチャー_3!S12="－",0,VLOOKUP(クリーチャー_3!S12,$X$6:$AA$68,2,FALSE()))+IF(クリーチャー_3!T12="－",0,VLOOKUP(クリーチャー_3!T12,X6:$AA$68,2,FALSE()))+IF(クリーチャー_3!U12="－",0,VLOOKUP(クリーチャー_3!U12,$X$6:$AA$68,2,FALSE()))+IF(クリーチャー_3!S13="－",0,VLOOKUP(クリーチャー_3!S13,$X$6:$AA$68,2,FALSE()))+IF(クリーチャー_3!T13="－",0,VLOOKUP(クリーチャー_3!T13,$X$6:$AA$68,2,FALSE()))+IF(クリーチャー_3!U13="－",0,VLOOKUP(クリーチャー_3!U13,$X$6:$AA$68,2,FALSE()))+_xlfn.IFS(AS10>=2,1+2*(AS10-1),AS10=1,1,AS10=0,0)+_xlfn.IFS(AT10>=2,1+2*(AT10-1),AT10=1,1,AT10=0,0)} -> 0 | AR10: =IF(クリーチャー_3!S12="－",0,VLOOKUP(クリーチャー_3!S12,$X$6:$AA$68,3,FALSE()))+IF(クリーチャー_3!T12="－",0,VLOOKUP(クリーチャー_3!T12,$X$6:$AA$68,3,FALSE()))+IF(クリーチャー_3!U12="－",0,VLOOKUP(クリーチャー_3!U12,$X$6:$AA$68,3,FALSE()))+IF(クリーチャー_3!S13="－",0,VLOOKUP(クリーチャー_3!S13,$X$6:$AA$68,3,FALSE()))+IF(クリーチャー_3!T13="－",0,VLOOKUP(クリーチャー_3!T13,$X$6:$AA$68,3,FALSE()))+IF(クリーチャー_3!U13="－",0,VLOOKUP(クリーチャー_3!U13,$X$6:$AA$68,3,FALSE())) -> 0 | AS10: =COUNTIFS(クリーチャー_3!S12:U13,"強化*") -> 0 | AT10: =COUNTIFS(クリーチャー_3!S12:U13,"減衰*") -> 0
B11: SE | C11: =IF(応用技!H12="－",0,VLOOKUP(応用技!H12,$T$15:$V$28,2,FALSE())) +IF(応用技!I12="－",0,VLOOKUP(応用技!I12,$T$15:$V$28,2,FALSE())) +IF(応用技!J12="－",0,VLOOKUP(応用技!J12,$T$15:$V$28,2,FALSE())) +IF(応用技!H13="－",0,VLOOKUP(応用技!H13,$T$15:$V$28,2,FALSE())) +IF(応用技!I13="－",0,VLOOKUP(応用技!I13,$T$15:$V$28,2,FALSE())) +IF(応用技!J13="－",0,VLOOKUP(応用技!J13,$T$15:$V$28,2,FALSE())) -> 0 | D11: =IF(応用技!H12="－",0,VLOOKUP(応用技!H12,$T$15:$V$28,3,FALSE())) +IF(応用技!I12="－",0,VLOOKUP(応用技!I12,$T$15:$V$28,3,FALSE())) +IF(応用技!J12="－",0,VLOOKUP(応用技!J12,$T$15:$V$28,3,FALSE())) +IF(応用技!H13="－",0,VLOOKUP(応用技!H13,$T$15:$V$28,3,FALSE())) +IF(応用技!I13="－",0,VLOOKUP(応用技!I13,$T$15:$V$28,3,FALSE())) +IF(応用技!J13="－",0,VLOOKUP(応用技!J13,$T$15:$V$28,3,FALSE())) -> 0 | I11: ＡＥ【重撃】 | J11: 1 | K11: 0 | M11: 強化【回】 | N11: 0 | O11: 1 | P11: 強化系 | T11: ＡＥ【重撃】 | U11: 1 | V11: 0 | X11: 強化【回】 | Y11: 0 | Z11: 1 | AA11: 強化系 | AD11: SE | AE11: =IF(クリーチャー!V12="－",0,VLOOKUP(クリーチャー!V12,$T$15:$V$28,2,FALSE()))+IF(クリーチャー!W12="－",0,VLOOKUP(クリーチャー!W12,$T$15:$V$28,2,FALSE()))+IF(クリーチャー!X12="－",0,VLOOKUP(クリーチャー!X12,$T$15:$V$28,2,FALSE()))+IF(クリーチャー!V13="－",0,VLOOKUP(クリーチャー!V13,$T$15:$V$28,2,FALSE()))+IF(クリーチャー!W13="－",0,VLOOKUP(クリーチャー!W13,$T$15:$V$28,2,FALSE()))+IF(クリーチャー!X13="－",0,VLOOKUP(クリーチャー!X13,$T$15:$V$28,2,FALSE())) -> 0 | AF11: =IF(クリーチャー!V12="－",0,VLOOKUP(クリーチャー!V12,$T$15:$V$28,3,FALSE()))+IF(クリーチャー!W12="－",0,VLOOKUP(クリーチャー!W12,$T$15:$V$28,3,FALSE()))+IF(クリーチャー!X12="－",0,VLOOKUP(クリーチャー!X12,$T$15:$V$28,3,FALSE()))+IF(クリーチャー!V13="－",0,VLOOKUP(クリーチャー!V13,$T$15:$V$28,3,FALSE()))+IF(クリーチャー!W13="－",0,VLOOKUP(クリーチャー!W13,$T$15:$V$28,3,FALSE()))+IF(クリーチャー!X13="－",0,VLOOKUP(クリーチャー!X13,$T$15:$V$28,3,FALSE())) -> 0 | AJ11: SE | AK11: =IF(クリーチャー_2!V12="－",0,VLOOKUP(クリーチャー_2!V12,$T$15:$V$28,2,FALSE()))+IF(クリーチャー_2!W12="－",0,VLOOKUP(クリーチャー_2!W12,$T$15:$V$28,2,FALSE()))+IF(クリーチャー_2!X12="－",0,VLOOKUP(クリーチャー_2!X12,$T$15:$V$28,2,FALSE()))+IF(クリーチャー_2!V13="－",0,VLOOKUP(クリーチャー_2!V13,$T$15:$V$28,2,FALSE()))+IF(クリーチャー_2!W13="－",0,VLOOKUP(クリーチャー_2!W13,$T$15:$V$28,2,FALSE()))+IF(クリーチャー_2!X13="－",0,VLOOKUP(クリーチャー_2!X13,$T$15:$V$28,2,FALSE())) -> 0 | AL11: =IF(クリーチャー_2!V12="－",0,VLOOKUP(クリーチャー_2!V12,$T$15:$V$28,3,FALSE()))+IF(クリーチャー_2!W12="－",0,VLOOKUP(クリーチャー_2!W12,$T$15:$V$28,3,FALSE()))+IF(クリーチャー_2!X12="－",0,VLOOKUP(クリーチャー_2!X12,$T$15:$V$28,3,FALSE()))+IF(クリーチャー_2!V13="－",0,VLOOKUP(クリーチャー_2!V13,$T$15:$V$28,3,FALSE()))+IF(クリーチャー_2!W13="－",0,VLOOKUP(クリーチャー_2!W13,$T$15:$V$28,3,FALSE()))+IF(クリーチャー_2!X13="－",0,VLOOKUP(クリーチャー_2!X13,$T$15:$V$28,3,FALSE())) -> 0 | AP11: SE | AQ11: =IF(クリーチャー_3!V12="－",0,VLOOKUP(クリーチャー_3!V12,$T$15:$V$28,2,FALSE()))+IF(クリーチャー_3!W12="－",0,VLOOKUP(クリーチャー_3!W12,$T$15:$V$28,2,FALSE()))+IF(クリーチャー_3!X12="－",0,VLOOKUP(クリーチャー_3!X12,$T$15:$V$28,2,FALSE()))+IF(クリーチャー_3!V13="－",0,VLOOKUP(クリーチャー_3!V13,$T$15:$V$28,2,FALSE()))+IF(クリーチャー_3!W13="－",0,VLOOKUP(クリーチャー_3!W13,$T$15:$V$28,2,FALSE()))+IF(クリーチャー_3!X13="－",0,VLOOKUP(クリーチャー_3!X13,$T$15:$V$28,2,FALSE())) -> 0 | AR11: =IF(クリーチャー_3!V12="－",0,VLOOKUP(クリーチャー_3!V12,$T$15:$V$28,3,FALSE()))+IF(クリーチャー_3!W12="－",0,VLOOKUP(クリーチャー_3!W12,$T$15:$V$28,3,FALSE()))+IF(クリーチャー_3!X12="－",0,VLOOKUP(クリーチャー_3!X12,$T$15:$V$28,3,FALSE()))+IF(クリーチャー_3!V13="－",0,VLOOKUP(クリーチャー_3!V13,$T$15:$V$28,3,FALSE()))+IF(クリーチャー_3!W13="－",0,VLOOKUP(クリーチャー_3!W13,$T$15:$V$28,3,FALSE()))+IF(クリーチャー_3!X13="－",0,VLOOKUP(クリーチャー_3!X13,$T$15:$V$28,3,FALSE())) -> 0
B12: 合計 | C12: {=_xlfn.IFS(COUNTIF(応用技!E12:G13,"創造")>=1, SUM(C9:C11)+1&"～"&SUM(C9:C11)+10, COUNTIF(応用技!E12:G13,"限定*")>=1,"※", COUNTIF(応用技!E12:G13,"影響無効")>=1,"※",TRUE(),SUM(C9:C11))} -> 0 | D12: =SUM(D9:D11) -> 0 | M12: 強化【技】 | N12: 0 | O12: 1 | P12: 強化系 | X12: 強化【技】 | Y12: 0 | Z12: 1 | AA12: 強化系 | AD12: 合計 | AE12: {=_xlfn.IFS(COUNTIF(クリーチャー!S12:U13,"創造")>=1,SUM(AE9:AE11)+1&"～"&SUM(AE9:AE11)+10,COUNTIF(クリーチャー!S12:U13,"限定*")>=1,"※",COUNTIF(クリーチャー!S12:U13,"影響無効")>=1,"※",TRUE(),SUM(AE9:AE11))} -> 0 | AF12: =SUM(AF9:AF11) -> 0 | AJ12: 合計 | AK12: {=_xlfn.IFS(COUNTIF(クリーチャー_2!S12:U13,"創造")>=1,SUM(AK9:AK11)+1&"～"&SUM(AK9:AK11)+10,COUNTIF(クリーチャー_2!S12:U13,"限定*")>=1,"※",COUNTIF(クリーチャー_2!S12:U13,"影響無効")>=1,"※",TRUE(),SUM(AK9:AK11))} -> 0 | AL12: =SUM(AL9:AL11) -> 0 | AP12: 合計 | AQ12: {=_xlfn.IFS(COUNTIF(クリーチャー_3!S12:U13,"創造")>=1,SUM(AQ9:AQ11)+1&"～"&SUM(AQ9:AQ11)+10,COUNTIF(クリーチャー_3!S12:U13,"限定*")>=1,"※",COUNTIF(クリーチャー_3!S12:U13,"影響無効")>=1,"※",TRUE(),SUM(AQ9:AQ11))} -> 0 | AR12: =SUM(AR9:AR11) -> 0
I13: SE | M13: 強化【解】 | N13: 0 | O13: 1 | P13: 強化系 | T13: SE | X13: 強化【解】 | Y13: 0 | Z13: 1 | AA13: 強化系
B14: 技2 | C14: 消費 | D14: スペック | E14: 強化変数 | F14: 減衰変数 | I14: 名称 | J14: 消費 | K14: スペック | M14: 減衰【行】 | N14: 0 | O14: 1 | P14: 減衰系 | T14: 名称 | U14: 消費 | V14: スペック | X14: 減衰【行】 | Y14: 0 | Z14: 1 | AA14: 減衰系 | AD14: 技2 | AE14: 消費 | AF14: スペック | AG14: 強化変数 | AH14: 減衰変数 | AJ14: 技2 | AK14: 消費 | AL14: スペック | AM14: 強化変数 | AN14: 減衰変数 | AP14: 技2 | AQ14: 消費 | AR14: スペック | AS14: 強化変数 | AT14: 減衰変数
B15: 発動系統 | C15: =IF(応用技!B23="－",0,VLOOKUP(応用技!B23,計算用!$I$6:$K$11,2,FALSE()))+IF(応用技!C23="－",0,VLOOKUP(応用技!C23,計算用!$I$6:$K$11,2,FALSE()))+IF(応用技!D23="－",0,VLOOKUP(応用技!D23,計算用!$I$6:$K$11,2,FALSE()))+COUNTIF(応用技!B23:D23,"防御発動")^2 -> 0 | D15: =IF(D16<0,0,IF(応用技!B23="－",0,VLOOKUP(応用技!B23,$I$6:$K$11,3,FALSE()))+IF(応用技!C23="－",0,VLOOKUP(応用技!C23,$I$6:$K$11,3,FALSE()))+IF(応用技!D23="－",0,VLOOKUP(応用技!D23,$I$6:$K$11,3,FALSE()))) -> 0 | I15: ペネトレイション | J15: 3 | K15: 1 | M15: 減衰【攻】 | N15: 0 | O15: 1 | P15: 減衰系 | T15: ペネトレイション | U15: 3 | V15: 1 | X15: 減衰【攻】 | Y15: 0 | Z15: 1 | AA15: 減衰系 | AD15: 発動系統 | AE15: =IF(クリーチャー!P23="－",0,VLOOKUP(クリーチャー!P23,計算用!$I$6:$K$11,2,FALSE()))+IF(クリーチャー!Q23="－",0,VLOOKUP(クリーチャー!Q23,計算用!$I$6:$K$11,2,FALSE()))+IF(クリーチャー!R23="－",0,VLOOKUP(クリーチャー!R23,計算用!$I$6:$K$11,2,FALSE()))+COUNTIF(クリーチャー!P23:R23,"防御発動")^2 -> 0 | AF15: =IF(AF16<0,0,IF(クリーチャー!P23="－",0,VLOOKUP(クリーチャー!P23,$I$6:$K$11,3,FALSE()))+IF(クリーチャー!Q23="－",0,VLOOKUP(クリーチャー!Q23,$I$6:$K$11,3,FALSE()))+IF(クリーチャー!R23="－",0,VLOOKUP(クリーチャー!R23,$I$6:$K$11,3,FALSE()))) -> 0 | AJ15: 発動系統 | AK15: =IF(クリーチャー_2!P23="－",0,VLOOKUP(クリーチャー_2!P23,計算用!$I$6:$K$11,2,FALSE()))+IF(クリーチャー_2!Q23="－",0,VLOOKUP(クリーチャー_2!Q23,計算用!$I$6:$K$11,2,FALSE()))+IF(クリーチャー_2!R23="－",0,VLOOKUP(クリーチャー_2!R23,計算用!$I$6:$K$11,2,FALSE()))+COUNTIF(クリーチャー_2!P23:R23,"防御発動")^2 -> 0 | AL15: =IF(AL16<0,0,IF(クリーチャー_2!P23="－",0,VLOOKUP(クリーチャー_2!P23,$I$6:$K$11,3,FALSE()))+IF(クリーチャー_2!Q23="－",0,VLOOKUP(クリーチャー_2!Q23,$I$6:$K$11,3,FALSE()))+IF(クリーチャー_2!R23="－",0,VLOOKUP(クリーチャー_2!R23,$I$6:$K$11,3,FALSE()))) -> 0 | AP15: 発動系統 | AQ15: =IF(クリーチャー_3!P23="－",0,VLOOKUP(クリーチャー_3!P23,計算用!$I$6:$K$11,2,FALSE()))+IF(クリーチャー_3!Q23="－",0,VLOOKUP(クリーチャー_3!Q23,計算用!$I$6:$K$11,2,FALSE()))+IF(クリーチャー_3!R23="－",0,VLOOKUP(クリーチャー_3!R23,計算用!$I$6:$K$11,2,FALSE()))+COUNTIF(クリーチャー_3!P23:R23,"防御発動")^2 -> 0 | AR15: =IF(AR16<0,0,IF(クリーチャー_3!P23="－",0,VLOOKUP(クリーチャー_3!P23,$I$6:$K$11,3,FALSE()))+IF(クリーチャー_3!Q23="－",0,VLOOKUP(クリーチャー_3!Q23,$I$6:$K$11,3,FALSE()))+IF(クリーチャー_3!R23="－",0,VLOOKUP(クリーチャー_3!R23,$I$6:$K$11,3,FALSE()))) -> 0
B16: 付加効果 | C16: {=IF(応用技!E23="－",0,VLOOKUP(応用技!E23,$M$6:$P$49,2,FALSE()))+IF(応用技!F23="－",0,VLOOKUP(応用技!F23,M6:$P$49,2,FALSE()))+IF(応用技!G23="－",0,VLOOKUP(応用技!G23,$M$6:$P$49,2,FALSE()))+IF(応用技!E24="－",0,VLOOKUP(応用技!E24,$M$6:$P$49,2,FALSE()))+IF(応用技!F24="－",0,VLOOKUP(応用技!F24,$M$6:$P$49,2,FALSE()))+IF(応用技!G24="－",0,VLOOKUP(応用技!G24,$M$6:$P$49,2,FALSE()))+_xlfn.IFS(E16>=2,1+2*(E16-1),E16=1,1,E16=0,0)+_xlfn.IFS(F16>=2,1+2*(F16-1),F16=1,1,F16=0,0)} -> 0 | D16: =IF(応用技!E23="－",0,VLOOKUP(応用技!E23,$M$6:$P$49,3,FALSE()))+IF(応用技!F23="－",0,VLOOKUP(応用技!F23,$M$6:$P$49,3,FALSE()))+IF(応用技!G23="－",0,VLOOKUP(応用技!G23,$M$6:$P$49,3,FALSE()))+IF(応用技!E24="－",0,VLOOKUP(応用技!E24,$M$6:$P$49,3,FALSE()))+IF(応用技!F24="－",0,VLOOKUP(応用技!F24,$M$6:$P$49,3,FALSE()))+IF(応用技!G24="－",0,VLOOKUP(応用技!G24,$M$6:$P$49,3,FALSE())) -> 0 | E16: =COUNTIFS(応用技!E23:G24,"強化*") -> 0 | F16: =COUNTIFS(応用技!E23:G24,"減衰*") -> 0 | I16: オールレンジ | J16: 3 | K16: 1 | M16: 減衰【防】 | N16: 0 | O16: 1 | P16: 減衰系 | T16: オールレンジ | U16: 3 | V16: 1 | X16: 減衰【防】 | Y16: 0 | Z16: 1 | AA16: 減衰系 | AD16: 付加効果 | AE16: {=IF(クリーチャー!S23="－",0,VLOOKUP(クリーチャー!S23,$M$6:$P$49,2,FALSE()))+IF(クリーチャー!T23="－",0,VLOOKUP(クリーチャー!T23,M6:$P$49,2,FALSE()))+IF(クリーチャー!U23="－",0,VLOOKUP(クリーチャー!U23,$M$6:$P$49,2,FALSE()))+IF(クリーチャー!S24="－",0,VLOOKUP(クリーチャー!S24,$M$6:$P$49,2,FALSE()))+IF(クリーチャー!T24="－",0,VLOOKUP(クリーチャー!T24,$M$6:$P$49,2,FALSE()))+IF(クリーチャー!U24="－",0,VLOOKUP(クリーチャー!U24,$M$6:$P$49,2,FALSE()))+_xlfn.IFS(AG16>=2,1+2*(AG16-1),AG16=1,1,AG16=0,0)+_xlfn.IFS(AH16>=2,1+2*(AH16-1),AH16=1,1,AH16=0,0)} -> 0 | AF16: =IF(クリーチャー!S23="－",0,VLOOKUP(クリーチャー!S23,$M$6:$P$49,3,FALSE()))+IF(クリーチャー!T23="－",0,VLOOKUP(クリーチャー!T23,$M$6:$P$49,3,FALSE()))+IF(クリーチャー!U23="－",0,VLOOKUP(クリーチャー!U23,$M$6:$P$49,3,FALSE()))+IF(クリーチャー!S24="－",0,VLOOKUP(クリーチャー!S24,$M$6:$P$49,3,FALSE()))+IF(クリーチャー!T24="－",0,VLOOKUP(クリーチャー!T24,$M$6:$P$49,3,FALSE()))+IF(クリーチャー!U24="－",0,VLOOKUP(クリーチャー!U24,$M$6:$P$49,3,FALSE())) -> 0 | AG16: =COUNTIFS(クリーチャー!S23:U24,"強化*") -> 0 | AH16: =COUNTIFS(クリーチャー!S23:U24,"減衰*") -> 0 | AJ16: 付加効果 | AK16: {=IF(クリーチャー_2!S23="－",0,VLOOKUP(クリーチャー_2!S23,$M$6:$P$49,2,FALSE()))+IF(クリーチャー_2!T23="－",0,VLOOKUP(クリーチャー_2!T23,$M$6:$P$49,2,FALSE()))+IF(クリーチャー_2!U23="－",0,VLOOKUP(クリーチャー_2!U23,$M$6:$P$49,2,FALSE()))+IF(クリーチャー_2!S24="－",0,VLOOKUP(クリーチャー_2!S24,$M$6:$P$49,2,FALSE()))+IF(クリーチャー_2!T24="－",0,VLOOKUP(クリーチャー_2!T24,$M$6:$P$49,2,FALSE()))+IF(クリーチャー_2!U24="－",0,VLOOKUP(クリーチャー_2!U24,$M$6:$P$49,2,FALSE()))+_xlfn.IFS(AM16>=2,1+2*(AM16-1),AM16=1,1,AM16=0,0)+_xlfn.IFS(AN16>=2,1+2*(AN16-1),AN16=1,1,AN16=0,0)} -> 0 | AL16: =IF(クリーチャー_2!S23="－",0,VLOOKUP(クリーチャー_2!S23,$M$6:$P$49,3,FALSE()))+IF(クリーチャー_2!T23="－",0,VLOOKUP(クリーチャー_2!T23,$M$6:$P$49,3,FALSE()))+IF(クリーチャー_2!U23="－",0,VLOOKUP(クリーチャー_2!U23,$M$6:$P$49,3,FALSE()))+IF(クリーチャー_2!S24="－",0,VLOOKUP(クリーチャー_2!S24,$M$6:$P$49,3,FALSE()))+IF(クリーチャー_2!T24="－",0,VLOOKUP(クリーチャー_2!T24,$M$6:$P$49,3,FALSE()))+IF(クリーチャー_2!U24="－",0,VLOOKUP(クリーチャー_2!U24,$M$6:$P$49,3,FALSE())) -> 0 | AM16: =COUNTIFS(クリーチャー_2!S23:U24,"強化*") -> 0 | AN16: =COUNTIFS(クリーチャー_2!S23:U24,"減衰*") -> 0 | AP16: 付加効果 | AQ16: {=IF(クリーチャー_3!S23="－",0,VLOOKUP(クリーチャー_3!S23,$M$6:$P$49,2,FALSE()))+IF(クリーチャー_3!T23="－",0,VLOOKUP(クリーチャー_3!T23,M6:$P$49,2,FALSE()))+IF(クリーチャー_3!U23="－",0,VLOOKUP(クリーチャー_3!U23,$M$6:$P$49,2,FALSE()))+IF(クリーチャー_3!S24="－",0,VLOOKUP(クリーチャー_3!S24,$M$6:$P$49,2,FALSE()))+IF(クリーチャー_3!T24="－",0,VLOOKUP(クリーチャー_3!T24,$M$6:$P$49,2,FALSE()))+IF(クリーチャー_3!U24="－",0,VLOOKUP(クリーチャー_3!U24,$M$6:$P$49,2,FALSE()))+_xlfn.IFS(AS16>=2,1+2*(AS16-1),AS16=1,1,AS16=0,0)+_xlfn.IFS(AT16>=2,1+2*(AT16-1),AT16=1,1,AT16=0,0)} -> 0 | AR16: =IF(クリーチャー_3!S23="－",0,VLOOKUP(クリーチャー_3!S23,$M$6:$P$49,3,FALSE()))+IF(クリーチャー_3!T23="－",0,VLOOKUP(クリーチャー_3!T23,$M$6:$P$49,3,FALSE()))+IF(クリーチャー_3!U23="－",0,VLOOKUP(クリーチャー_3!U23,$M$6:$P$49,3,FALSE()))+IF(クリーチャー_3!S24="－",0,VLOOKUP(クリーチャー_3!S24,$M$6:$P$49,3,FALSE()))+IF(クリーチャー_3!T24="－",0,VLOOKUP(クリーチャー_3!T24,$M$6:$P$49,3,FALSE()))+IF(クリーチャー_3!U24="－",0,VLOOKUP(クリーチャー_3!U24,$M$6:$P$49,3,FALSE())) -> 0 | AS16: =COUNTIFS(クリーチャー_3!S23:U24,"強化*") -> 0 | AT16: =COUNTIFS(クリーチャー_3!S23:U24,"減衰*") -> 0
B17: SE | C17: =IF(応用技!H23="－",0,VLOOKUP(応用技!H23,$I$15:$K$27,2,FALSE()))+IF(応用技!I23="－",0,VLOOKUP(応用技!I23,$I$15:$K$27,2,FALSE()))+IF(応用技!J23="－",0,VLOOKUP(応用技!J23,$I$15:$K$27,2,FALSE()))+IF(応用技!H24="－",0,VLOOKUP(応用技!H24,$I$15:$K$27,2,FALSE()))+IF(応用技!I24="－",0,VLOOKUP(応用技!I24,$I$15:$K$27,2,FALSE()))+IF(応用技!J24="－",0,VLOOKUP(応用技!J24,$I$15:$K$27,2,FALSE())) -> 0 | D17: =IF(応用技!H23="－",0,VLOOKUP(応用技!H23,$I$15:$K$27,3,FALSE()))+IF(応用技!I23="－",0,VLOOKUP(応用技!I23,$I$15:$K$27,3,FALSE()))+IF(応用技!J23="－",0,VLOOKUP(応用技!J23,$I$15:$K$27,3,FALSE()))+IF(応用技!H24="－",0,VLOOKUP(応用技!H24,$I$15:$K$27,3,FALSE()))+IF(応用技!I24="－",0,VLOOKUP(応用技!I24,$I$15:$K$27,3,FALSE()))+IF(応用技!J24="－",0,VLOOKUP(応用技!J24,$I$15:$K$27,3,FALSE())) -> 0 | I17: テリトリー | J17: 3 | K17: 1 | M17: 減衰【抵】 | N17: 0 | O17: 1 | P17: 減衰系 | T17: テリトリー | U17: 3 | V17: 1 | X17: 減衰【抵】 | Y17: 0 | Z17: 1 | AA17: 減衰系 | AD17: SE | AE17: =IF(クリーチャー!V23="－",0,VLOOKUP(クリーチャー!V23,$I$15:$K$27,2,FALSE()))+IF(クリーチャー!W23="－",0,VLOOKUP(クリーチャー!W23,$I$15:$K$27,2,FALSE()))+IF(クリーチャー!X23="－",0,VLOOKUP(クリーチャー!X23,$I$15:$K$27,2,FALSE()))+IF(クリーチャー!V24="－",0,VLOOKUP(クリーチャー!V24,$I$15:$K$27,2,FALSE()))+IF(クリーチャー!W24="－",0,VLOOKUP(クリーチャー!W24,$I$15:$K$27,2,FALSE()))+IF(クリーチャー!X24="－",0,VLOOKUP(クリーチャー!X24,$I$15:$K$27,2,FALSE())) -> 0 | AF17: =IF(クリーチャー!V23="－",0,VLOOKUP(クリーチャー!V23,$I$15:$K$27,3,FALSE()))+IF(クリーチャー!W23="－",0,VLOOKUP(クリーチャー!W23,$I$15:$K$27,3,FALSE()))+IF(クリーチャー!X23="－",0,VLOOKUP(クリーチャー!X23,$I$15:$K$27,3,FALSE()))+IF(クリーチャー!V24="－",0,VLOOKUP(クリーチャー!V24,$I$15:$K$27,3,FALSE()))+IF(クリーチャー!W24="－",0,VLOOKUP(クリーチャー!W24,$I$15:$K$27,3,FALSE()))+IF(クリーチャー!X24="－",0,VLOOKUP(クリーチャー!X24,$I$15:$K$27,3,FALSE())) -> 0 | AJ17: SE | AK17: =IF(クリーチャー_2!V23="－",0,VLOOKUP(クリーチャー_2!V23,$I$15:$K$27,2,FALSE()))+IF(クリーチャー_2!W23="－",0,VLOOKUP(クリーチャー_2!W23,$I$15:$K$27,2,FALSE()))+IF(クリーチャー_2!X23="－",0,VLOOKUP(クリーチャー_2!X23,$I$15:$K$27,2,FALSE()))+IF(クリーチャー_2!V24="－",0,VLOOKUP(クリーチャー_2!V24,$I$15:$K$27,2,FALSE()))+IF(クリーチャー_2!W24="－",0,VLOOKUP(クリーチャー_2!W24,$I$15:$K$27,2,FALSE()))+IF(クリーチャー_2!X24="－",0,VLOOKUP(クリーチャー_2!X24,$I$15:$K$27,2,FALSE())) -> 0 | AL17: =IF(クリーチャー_2!V23="－",0,VLOOKUP(クリーチャー_2!V23,$I$15:$K$27,3,FALSE()))+IF(クリーチャー_2!W23="－",0,VLOOKUP(クリーチャー_2!W23,$I$15:$K$27,3,FALSE()))+IF(クリーチャー_2!X23="－",0,VLOOKUP(クリーチャー_2!X23,$I$15:$K$27,3,FALSE()))+IF(クリーチャー_2!V24="－",0,VLOOKUP(クリーチャー_2!V24,$I$15:$K$27,3,FALSE()))+IF(クリーチャー_2!W24="－",0,VLOOKUP(クリーチャー_2!W24,$I$15:$K$27,3,FALSE()))+IF(クリーチャー_2!X24="－",0,VLOOKUP(クリーチャー_2!X24,$I$15:$K$27,3,FALSE())) -> 0 | AP17: SE | AQ17: =IF(クリーチャー_3!V23="－",0,VLOOKUP(クリーチャー_3!V23,$I$15:$K$27,2,FALSE()))+IF(クリーチャー_3!W23="－",0,VLOOKUP(クリーチャー_3!W23,$I$15:$K$27,2,FALSE()))+IF(クリーチャー_3!X23="－",0,VLOOKUP(クリーチャー_3!X23,$I$15:$K$27,2,FALSE()))+IF(クリーチャー_3!V24="－",0,VLOOKUP(クリーチャー_3!V24,$I$15:$K$27,2,FALSE()))+IF(クリーチャー_3!W24="－",0,VLOOKUP(クリーチャー_3!W24,$I$15:$K$27,2,FALSE()))+IF(クリーチャー_3!X24="－",0,VLOOKUP(クリーチャー_3!X24,$I$15:$K$27,2,FALSE())) -> 0 | AR17: =IF(クリーチャー_3!V23="－",0,VLOOKUP(クリーチャー_3!V23,$I$15:$K$27,3,FALSE()))+IF(クリーチャー_3!W23="－",0,VLOOKUP(クリーチャー_3!W23,$I$15:$K$27,3,FALSE()))+IF(クリーチャー_3!X23="－",0,VLOOKUP(クリーチャー_3!X23,$I$15:$K$27,3,FALSE()))+IF(クリーチャー_3!V24="－",0,VLOOKUP(クリーチャー_3!V24,$I$15:$K$27,3,FALSE()))+IF(クリーチャー_3!W24="－",0,VLOOKUP(クリーチャー_3!W24,$I$15:$K$27,3,FALSE()))+IF(クリーチャー_3!X24="－",0,VLOOKUP(クリーチャー_3!X24,$I$15:$K$27,3,FALSE())) -> 0
B18: 合計 | C18: {=_xlfn.IFS(COUNTIF(応用技!E23:G24,"創造")>=1,SUM(C15:C17)+1&"～"&SUM(C15:C17)+10,COUNTIF(応用技!E23:G24,"限定*")>=1,"※",COUNTIF(応用技!E23:G24,"影響無効")>=1,"※",TRUE(),SUM(C15:C17))} -> 0 | D18: =SUM(D15:D17) -> 0 | I18: コンティニュー | J18: 2 | K18: 1 | M18: 減衰【命】 | N18: 0 | O18: 1 | P18: 減衰系 | T18: コンティニュー | U18: 2 | V18: 1 | X18: 減衰【命】 | Y18: 0 | Z18: 1 | AA18: 減衰系 | AD18: 合計 | AE18: {=_xlfn.IFS(COUNTIF(クリーチャー!S23:U24,"創造")>=1,SUM(AE15:AE17)+1&"～"&SUM(AE15:AE17)+10,COUNTIF(クリーチャー!S23:U24,"限定*")>=1,"※",COUNTIF(クリーチャー!S23:U24,"影響無効")>=1,"※",TRUE(),SUM(AE15:AE17))} -> 0 | AF18: =SUM(AF15:AF17) -> 0 | AJ18: 合計 | AK18: {=_xlfn.IFS(COUNTIF(クリーチャー_2!S23:U24,"創造")>=1,SUM(AK15:AK17)+1&"～"&SUM(AK15:AK17)+10,COUNTIF(クリーチャー_2!S23:U24,"限定*")>=1,"※",COUNTIF(クリーチャー_2!S23:U24,"影響無効")>=1,"※",TRUE(),SUM(AK15:AK17))} -> 0 | AL18: =SUM(AL15:AL17) -> 0 | AP18: 合計 | AQ18: {=_xlfn.IFS(COUNTIF(クリーチャー_3!S23:U24,"創造")>=1,SUM(AQ15:AQ17)+1&"～"&SUM(AQ15:AQ17)+10,COUNTIF(クリーチャー_3!S23:U24,"限定*")>=1,"※",COUNTIF(クリーチャー_3!S23:U24,"影響無効")>=1,"※",TRUE(),SUM(AQ15:AQ17))} -> 0 | AR18: =SUM(AR15:AR17) -> 0
I19: ドレイン | J19: 2 | K19: 1 | M19: 減衰【回】 | N19: 0 | O19: 1 | P19: 減衰系 | T19: ドレイン | U19: 2 | V19: 1 | X19: 減衰【回】 | Y19: 0 | Z19: 1 | AA19: 減衰系
B20: 技2（蟹） | C20: 消費 | D20: スペック | E20: 強化変数 | F20: 減衰変数 | I20: ブレイク | J20: 3 | K20: 1 | M20: 減衰【技】 | N20: 0 | O20: 1 | P20: 減衰系 | T20: ブレイク | U20: 3 | V20: 1 | X20: 減衰【技】 | Y20: 0 | Z20: 1 | AA20: 減衰系 | AD20: 技2（蟹） | AE20: 消費 | AF20: スペック | AG20: 強化変数 | AH20: 減衰変数 | AJ20: 技2（蟹） | AK20: 消費 | AL20: スペック | AM20: 強化変数 | AN20: 減衰変数 | AP20: 技2（蟹） | AQ20: 消費 | AR20: スペック | AS20: 強化変数 | AT20: 減衰変数
B21: 発動系統 | C21: =IF(応用技!B23="－",0,VLOOKUP(応用技!B23,計算用!$T$6:$V$11,2,FALSE()))+IF(応用技!C23="－",0,VLOOKUP(応用技!C23,計算用!$T$6:$V$11,2,FALSE()))+IF(応用技!D23="－",0,VLOOKUP(応用技!D23,計算用!$T$6:$V$11,2,FALSE()))+COUNTIF(応用技!B23:D23,"防御発動")^2 -> 0 | D21: =IF(VALUE(D22)<0,0,IF(応用技!B23="－",0,VLOOKUP(応用技!B23,$I$6:$K$11,3,FALSE()))+IF(応用技!C23="－",0,VLOOKUP(応用技!C23,$I$6:$K$11,3,FALSE()))+IF(応用技!D23="－",0,VLOOKUP(応用技!D23,$I$6:$K$11,3,FALSE()))) -> 0 | I21: チャージ | J21: 2 | K21: 1 | M21: 減衰【解】 | N21: 0 | O21: 1 | P21: 減衰系 | T21: チャージ | U21: 2 | V21: 1 | X21: 減衰【解】 | Y21: 0 | Z21: 1 | AA21: 減衰系 | AD21: 発動系統 | AE21: =IF(クリーチャー!P23="－",0,VLOOKUP(クリーチャー!P23,計算用!$T$6:$V$11,2,FALSE()))+IF(クリーチャー!Q23="－",0,VLOOKUP(クリーチャー!Q23,計算用!$T$6:$V$11,2,FALSE()))+IF(クリーチャー!R23="－",0,VLOOKUP(クリーチャー!R23,計算用!$T$6:$V$11,2,FALSE()))+COUNTIF(クリーチャー!P23:R23,"防御発動")^2 -> 0 | AF21: =IF(AF22<0,0,IF(クリーチャー!P23="－",0,VLOOKUP(クリーチャー!P23,$I$6:$K$11,3,FALSE()))+IF(クリーチャー!Q23="－",0,VLOOKUP(クリーチャー!Q23,$I$6:$K$11,3,FALSE()))+IF(クリーチャー!R23="－",0,VLOOKUP(クリーチャー!R23,$I$6:$K$11,3,FALSE()))) -> 0 | AJ21: 発動系統 | AK21: =IF(クリーチャー_2!P23="－",0,VLOOKUP(クリーチャー_2!P23,計算用!$T$6:$V$11,2,FALSE()))+IF(クリーチャー_2!Q23="－",0,VLOOKUP(クリーチャー_2!Q23,計算用!$T$6:$V$11,2,FALSE()))+IF(クリーチャー_2!R23="－",0,VLOOKUP(クリーチャー_2!R23,計算用!$T$6:$V$11,2,FALSE()))+COUNTIF(クリーチャー_2!P23:R23,"防御発動")^2 -> 0 | AL21: =IF(AL22<0,0,IF(クリーチャー_2!P23="－",0,VLOOKUP(クリーチャー_2!P23,$I$6:$K$11,3,FALSE()))+IF(クリーチャー_2!Q23="－",0,VLOOKUP(クリーチャー_2!Q23,$I$6:$K$11,3,FALSE()))+IF(クリーチャー_2!R23="－",0,VLOOKUP(クリーチャー_2!R23,$I$6:$K$11,3,FALSE()))) -> 0 | AP21: 発動系統 | AQ21: =IF(クリーチャー_3!P23="－",0,VLOOKUP(クリーチャー_3!P23,計算用!$T$6:$V$11,2,FALSE()))+IF(クリーチャー_3!Q23="－",0,VLOOKUP(クリーチャー_3!Q23,計算用!$T$6:$V$11,2,FALSE()))+IF(クリーチャー_3!R23="－",0,VLOOKUP(クリーチャー_3!R23,計算用!$T$6:$V$11,2,FALSE()))+COUNTIF(クリーチャー_3!P23:R23,"防御発動")^2 -> 0 | AR21: =IF(AR22<0,0,IF(クリーチャー_3!P23="－",0,VLOOKUP(クリーチャー_3!P23,$I$6:$K$11,3,FALSE()))+IF(クリーチャー_3!Q23="－",0,VLOOKUP(クリーチャー_3!Q23,$I$6:$K$11,3,FALSE()))+IF(クリーチャー_3!R23="－",0,VLOOKUP(クリーチャー_3!R23,$I$6:$K$11,3,FALSE()))) -> 0
