Workbook
Name 攻撃スタイル: リスト!$C$3:$C$5
Name 身体タイプ: リスト!$F$3:$F$5
Name 能力タイプ: リスト!$A$3:$A$8
Name 能力分類: リスト!$A$3:$A$8

Sheet リスト
A1: 能力タイプ | C1: 活性タイプ | D1: 活性タイプ | F1: 身体タイプ | H1: 在住エリア | K1: ＳＰＥ | M1: 所属 | P1: 判定ダイス | R1: 幸運ボーナス | T1: 容姿 | V1: 発動系統 | X1: 付加効果 | Z1: ＳＥ | AH1: 特殊武装 | AI1: スペック | AN1: ライフ＆ライフ | AP1: スタンス＆トゥルー | AR1: カルマ | AU1: 崩壊症状 | AW1: 消費アイテム | BB1: ＳＰＥ | BC1: 使用回数 | BE1: カルマ | BF1: 使用回数 | BG1: 使用回数（蟹）
A2: － | C2: － | D2: － | F2: － | H2: － | K2: － | M2: － | P2: １Ｄ６ | R2: -2 | T2: － | V2: － | X2: － | Z2: － | AB2: － | AD2: 0 | AF2: － | AH2: － | AN2: － | AP2: － | AR2: － | AU2: － | AW2: － | BA2: － | BB2: － | BC2: 0 | BE2: － | BF2: 0 | BG2: 0
A3: ノーマル | C3: 覚醒型 | D3: 増強型 | F3: ナチュラル | H3: 上層【アースガルズ】 | K3: 奇跡 | M3: 司法機関グングニル | P3: ２Ｄ６ | R3: -1 | T3: Ｓ | V3: 攻撃発動 | X3: 強化【行】 | Z3: トラップ | AB3: 攻撃型 | AD3: 1 | AF3: 力技 | AH3: アタッチメント【スペック－０】 | AI3: 0 | AN3: 異形 | AP3: 正義 | AR3: 昇華者【リバーサー】 | AU3: 聴覚崩壊 | AW3: マグタフ 【因子１】 | BA3: 行為発動 | BB3: 奇跡 | BC3: 1 | BE3: 昇華者【リバーサー】 | BF3: 1 | BG3: 1
A4: サイキッカー | C4: 増強型 | D4: 反応型 | F4: コーディネーター | H4: 中層【ミズガルズ】 | K4: 悪運 | M4: 民主機構オルレアン | P4: ３Ｄ６ | R4: 0 | T4: Ａ | V4: 精神発動 | X4: 強化【攻】 | Z4: チャージ | AB4: 速度型 | AD4: 2 | AH4: ロケットランチャー【スペック－４】 | AI4: 4 | AN4: 暴走 | AP4: 中庸 | AR4: 駆け出し【ルーキー】 | AU4: 視覚崩壊 | AW4: マグタフＥＸ 【因子１】 | BA4: チェイン発動 | BB4: 悪運 | BC4: 1 | BE4: 駆け出し【ルーキー】 | BF4: 1 | BG4: 1
A5: エスパー | C5: 反応型 | D5: 感覚型 | F5: サイボーグ | H5: 下層【ヘルヘイム】 | K5: 闘志 | M5: 抑制機構テセウス | R5: 1 | T5: Ｂ | V5: 防御発動 | X5: 強化【防】 | Z5: ドレイン | AB5: 探索型 | AD5: 3 | AF5: － | AH5: パイルバンカー【スペック－３】 | AI5: 3 | AN5: 崩壊 | AP5: 悪徳 | AR5: 新鋭【ニューフェイス】 | AU5: 言語崩壊 | AW5: マグタフＺ 【因子２】 | BA5: キャラ特性 | BB5: 闘志 | BC5: 1 | BE5: 新鋭【ニューフェイス】 | BF5: 1 | BG5: 1
A6: トランサー | C6: 感覚型 | D6: 回復型 | F6: ハイブリッド | H6: 不明 | K6: リベンジ | M6: ルーン企業連 | R6: 2 | T6: Ｃ | V6: 付加発動 | X6: 強化【抵】 | Z6: ブレイク | AD6: 4 | AF6: 威圧 | AH6: 荷電粒子砲【スペック－３】 | AI6: 3 | AN6: 恩恵 | AP6: 優柔不断 | AR6: 初心【ビギナーズラック】 | AU6: 身体崩壊 | AW6: トランス 【因子１】 | BA6: オリジナル特性 | BB6: リベンジ | BC6: 0 | BE6: 初心【ビギナーズラック】 | BF6: 2 | BG6: 2
A7: クリエイター | C7: 回復型 | F7: アンドロイド | K7: リテイク | M7: チーム世紀末覇者 | R7: 3 | T7: Ｄ | V7: 行為発動 | X7: 強化【命】 | Z7: ペネトレイション | AD7: 5 | AH7: 手榴弾【スペック－３】 | AI7: 3 | AN7: 実験 | AP7: 唯我独尊 | AR7: 失敗談【ミステイク】 | AU7: 精神崩壊 | AW7: ライズ 【因子２】 | BA7: SPE/奇跡 | BB7: リテイク | BC7: 2 | BE7: 失敗談【ミステイク】 | BF7: 1 | BG7: 1
A8: アンノウン | F8: ロボット | K8: 逆転 | M8: スヴァルトアルフ | T8: Ｅ | V8: ＡＥ【重撃】 | X8: 強化【回】 | Z8: オールレンジ | AD8: 6 | AF8: － | AH8: トラップボム【スペック－３】 | AI8: 3 | AN8: 才能 | AP8: 天真爛漫 | AR8: 伏兵【ダークホース】 | AU8: 記憶崩壊 | AW8: ネクスト 【因子３】 | BA8: SPE/悪運 | BB8: 逆転 | BC8: 2 | BE8: 伏兵【ダークホース】 | BF8: 1 | BG8: 1
F9: ミュータント | K9: 絆 | M9: フリーランス | X9: 強化【技】 | Z9: コンティニュー | AD9: 7 | AF9: 観察眼 | AH9: レールガン【スペック－３】 | AI9: 3 | AN9: 喪失 | AP9: 家族 | AR9: 調律者【バランサー】 | AW9: ユートピア 【因子１】 | BA9: SPE/闘志 | BB9: 絆 | BC9: 0 | BE9: 調律者【バランサー】 | BF9: 1 | BG9: 2
K10: 激励 | Q10: 特殊技 | X10: 強化【解】 | Z10: テリトリー | AD10: 8 | AH10: ドリル【スペック－３】 | AI10: 3 | AN10: 復讐 | AP10: 友情 | AR10: 崩壊者【ディケイド】 | AW10: パンドラ 【因子１】 | BA10: SPE/リベンジ | BB10: 激励 | BC10: 3 | BE10: 崩壊者【ディケイド】 | BF10: 1 | BG10: 2
F11: 活性 | K11: 不屈 | Q11: － | X11: 減衰【行】 | Z11: リスク | AD11: 9 | AF11: － | AH11: ブラスター【スペック－２】 | AI11: 2 | AN11: 逃亡 | AP11: 愛 | AR11: 喪失者【ミッシング】 | AW11: マグタフ黒 【因子４】 | BA11: SPE/リテイク | BB11: 不屈 | BC11: 1 | BE11: 喪失者【ミッシング】 | BF11: 1 | BG11: 2
A12: 暴走症状 | C12: 次回追加 | F12: － | K12: 瞑想 | Q12: 行為発動 | X12: 減衰【攻】 | Z12: オート | AD12: 10 | AF12: 察知 | AH12: 高周波ブレード【スペック－２】 | AI12: 2 | AN12: 傷病 | AP12: 仁義 | AR12: 突然変異【アナザー】 | AW12: 使い捨てランチャー 【因子１０】 | BA12: SPE/逆転 | BB12: 瞑想 | BC12: 2 | BE12: 突然変異【アナザー】 | BF12: 0 | BG12: 0
A13: － | C13: － | D13: 0 | F13: ＋１ | K13: 鎮静 | Q13: チェイン発動 | X13: 減衰【防】 | Z13: セミオート | AD13: 11 | AH13: 火炎放射器【スペック－２】 | AI13: 2 | AN13: 贖罪 | AP13: 礼節 | AR13: 覚醒者【アクトレイザー】 | AW13: 違法グレネード 【因子４】 | BA13: SPE/絆 | BB13: 鎮静 | BC13: 1 | BE13: 覚醒者【アクトレイザー】 | BF13: 1 | BG13: 1
A14: 制御異常 | C14: 生還者（補正なし） | D14: 0 | F14: ＋２ | K14: 精神凌駕 | Q14: 特殊技 | X14: 減衰【抵】 | Z14: リフレクション | AD14: 12 | AF14: － | AH14: 電子ドラッグ【スペック－２】 | AI14: 2 | AN14: 裏切り | AP14: 誇り | AR14: 探索者【シャープネス】 | AW14: ＥＣＭ【Ｐ】 【因子４】 | BA14: SPE/激励 | BB14: 精神凌駕 | BC14: 1 | BE14: 探索者【シャープネス】 | BF14: 1 | BG14: 1
A15: 過負荷 | C15: 初期暴走率＋５％ | D15: 5 | F15: ＋３ | K15: 愛 | Q15: 特殊武装 | X15: 減衰【命】 | Z15: パーフェクト | AF15: 知識 | AH15: スタンガン【スペック－１】 | AI15: 1 | AN15: 名声 | AP15: 男性的 | AR15: 修羅【アタッカー】 | AW15: ＥＣＭ【Ｅ】 【因子４】 | BA15: SPE/不屈 | BB15: 愛 | BC15: 2 | BE15: 修羅【アタッカー】 | BF15: 1 | BG15: 1
A16: 聴覚異常 | C16: 初期暴走率＋１０％ | D16: 10 | K16: 瞬動 | X16: 減衰【回】 | Z16: シンクロニティ | AH16: ワイヤートラップ【スペック－１】 | AI16: 1 | AN16: 悪名 | AP16: 中性的 | AR16: 寵愛【アイドル】 | AW16: ＥＣＭ【Ｔ】 【因子４】 | BA16: SPE/瞑想 | BB16: 瞬動 | BC16: 1 | BE16: 寵愛【アイドル】 | BF16: 1 | BG16: 1
A17: 視覚異常 | C17: 初期暴走率＋１５％ | D17: 15 | K17: 限界突破 | X17: 減衰【技】 | AF17: － | AH17: フラッシュガン【スペック－２】 | AI17: 2 | AN17: 孤独 | AP17: 女性的 | AR17: 英雄【ブレイブ】 | AW17: ＥＣＭ【Ｃ】 【因子４】 | BA17: SPE/鎮静 | BB17: 限界突破 | BC17: 1 | BE17: 英雄【ブレイブ】 | BF17: 1 | BG17: 1
A18: 身体異常 | C18: 初期暴走率＋２０％ | D18: 20 | K18: 防衛本能 | X18: 減衰【解】 | AF18: 技術 | AH18: 増強アンプル【スペック－1】 | AI18: 1 | AN18: 義理の家族 | AP18: 一途 | AR18: 凡骨【ナチュラルボーン】 | AW18: パイル予備弾 【因子２】 | BA18: SPE/精神凌駕 | BB18: 防衛本能 | BC18: 2 | BE18: 凡骨【ナチュラルボーン】 | BF18: 1 | BG18: 1
A19: 能力異常 | C19: 暴走崩壊者 | D19: 0 | K19: 共鳴 | X19: 回復 | AH19: 強化シナプス【スペック－1】 | AI19: 1 | AN19: 機械化 | AP19: 好色 | AR19: 殺し屋【ザ・キラー】 | AW19: 荷電粒子予備弾 【因子２】 | BA19: SPE/愛 | BB19: 共鳴 | BC19: 0 | BE19: 殺し屋【ザ・キラー】 | BF19: 1 | BG19: 1
A20: 言語異常 | K20: パージ | X20: 拡張 | AF20: － | AH20: スモーク【スペック－1】 | AI20: 1 | AN20: 被害者 | AP20: 同性愛 | AR20: 武器屋【マスター】 | AW20: スタン予備弾 【因子２】 | BA20: SPE/瞬動 | BB20: パージ | BC20: 0 | BE20: 武器屋【マスター】 | BF20: 1 | BG20: 1
A21: 記憶異常 | C21: 持ち越し抑制ダイス | K21: 奥義 | X21: 制限 | AF21: 隠密 | AH21: サイキックジャミング【スペック－1】 | AI21: 1 | AN21: 成功 | AP21: 倹約 | AR21: 守護者【イージス】 | AW21: フラッシュ予備弾 【因子２】 | BA21: SPE/限界突破 | BB21: 奥義 | BC21: 0 | BE21: 守護者【イージス】 | BF21: 1 | BG21: 1
A22: 精神異常 | C22: － | K22: 大器 | X22: 幸運 | AH22: 神経ジャマー【スペック－1】 | AI22: 1 | AN22: 没落 | AP22: 几帳面 | AR22: 反撃者【リベリオン】 | AW22: バーサーカー 【因子１】 | BA22: SPE/防衛本能 | BB22: 大器 | BC22: 0 | BE22: 反撃者【リベリオン】 | BF22: 1 | BG22: 1
A23: 忘我 | C23: 1 | K23: 熟練 | X23: 追加【命】 | AF23: － | AH23: トランスキャンセラー【スペック－1】 | AI23: 1 | AN23: 権力 | AP23: 独立 | AR23: 影の者【アサシン】 | AW23: ハイウェイ 【因子１】 | BA23: SPE/共鳴 | BB23: 熟練 | BC23: 0 | BE23: 影の者【アサシン】 | BF23: 2 | BG23: 2
C24: 2 | K24: エキスパート | X24: 追加【回】 | AF24: 俊敏 | AH24: クリエイトノイザー【スペック－1】 | AI24: 1 | AN24: 勤労 | AP24: 物欲 | AR24: 癒し手【ヒーラー】 | AW24: 煙幕 【因子１】 | BA24: SPE/パージ | BB24: エキスパート | BC24: 0 | BE24: 癒し手【ヒーラー】 | BF24: 0 | BG24: 0
C25: 3 | T25: 技系統 | X25: 追加【技】 | AH25: アーマー【スペック－1】 | AI25: 1 | AN25: 無名 | AP25: リーダーシップ | AR25: 使役者【ブリーダー】 | BA25: SPE/奥義 | BB25: 切札 | BC25: 1 | BE25: 使役者【ブリーダー】 | BF25: 1 | BG25: 1
C26: 4 | T26: － | X26: 追加【解】 | AF26: － | AH26: ブラックボックス【スペック－1】 | AI26: 1 | AN26: 裏社会 | AP26: 慎重 | AR26: 不幸【アンラッキー】 | AW26: ネクスト（蟹） 【因子２】 | BA26: SPE/大器 | BE26: 不幸【アンラッキー】 | BF26: 1 | BG26: 1
C27: 5 | T27: 攻撃 | X27: 混乱 | AF27: 話術 | AH27: パワードスーツ【スペック－1】 | AI27: 1 | AN27: 平凡 | AP27: 豪胆 | AR27: 抗体【ワクチン】 | AW27: 使い捨てランチャー（蟹） 【因子７】 | BA27: SPE/熟練 | BE27: 抗体【ワクチン】 | BF27: 1 | BG27: 1
T28: 回復 | X28: 複製 | AH28: スキャンスコープ【スペック－1】 | AI28: 1 | AN28: 商人 | AP28: ポジティブ | AR28: 愚者【トラブルメイカー】 | AW28: マキシマム（蟹）【因子４】 | BA28: SPE/エキスパート | BE28: 愚者【トラブルメイカー】 | BF28: 2 | BG28: 2
A29: - | T29: 防御 | X29: 制止 | AF29: － | AH29: 高感度センサー【スペック－1】 | AI29: 1 | AN29: 犯罪 | AP29: 自由 | AR29: 不死身【アンデッド】 | AW29: 世界樹の朝露（蟹）【因子10】 | BA29: SPE/切り札 | BE29: 不死身【アンデッド】 | BF29: 1 | BG29: 1
A30: ＰＣ | T30: 補正 | X30: 継続 | AF30: 読心 | AH30: 高演算電脳【スペック－1】 | AI30: 1 | AN30: 技術者 | AP30: お人好し | AR30: 奉仕者【トレーダー】 | AW30: ＥＣＭ【U】 【因子４】 | BA30: K/昇華者 | BE30: 奉仕者【トレーダー】 | BF30: 1 | BG30: 1
A31: ＮＰＣ | T31: 状態異常 | X31: 操作 | AH31: 高性能マニピュレーター【スペック－1】 | AI31: 1 | AN31: 宗教 | AP31: 目立ちたがり | AR31: 闇商人【ディーラー】 | BA31: K/駆け出し | BE31: 闇商人【ディーラー】 | BF31: 1 | BG31: 1
A32: 親愛 | B32: 他に代えがたいほど友情を感じている。最早家族のような存在である。 | T32: 創造 | X32: 創造 | AF32: － | AH32: 光学迷彩【スペック－1】 | AI32: 1 | AN32: 芸術 | AP32: 友好 | AR32: 破壊者【デストロイヤー】 | BA32: K/新鋭 | BE32: 破壊者【デストロイヤー】 | BF32: 1 | BG32: 1
A33: 敬愛 | B33: ただ仲が良いということではなく、一人の人間として敬意を払っている。 | T33: その他 | X33: 性質【威力】 | AF33: 閃き | AH33: 高出力ブースター【スペック－1】 | AI33: 1 | AN33: 忠誠 | AP33: 臆病 | AR33: 職人【プロフェッショナル】 | BA33: K/初心 | BE33: 職人【プロフェッショナル】 | BF33: 1 | BG33: 1
A34: 友人 | B34: 知り合いの中でも特に仲が良い。友達。 | X34: 性質【反応】 | AH34: 心拍スカウター【スペック－1】 | AI34: 1 | AN34: 野心 | AP34: ネガティブ | AR34: 鷹の目【ホークアイ】 | BA34: K/失敗談 | BE34: 鷹の目【ホークアイ】 | BF34: 2 | BG34: 2
A35: 好感 | X35: 性質【耐性】 | AF35: － | AN35: 秘密 | AP35: 寂しがり屋 | AR35: 幻影【ファントム】 | BA35: K/伏兵 | BE35: 幻影【ファントム】 | BF35: 2 | BG35: 2
A36: 普通 | B36: 知り合い。顔見知り。 | X36: 性質【感覚】 | AF36: 幸運 | AH36: ジェットハンマー（蟹）【スペック－４】 | AI36: 4 | AN36: 探求 | AP36: 嫉妬 | AR36: 無血開城【ピースメイカー】 | BA36: K/調律者 | BE36: 無血開城【ピースメイカー】 | BF36: 1 | BG36: 1
A37: 反感 | X37: 性質【幸運】 | AH37: 毒電波発生装置（蟹）【スペック－２】 | AI37: 2 | AN37: 武道 | AP37: 疑心 | AR37: 人外【レジェンド】 | BA37: K/崩壊者 | BE37: 人外【レジェンド】 | BF37: 0 | BG37: 0
A38: 嫌悪 | B38: 正直、あまり一緒にいたくはない。 | X38: 性質【増強】 | AH38: ショックバトン（蟹）【スペック－２】 | AI38: 2 | AN38: 研究 | AP38: 虚偽 | AR38: 希少種【レア】 | BA38: K/喪失者 | BE38: 希少種【レア】 | BF38: 2 | BG38: 2
A39: 憎悪 | B39: 敵対的な心理を明確に抱いている。 | X39: 限定耐性 | AH39: 逆位相発生装置（蟹）【スペック－１】 | AI39: 1 | AN39: 恋愛 | AP39: 温厚 | AR39: 勇猛【ベルセルク】 | BA39: K/突然変異 | BE39: 勇猛【ベルセルク】 | BF39: 1 | BG39: 1
A40: 殺意 | B40: 殺したいほど憎い相手。 | X40: 限定無効 | AH40: 擬態ホログラム（蟹）【スペック－１】 | AI40: 1 | AN40: 友人 | AP40: 慈愛 | AR40: 魔性【フェロモン】 | BA40: K/覚醒者 | BE40: 魔性【フェロモン】 | BF40: 2 | BG40: 2
...

Sheet キャラシート
B2: キャラクター名 | I2: 環境 | J2: ＰＬ名 | N2: 次回セッション | T2: ※先にこちらの欄を入力する事で左欄にある程度数値が自動反映されます
I3: 蟹 | N3: 次回状態 | P3: － | AC3: 基礎技能値 | AF3: 運ボーナス | AG3: 基礎技能値 | AJ3: 運ボーナス
N4: 持ち越し因子ダイス | P4: － | U4: →手入力 | W4: →選択入力 | Y4: →自動反映 | AA4: →反映結果 | AC4: 力技 | AE4: =(AA10*2) -> 8 | AF4: =IF(AA16<18,IF(AA16<14,IF(AA16<10,IF(AA16<5,IF(AA16<3,"-2","-1"),0),"+1"),"+2"),"+3") -> -1 | AG4: 隠密 | AI4: =AA14+AA15 -> 8 | AJ4: =IF(AA16<18,IF(AA16<14,IF(AA16<10,IF(AA16<5,IF(AA16<3,"-2","-1"),0),"+1"),"+2"),"+3") -> -1
B5: 性別 | D5: 年齢 | F5: 身長 | H5: 容姿 | J5: カルマ | N5: 崩壊深度 | P5: － | AC5: 威圧 | AE5: =AA10+AA11 -> 8 | AF5: =IF(AA16<18,IF(AA16<14,IF(AA16<10,IF(AA16<5,IF(AA16<3,"-2","-1"),0),"+1"),"+2"),"+3") -> -1 | AG5: 俊敏 | AI5: =(AA15*2) -> 8 | AJ5: =IF(AA16<18,IF(AA16<14,IF(AA16<10,IF(AA16<5,IF(AA16<3,"-2","-1"),0),"+1"),"+2"),"+3") -> -1
H6: － | J6: － | N6: 後遺症 | P6: － | T6: ▼ステータス計算 | AC6: 観察眼 | AE6: =ROUNDDOWN((AA55/2),0)+AA12 -> 7 | AF6: =IF(AA16<18,IF(AA16<14,IF(AA16<10,IF(AA16<5,IF(AA16<3,"-2","-1"),0),"+1"),"+2"),"+3") -> -1 | AG6: 話術 | AI6: =AA14+AA12 -> 8 | AJ6: =IF(AA16<18,IF(AA16<14,IF(AA16<10,IF(AA16<5,IF(AA16<3,"-2","-1"),0),"+1"),"+2"),"+3") -> -1
B7: 職業 | J7: 所属 | K7: － | N7: － | P7: － | T7: 能力タイプ | V7: =C10 -> － | X7: 身体タイプ | Z7: =F10 -> － | AC7: 察知 | AE7: =ROUNDDOWN((AA55/2),0)+AA15 -> 7 | AF7: =IF(AA16<18,IF(AA16<14,IF(AA16<10,IF(AA16<5,IF(AA16<3,"-2","-1"),0),"+1"),"+2"),"+3") -> -1 | AG7: 読心 | AI7: =ROUNDDOWN((AA55/2),0)+AA13 -> 7 | AJ7: =IF(AA16<18,IF(AA16<14,IF(AA16<10,IF(AA16<5,IF(AA16<3,"-2","-1"),0),"+1"),"+2"),"+3") -> -1
J8: 在住エリア | K8: － | N8: － | P8: － | T8: 基礎パラメーター | AA8: 総パラ | AC8: 知識 | AE8: =(AA12*2) -> 8 | AF8: =IF(AA16<18,IF(AA16<14,IF(AA16<10,IF(AA16<5,IF(AA16<3,"-2","-1"),0),"+1"),"+2"),"+3") -> -1 | AG8: 閃き | AI8: =ROUNDDOWN((AA55/2),0)+AA16 -> 7 | AJ8: =IF(AA16<18,IF(AA16<14,IF(AA16<10,IF(AA16<5,IF(AA16<3,"-2","-1"),0),"+1"),"+2"),"+3") -> -1
U9: 基礎pt | V9: フリーpt | W9: 計① | X9: 能力者付与pt | Y9: ノーマル付与pt | Z9: 身体付与pt | AA9: ①＋② | AC9: 技術 | AE9: =AA14+AA13 -> 8 | AF9: =IF(AA16<18,IF(AA16<14,IF(AA16<10,IF(AA16<5,IF(AA16<3,"-2","-1"),0),"+1"),"+2"),"+3") -> -1 | AG9: 幸運 | AI9: =(AA16*2) -> 8 | AJ9: =IF(AA16<18,IF(AA16<14,IF(AA16<10,IF(AA16<5,IF(AA16<3,"-2","-1"),0),"+1"),"+2"),"+3") -> -1
B10: 能力タイプ | C10: － | E10: 身体タイプ | F10: － | J10: ライフパス | T10: 筋力 | U10: 4 | W10: =SUM(U10:V10) -> 4 | X10: =IF(C10="トランサー",2,0) -> 0 | Z10: =IF(F10="サイボーグ",1,0) -> 0 | AA10: =W10+AA24+SUM(X10:Z10)-T70 -> 4
J11: ライフ＆ライフ | L11: － | N11: スタンス | P11: － | T11: 耐久 | U11: 4 | W11: =SUM(U11:V11) -> 4 | X11: =IF(C10="サイキッカー",1,0) -> 0 | Z11: =IF(F10="ロボット",1,0) -> 0 | AA11: =W11+AA25+SUM(X11:Z11)-U70 -> 4
L12: － | N12: トゥルー | P12: － | T12: 知力 | U12: 4 | W12: =SUM(U12:V12) -> 4 | X12: =IF(C10="エスパー",1,0)+IF(C10="アンノウン",1,0) -> 0 | Z12: =IF(F10="コーディネーター",1,0) -> 0 | AA12: =W12+AA26+SUM(X12:Z12)-V70 -> 4 | AC12: パラメーター基準値
B13: ＳＰＥ | C13: － | E13: 活性タイプ | F13: － | J13: キャライメージ | O13: エキスパ | P13: - | Q13: - | T13: 精神 | U13: 4 | W13: =SUM(U13:V13) -> 4 | X13: =IF(C10="エスパー",2,0)+IF(C10="クリエイター",1,0) -> 0 | Z13: =IF(F10="ナチュラル",1,0) -> 0 | AA13: =W13+AA27+SUM(X13:Z13)-W70 -> 4 | AC13: 無能 | AD13: 貧弱 | AE13: 常人 | AG13: 秀才 | AI13: 達人 | AJ13: 天才
O14: 探索技能 | Q14: ＳＰＥ補正 | T14: 器用 | U14: 4 | W14: =SUM(U14:V14) -> 4 | X14: =IF(C10="クリエイター",2,0) -> 0 | Z14: =IF(F10="ハイブリッド",1,0) -> 0 | AA14: =W14+AA28+SUM(X14:Z14)-X70 -> 4 | AC14: 1～２ | AD14: ３～４ | AE14: ５～９ | AG14: １０～１３ | AI14: １４～１７ | AJ14: １８～
O15: 力技 | P15: =ROUNDDOWN((AE4+AF4)/2,0) -> 3 | T15: 敏捷 | U15: 4 | W15: =SUM(U15:V15) -> 4 | X15: =IF(C10="サイキッカー",2,0)+IF(C10="トランサー",1,0) -> 0 | Z15: =IF(F10="アンドロイド",1,0) -> 0 | AA15: =W15+AA29+SUM(X15:Z15)-Y70 -> 4
B16: ステータス | F16: パラメーター | O16: 威圧 | P16: =ROUNDDOWN((AE5+AF5)/2,0) -> 3 | T16: 運 | U16: 4 | W16: =SUM(U16:V16) -> 4 | X16: =IF(C10="アンノウン",2,0) -> 0 | Z16: =IF(SUM(Z10:Z15)=0,IF(F10="－",0,1),0) -> 0 | AA16: =W16+AA30+SUM(X16:Z16)-Z70 -> 4
B17: HP | D17: =ABS(AA49) -> 12 | F17: 筋力 | H17: =AA10 -> 4 | O17: 観察眼 | P17: =ROUNDDOWN((AE6+AF6)/2,0) -> 3 | T17: 計 | U17: =SUM(U10:U16) -> 28 | V17: =SUM(V10:V16) -> 0 | W17: =SUM(W10:W16) -> 28 | X17: =SUM(X10:X16) -> 0 | Y17: =SUM(Y10:Y16) -> 0 | Z17: =SUM(Z10:Z16) -> 0 | AA17: =SUM(AA10:AA16) -> 28 | AC17: 運ボーナス
F18: 耐久 | H18: =AA11 -> 4 | O18: 察知 | P18: =ROUNDDOWN((AE7+AF7)/2,0) -> 3 | U18: =28-U17 -> 0 | V18: =10-V17 -> 10 | X18: =IF(I3="バニラ",3-X17,0) -> 0 | Y18: =IF(C10="ノーマル",3-Y17,0) -> 0 | Z18: =IF(I3="バニラ",1-Z17,0) -> 0 | AA18: =47-AA17 -> 19 | AC18: 運１～２ | AE18: ― | AH18: 基礎技能値－２
B19: PP | D19: =ABS(AA50) -> 18 | F19: 知力 | H19: =AA12 -> 4 | O19: 知識 | P19: =ROUNDDOWN((AE8+AF8)/2,0) -> 3 | U19: ↑フリーpt入力計↑ 計①がゼロ以下はＮＧ | X19: ↑身体・能力タイプｐｔ↑ | AC19: 運３～４ | AE19: ― | AH19: 基礎技能値－１
F20: 精神 | H20: =AA13 -> 4 | O20: 技術 | P20: =ROUNDDOWN((AE9+AF9)/2,0) -> 3 | X20: =IF(I3="バニラ","ノーマルは手入力","追加フリーptを入力してね") -> 追加フリーptを入力してね | AC20: 運５～９ | AE20: ― | AH20: ―
B21: 暴走率 | D21: =AA51 -> 16 | F21: 器用 | H21: =AA14 -> 4 | O21: 隠密 | P21: =ROUNDDOWN((AI4+AJ4)/2,0) -> 3 | AC21: 運１０～１３ | AE21: ― | AH21: 基礎技能値+１
F22: 敏捷 | H22: =AA15 -> 4 | O22: 俊敏 | P22: =ROUNDDOWN((AI5+AJ5)/2,0) -> 3 | T22: キャラ特性付与パラメーター | Z22: キャラpt | AA22: =5+IF(C10="ノーマル",1,0) -> 5 | AC22: 運１４～１７ | AE22: 命中・回避判定ダイス＋１Ｄ６ | AH22: 基礎技能値+２
B23: 防御力 | D23: =AA52 -> 2 | F23: 運 | H23: =AA16 -> 4 | O23: 話術 | P23: =ROUNDDOWN((AI6+AJ6)/2,0) -> 3 | T23: キャラ特性 | U23: - | V23: - | W23: - | X23: - | Y23: - | Z23: - | AA23: 計② | AC23: 運１８～２０ | AE23: 命中・回避判定ダイス＋１Ｄ６ | AH23: 基礎技能値+３
O24: 読心 | P24: =ROUNDDOWN((AI7+AJ7)/2,0) -> 3 | T24: =T10 -> 筋力 | AA24: =SUM(U24:Z24) -> 0
B25: 精神抵抗 | D25: =AA53 -> 2 | F25: 能力精度 | H25: =AA58 -> 4 | O25: 閃き | P25: =ROUNDDOWN((AI8+AJ8)/2,0) -> 3 | T25: =T11 -> 耐久 | AA25: =SUM(U25:Z25) -> 0
O26: 幸運 | P26: =ROUNDDOWN((AI9+AJ9)/2,0) -> 3 | T26: =T12 -> 知力 | AA26: =SUM(U26:Z26) -> 0
B27: 行動値 | D27: =AA54 -> 5 | F27: 発動スペック | H27: =AA59 -> 2 | O27: キャラ特性 | T27: =T13 -> 精神 | AA27: =SUM(U27:Z27) -> 0 | AC27: ◆ 探索技能補足説明 ◆
O28: =U23 -> - | T28: =T14 -> 器用 | AA28: =SUM(U28:Z28) -> 0
O29: =V23 -> - | T29: =T15 -> 敏捷 | AA29: =SUM(U29:Z29) -> 0 | AC29: 技能名 | AE29: 説明
B30: 命中・回避 | F30: 攻撃力 | O30: =W23 -> - | T30: =T16 -> 運 | AA30: =SUM(U30:Z30) -> 0 | AC30: 力技 | AE30: 物を動かす、ドアを破るなど、力で物事を突破する際に必要な判定技能。
B31: ＳＳ | C31: =AA55 -> 6 | D31: =IF(AA16<14,1,2) -> 1 | F31: 格闘 | G31: =IF(AND(T43="ON",AA10>=18),V38+1,V38) -> 0 | H31: =W38 -> 0 | O31: =X23 -> - | T31: 消費pt | U31: =SUM(U24:U30) -> 0 | V31: =SUM(V24:V30) -> 0 | W31: =SUM(W24:W30) -> 0 | X31: =SUM(X24:X30) -> 0 | Y31: =SUM(Y24:Y30) -> 0 | Z31: =SUM(Z24:Z30) -> 0 | AA31: =SUM(U31:Z31) -> 0 | AC31: 観察眼 | AE31: 物事・現場を観察し、何かに気づけるかどうかの判定技能。
O32: =Y23 -> - | U32: ↑マイナス入力もOK！↑ | AA32: =AA22-AA31 -> 5 | AC32: 閃き | AE32: 推理・考察時に何かを思い付けるかどうかの判定技能。
B33: 命中力 | C33: =AA56 -> 7 | D33: =IF(AA16<14,1,2) -> 1 | F33: 武器 | G33: =IF(AND(T43="ON",AA10>=18),V39+1,V39) -> 0 | H33: =W39 -> 0 | O33: =Z23 -> - | T33: 攻撃力取得 1D6/3点 固定値１/1点 点移行/2点 | AC33: 察知 | AE33: 突然の出来事・気配等に反応できるか・気づけるかどうかの判定技能。
J34: アライメント | O34: 睡眠回復量 | AC34: 知識 | AE34: 物事・情報・使用方法などについて知っているかどうかの判定技能。
B35: 回避力 | C35: =AA57 -> 7 | D35: =IF(AA16<14,1,2) -> 1 | F35: 能力 | G35: =IF(AND(T43="ON",AA10>=18),V40+1,V40) -> 0 | H35: =W40 -> 0 | J35: － | O35: ＨＰ＆ＰＰ回復量 | Q35: =ROUNDDOWN((AA11/3),0) -> 1 | T35: 取得結果 | X35: 取得点 | AC35: 技術 | AE35: 機械を修理する、鍵開けを行うなど、技術を要求される場合の判定技能。
O36: 暴走率回復量 | Q36: =ROUNDDOWN((AA13/3),0) -> 1 | X36: 格闘点 | Y36: 武器点 | Z36: 能力点 | AC36: 隠密 | AE36: 身を隠す、対象を追跡する、物を隠す際の判定技能。
V37: 取得ダイス | W37: 取得固定値 | X37: =Z63-SUM(X38:X40) -> 3 | Y37: =Z64-SUM(Y38:Y40) -> 7 | Z37: =Z65-SUM(Z38:Z40) -> 7 | AA37: 移行結果 | AC37: 俊敏 | AE37: 逃げる、対象を追いかける、高所からの着地ができるかなどの判定技能。
B38: アイテム | J38: 能力名 | T38: 格闘攻撃 | AA38: =ROUNDDOWN((Y38/2),0)+ROUNDDOWN((Z38/2),0)+(X38) -> 0 | AC38: 威圧 | AE38: 強制的に対象を従わせる、威嚇などで黙らせるなどに必要な判定技能。
B39: 特殊武装 | E39: 消費アイテム／アタッチメント | H39: 所持品 | T39: 武器攻撃 | AA39: =ROUNDDOWN((X39/2),0)+ROUNDDOWN((Z39/2),0)+(Y39) -> 0 | AC39: 話術 | AE39: 説得・言いくるめ・交渉など、話術が必要な際の判定技能。
B40: － | E40: － | T40: 能力攻撃 | AA40: =ROUNDDOWN((X40/2),0)+ROUNDDOWN((Y40/2),0)+(Z40) -> 0 | AC40: 読心 | AE40: 対象が嘘をついているかなど、相手の心情を察する判定技能。
B41: － | E41: － | V41: ↑数値のみ入力でＯＫ | X41: ▼ ▼ ▼ ▼ | AC41: 幸運 | AE41: 運が試される際の判定技能。
...

Sheet 応用技
B2: 能力応用技 ※応用技は最大８個まで | M2: 行為発動・特殊技 ※フレーバーの行為発動や、技組合せのチェイン発動、 ＡＥ・ＳＰＥを演出の特殊技、特殊武装などをフレーバー技として明記したい場合に入力下さい。
B4: 発動スペック | D4: =キャラシート!H27-D5 -> 2 | E4: 防御発動量 | G4: =ROUNDDOWN((キャラシート!H25)/2,0) -> 2 | H4: 付加補正量 | J4: =ROUNDDOWN((キャラシート!H25)/3,0) -> 1
B5: スペック圧迫分 | D5: =IF(キャラシート!I3="蟹",計算用!E99,計算用!E98)+IF(キャラシート!B40="－","0",VLOOKUP(キャラシート!B40,リスト!$AH$3:$AI$43,2,FALSE))+IF(キャラシート!B41="－","0",VLOOKUP(キャラシート!B41,リスト!$AH$3:$AI$43,2,FALSE()))+IF(キャラシート!B42="－","0",VLOOKUP(キャラシート!B42,リスト!$AH$3:$AI$43,2,FALSE()))+IF(キャラシート!B43="－","0",VLOOKUP(キャラシート!B43,リスト!$AH$3:$AI$43,2,FALSE()))+IF(キャラシート!B44="－","0",VLOOKUP(キャラシート!B44,リスト!$AH$3:$AI$43,2,FALSE()))+IF(キャラシート!B45="－","0",VLOOKUP(キャラシート!B45,リスト!$AH$3:$AI$43,2,FALSE()))+IF(キャラシート!B46="－","0",VLOOKUP(キャラシート!B46,リスト!$AH$3:$AI$43,2,FALSE()))+IF(キャラシート!B47="－","0",VLOOKUP(キャラシート!B47,リスト!$AH$3:$AI$43,2,FALSE()))+IF(キャラシート!B48="－","0",VLOOKUP(キャラシート!B48,リスト!$AH$3:$AI$43,2,FALSE()))+IF(キャラシート!B49="－","0",VLOOKUP(キャラシート!B49,リスト!$AH$3:$AI$43,2,FALSE()))+IF(キャラシート!B50="－","0",VLOOKUP(キャラシート!B50,リスト!$AH$3:$AI$43,2,FALSE()))+IF(キャラシート!B51="－","0",VLOOKUP(キャラシート!B51,リスト!$AH$3:$AI$43,2,FALSE)) -> 0
B8: 技名 | G8: 射程 | H8: 技系統 | I8: 消費 | J8: 必要スペック | M8: 技名 | R8: 演出 | T8: 射程 | U8: 消費
G9: － | H9: － | I9: =IF(キャラシート!$I$3="蟹",計算用!C12,計算用!C6) -> 0 | J9: =IF(キャラシート!$I$3="蟹",計算用!D12,計算用!D6) -> 0 | R9: － | T9: －
B11: 発動系統 | E11: 付加効果 | H11: ＳＥ
B12: － | C12: － | D12: － | E12: － | F12: － | G12: － | H12: － | I12: － | J12: － | M12: 効果補足
E13: － | F13: － | G13: － | H13: － | I13: － | J13: －
B14: 効果補足
B17: ※この行には具体的な補正量やトリガー条件などをお書き下さい。 | M17: ※この行には具体的な効果やチェイン発動の組合せをお書き下さい。
B19: 技名 | G19: 射程 | H19: 技系統 | I19: 消費 | J19: 必要スペック | M19: 技名 | R19: 演出 | T19: 射程 | U19: 消費
G20: － | H20: － | I20: =IF(キャラシート!$I$3="蟹",計算用!C24,計算用!C18) -> 0 | J20: =IF(キャラシート!$I$3="蟹",計算用!D24,計算用!D18) -> 0 | R20: － | T20: －
B22: 発動系統 | E22: 付加効果 | H22: ＳＥ
B23: － | C23: － | D23: － | E23: － | F23: － | G23: － | H23: － | I23: － | J23: － | M23: 効果補足
E24: － | F24: － | G24: － | H24: － | I24: － | J24: －
B25: 効果補足
B28: ※この行には具体的な補正量やトリガー条件などをお書き下さい。 | M28: ※この行には具体的な効果やチェイン発動の組合せをお書き下さい。
B30: 技名 | G30: 射程 | H30: 技系統 | I30: 消費 | J30: 必要スペック | M30: 技名 | R30: 演出 | T30: 射程 | U30: 消費
G31: － | H31: － | I31: =IF(キャラシート!$I$3="蟹",計算用!C36,計算用!C30) -> 0 | J31: =IF(キャラシート!$I$3="蟹",計算用!D36,計算用!D30) -> 0 | R31: － | T31: －
B33: 発動系統 | E33: 付加効果 | H33: ＳＥ
B34: － | C34: － | D34: － | E34: － | F34: － | G34: － | H34: － | I34: － | J34: － | M34: 効果補足
E35: － | F35: － | G35: － | H35: － | I35: － | J35: －
B36: 効果補足
B39: ※この行には具体的な補正量やトリガー条件などをお書き下さい。 | M39: ※この行には具体的な効果やチェイン発動の組合せをお書き下さい。
B41: 技名 | G41: 射程 | H41: 技系統 | I41: 消費 | J41: 必要スペック | M41: 技名 | R41: 演出 | T41: 射程 | U41: 消費
G42: － | H42: － | I42: =IF(キャラシート!$I$3="蟹",計算用!C48,計算用!C42) -> 0 | J42: =IF(キャラシート!$I$3="蟹",計算用!D48,計算用!D42) -> 0 | R42: － | T42: －
B44: 発動系統 | E44: 付加効果 | H44: ＳＥ
B45: － | C45: － | D45: － | E45: － | F45: － | G45: － | H45: － | I45: － | J45: － | M45: 効果補足
E46: － | F46: － | G46: － | H46: － | I46: － | J46: －
B47: 効果補足
B50: ※この行には具体的な補正量やトリガー条件などをお書き下さい。 | M50: ※この行には具体的な効果やチェイン発動の組合せをお書き下さい。
B52: 技名 | G52: 射程 | H52: 技系統 | I52: 消費 | J52: 必要スペック | M52: 技名 | R52: 演出 | T52: 射程 | U52: 消費
G53: － | H53: － | I53: =IF(キャラシート!$I$3="蟹",計算用!C60,計算用!C54) -> 0 | J53: =IF(キャラシート!$I$3="蟹",計算用!D60,計算用!D54) -> 0 | R53: － | T53: －
B55: 発動系統 | E55: 付加効果 | H55: ＳＥ
B56: － | C56: － | D56: － | E56: － | F56: － | G56: － | H56: － | I56: － | J56: － | M56: 効果補足
E57: － | F57: － | G57: － | H57: － | I57: － | J57: －
B58: 効果補足
B61: ※この行には具体的な補正量やトリガー条件などをお書き下さい。 | M61: ※この行には具体的な効果やチェイン発動の組合せをお書き下さい。
B63: 技名 | G63: 射程 | H63: 技系統 | I63: 消費 | J63: 必要スペック | M63: 技名 | R63: 演出 | T63: 射程 | U63: 消費
G64: － | H64: － | I64: =IF(キャラシート!$I$3="蟹",計算用!C72,計算用!C66) -> 0 | J64: =IF(キャラシート!$I$3="蟹",計算用!D72,計算用!D66) -> 0 | R64: － | T64: －
...

Sheet 計算用
B1: 応用技 | AG1: クリーチャー＿１ | AN1: クリーチャー＿２ | AU1: クリーチャー＿３
B2: 技１ | C2: 消費 | D2: スペック | E2: 圧迫 | F2: 強化変数 | G2: 減衰変数 | I2: バニラ表 | U2: カニ表 | AG2: 技１ | AH2: 消費 | AI2: スペック | AJ2: 圧迫 | AK2: 強化変数 | AL2: 減衰変数 | AN2: 技１ | AO2: 消費 | AP2: スペック | AQ2: 圧迫 | AR2: 強化変数 | AS2: 減衰変数 | AU2: 技１ | AV2: 消費 | AW2: スペック | AX2: 圧迫 | AY2: 強化変数 | AZ2: 減衰変数
B3: 発動系統 | C3: =IF(応用技!B12="－","0",VLOOKUP(応用技!B12,計算用!$J$6:$L$11,2,FALSE())) +IF(応用技!C12="－","0",VLOOKUP(応用技!C12,計算用!$J$6:$L$11,2,FALSE())) +IF(応用技!D12="－","0",VLOOKUP(応用技!D12,計算用!$J$6:$L$11,2,FALSE())) +COUNTIF(応用技!B12:D12,"防御発動")^2 -> 0 | D3: =IF(応用技!B12="－","0",VLOOKUP(応用技!B12,$J$6:$L$11,3,FALSE())) +IF(応用技!C12="－","0",VLOOKUP(応用技!C12,$J$6:$L$11,3,FALSE())) +IF(応用技!D12="－","0",VLOOKUP(応用技!D12,$J$6:$L$11,3,FALSE())) -> 0 | AG3: 発動系統 | AH3: =IF(クリーチャー!P12="－","0",VLOOKUP(クリーチャー!P12,計算用!$J$6:$L$11,2,FALSE()))+IF(クリーチャー!Q12="－","0",VLOOKUP(クリーチャー!Q12,計算用!$J$6:$L$11,2,FALSE()))+IF(クリーチャー!R12="－","0",VLOOKUP(クリーチャー!R12,計算用!$J$6:$L$11,2,FALSE()))+COUNTIF(クリーチャー!P12:R12,"防御発動")^2 -> 0 | AI3: =IF(クリーチャー!P12="－","0",VLOOKUP(クリーチャー!P12,$J$6:$L$11,3,FALSE()))+IF(クリーチャー!Q12="－","0",VLOOKUP(クリーチャー!Q12,$J$6:$L$11,3,FALSE()))+IF(クリーチャー!R12="－","0",VLOOKUP(クリーチャー!R12,$J$6:$L$11,3,FALSE())) -> 0 | AN3: 発動系統 | AO3: =IF(クリーチャー_2!P12="－","0",VLOOKUP(クリーチャー_2!P12,計算用!$J$6:$L$11,2,FALSE()))+IF(クリーチャー_2!Q12="－","0",VLOOKUP(クリーチャー_2!Q12,計算用!$J$6:$L$11,2,FALSE()))+IF(クリーチャー_2!R12="－","0",VLOOKUP(クリーチャー_2!R12,計算用!$J$6:$L$11,2,FALSE()))+COUNTIF(クリーチャー_2!P12:R12,"防御発動")^2 -> 0 | AP3: =IF(クリーチャー_2!P12="－","0",VLOOKUP(クリーチャー_2!P12,$J$6:$L$11,3,FALSE()))+IF(クリーチャー_2!Q12="－","0",VLOOKUP(クリーチャー_2!Q12,$J$6:$L$11,3,FALSE()))+IF(クリーチャー_2!R12="－","0",VLOOKUP(クリーチャー_2!R12,$J$6:$L$11,3,FALSE())) -> 0 | AU3: 発動系統 | AV3: =IF(クリーチャー_3!P12="－","0",VLOOKUP(クリーチャー_3!P12,計算用!$J$6:$L$11,2,FALSE()))+IF(クリーチャー_3!Q12="－","0",VLOOKUP(クリーチャー_3!Q12,計算用!$J$6:$L$11,2,FALSE()))+IF(クリーチャー_3!R12="－","0",VLOOKUP(クリーチャー_3!R12,計算用!$J$6:$L$11,2,FALSE()))+COUNTIF(クリーチャー_3!P12:R12,"防御発動")^2 -> 0 | AW3: =IF(クリーチャー_3!P12="－","0",VLOOKUP(クリーチャー_3!P12,$J$6:$L$11,3,FALSE()))+IF(クリーチャー_3!Q12="－","0",VLOOKUP(クリーチャー_3!Q12,$J$6:$L$11,3,FALSE()))+IF(クリーチャー_3!R12="－","0",VLOOKUP(クリーチャー_3!R12,$J$6:$L$11,3,FALSE())) -> 0
B4: 付加効果 | C4: {=IF(応用技!E12="－","0",VLOOKUP(応用技!E12,$N$6:$R$49,2,FALSE()))+IF(応用技!F12="－","0",VLOOKUP(応用技!F12,N6:$R$49,2,FALSE()))+IF(応用技!G12="－","0",VLOOKUP(応用技!G12,$N$6:$R$49,2,FALSE()))+IF(応用技!E13="－","0",VLOOKUP(応用技!E13,$N$6:$R$49,2,FALSE()))+IF(応用技!F13="－","0",VLOOKUP(応用技!F13,$N$6:$R$49,2,FALSE()))+IF(応用技!G13="－","0",VLOOKUP(応用技!G13,$N$6:$R$49,2,FALSE()))+_xlfn.IFS(F4>=2,1+2*(F4-1),F4=1,1,F4=0,0)+_xlfn.IFS(G4>=2,1+2*(G4-1),G4=1,1,G4=0,0)} -> 0 | D4: =IF(応用技!E12="－","0",VLOOKUP(応用技!E12,$N$6:$R$49,3,FALSE())) +IF(応用技!F12="－","0",VLOOKUP(応用技!F12,$N$6:$R$49,3,FALSE())) +IF(応用技!G12="－","0",VLOOKUP(応用技!G12,$N$6:$R$49,3,FALSE())) +IF(応用技!E13="－","0",VLOOKUP(応用技!E13,$N$6:$R$49,3,FALSE())) +IF(応用技!F13="－","0",VLOOKUP(応用技!F13,$N$6:$R$49,3,FALSE())) +IF(応用技!G13="－","0",VLOOKUP(応用技!G13,$N$6:$R$49,3,FALSE())) -> 0 | E4: =IF(応用技!E12="－","0",VLOOKUP(応用技!E12,$N$6:$R$49,4,FALSE())) +IF(応用技!F12="－","0",VLOOKUP(応用技!F12,$N$6:$R$49,4,FALSE())) +IF(応用技!G12="－","0",VLOOKUP(応用技!G12,$N$6:$R$49,4,FALSE())) +IF(応用技!E13="－","0",VLOOKUP(応用技!E13,$N$6:$R$49,4,FALSE())) +IF(応用技!F13="－","0",VLOOKUP(応用技!F13,$N$6:$R$49,4,FALSE())) +IF(応用技!G13="－","0",VLOOKUP(応用技!G13,$N$6:$R$49,4,FALSE())) -> 0 | F4: =COUNTIFS(応用技!E12:G13,"強化*") -> 0 | G4: =COUNTIFS(応用技!E12:G13,"減衰*") -> 0 | J4: 発動系統 | N4: 付加効果 | V4: 発動系統 | Z4: 付加効果 | AG4: 付加効果 | AH4: {=IF(クリーチャー!S12="－","0",VLOOKUP(クリーチャー!S12,$N$6:$R$49,2,FALSE()))+IF(クリーチャー!T12="－","0",VLOOKUP(クリーチャー!T12,N6:$R$49,2,FALSE()))+IF(クリーチャー!U12="－","0",VLOOKUP(クリーチャー!U12,$N$6:$R$49,2,FALSE()))+IF(クリーチャー!S13="－","0",VLOOKUP(クリーチャー!S13,$N$6:$R$49,2,FALSE()))+IF(クリーチャー!T13="－","0",VLOOKUP(クリーチャー!T13,$N$6:$R$49,2,FALSE()))+IF(クリーチャー!U13="－","0",VLOOKUP(クリーチャー!U13,$N$6:$R$49,2,FALSE()))+_xlfn.IFS(AK4>=2,1+2*(AK4-1),AK4=1,1,AK4=0,0)+_xlfn.IFS(AL4>=2,1+2*(AL4-1),AL4=1,1,AL4=0,0)} -> 0 | AI4: =IF(クリーチャー!S12="－","0",VLOOKUP(クリーチャー!S12,$N$6:$R$49,3,FALSE()))+IF(クリーチャー!T12="－","0",VLOOKUP(クリーチャー!T12,$N$6:$R$49,3,FALSE()))+IF(クリーチャー!U12="－","0",VLOOKUP(クリーチャー!U12,$N$6:$R$49,3,FALSE()))+IF(クリーチャー!S13="－","0",VLOOKUP(クリーチャー!S13,$N$6:$R$49,3,FALSE()))+IF(クリーチャー!T13="－","0",VLOOKUP(クリーチャー!T13,$N$6:$R$49,3,FALSE()))+IF(クリーチャー!U13="－","0",VLOOKUP(クリーチャー!U13,$N$6:$R$49,3,FALSE())) -> 0 | AJ4: =IF(クリーチャー!S12="－","0",VLOOKUP(クリーチャー!S12,$N$6:$R$49,4,FALSE()))+IF(クリーチャー!T12="－","0",VLOOKUP(クリーチャー!T12,$N$6:$R$49,4,FALSE()))+IF(クリーチャー!U12="－","0",VLOOKUP(クリーチャー!U12,$N$6:$R$49,4,FALSE()))+IF(クリーチャー!S13="－","0",VLOOKUP(クリーチャー!S13,$N$6:$R$49,4,FALSE()))+IF(クリーチャー!T13="－","0",VLOOKUP(クリーチャー!T13,$N$6:$R$49,4,FALSE()))+IF(クリーチャー!U13="－","0",VLOOKUP(クリーチャー!U13,$N$6:$R$49,4,FALSE())) -> 0 | AK4: =COUNTIFS(クリーチャー!S12:U13,"強化*") -> 0 | AL4: =COUNTIFS(クリーチャー!S12:U13,"減衰*") -> 0 | AN4: 付加効果 | AO4: {=IF(クリーチャー_2!S12="－","0",VLOOKUP(クリーチャー_2!S12,$N$6:$R$49,2,FALSE()))+IF(クリーチャー_2!T12="－","0",VLOOKUP(クリーチャー_2!T12,$N$6:$R$49,2,FALSE()))+IF(クリーチャー_2!U12="－","0",VLOOKUP(クリーチャー_2!U12,$N$6:$R$49,2,FALSE()))+IF(クリーチャー_2!S13="－","0",VLOOKUP(クリーチャー_2!S13,$N$6:$R$49,2,FALSE()))+IF(クリーチャー_2!T13="－","0",VLOOKUP(クリーチャー_2!T13,$N$6:$R$49,2,FALSE()))+IF(クリーチャー_2!U13="－","0",VLOOKUP(クリーチャー_2!U13,$N$6:$R$49,2,FALSE()))+_xlfn.IFS(AR4>=2,1+2*(AR4-1),AR4=1,1,AR4=0,0)+_xlfn.IFS(AS4>=2,1+2*(AS4-1),AS4=1,1,AS4=0,0)} -> 0 | AP4: =IF(クリーチャー_2!S12="－","0",VLOOKUP(クリーチャー_2!S12,$N$6:$R$49,3,FALSE()))+IF(クリーチャー_2!T12="－","0",VLOOKUP(クリーチャー_2!T12,$N$6:$R$49,3,FALSE()))+IF(クリーチャー_2!U12="－","0",VLOOKUP(クリーチャー_2!U12,$N$6:$R$49,3,FALSE()))+IF(クリーチャー_2!S13="－","0",VLOOKUP(クリーチャー_2!S13,$N$6:$R$49,3,FALSE()))+IF(クリーチャー_2!T13="－","0",VLOOKUP(クリーチャー_2!T13,$N$6:$R$49,3,FALSE()))+IF(クリーチャー_2!U13="－","0",VLOOKUP(クリーチャー_2!U13,$N$6:$R$49,3,FALSE())) -> 0 | AQ4: =IF(クリーチャー_2!S12="－","0",VLOOKUP(クリーチャー_2!S12,$N$6:$R$49,4,FALSE()))+IF(クリーチャー_2!T12="－","0",VLOOKUP(クリーチャー_2!T12,$N$6:$R$49,4,FALSE()))+IF(クリーチャー_2!U12="－","0",VLOOKUP(クリーチャー_2!U12,$N$6:$R$49,4,FALSE()))+IF(クリーチャー_2!S13="－","0",VLOOKUP(クリーチャー_2!S13,$N$6:$R$49,4,FALSE()))+IF(クリーチャー_2!T13="－","0",VLOOKUP(クリーチャー_2!T13,$N$6:$R$49,4,FALSE()))+IF(クリーチャー_2!U13="－","0",VLOOKUP(クリーチャー_2!U13,$N$6:$R$49,4,FALSE())) -> 0 | AR4: =COUNTIFS(クリーチャー_2!S12:U13,"強化*") -> 0 | AS4: =COUNTIFS(クリーチャー_2!S12:U13,"減衰*") -> 0 | AU4: 付加効果 | AV4: {=IF(クリーチャー_3!S12="－","0",VLOOKUP(クリーチャー_3!S12,$N$6:$R$49,2,FALSE()))+IF(クリーチャー_3!T12="－","0",VLOOKUP(クリーチャー_3!T12,N6:$R$49,2,FALSE()))+IF(クリーチャー_3!U12="－","0",VLOOKUP(クリーチャー_3!U12,$N$6:$R$49,2,FALSE()))+IF(クリーチャー_3!S13="－","0",VLOOKUP(クリーチャー_3!S13,$N$6:$R$49,2,FALSE()))+IF(クリーチャー_3!T13="－","0",VLOOKUP(クリーチャー_3!T13,$N$6:$R$49,2,FALSE()))+IF(クリーチャー_3!U13="－","0",VLOOKUP(クリーチャー_3!U13,$N$6:$R$49,2,FALSE()))+_xlfn.IFS(AY4>=2,1+2*(AY4-1),AY4=1,1,AY4=0,0)+_xlfn.IFS(AZ4>=2,1+2*(AZ4-1),AZ4=1,1,AZ4=0,0)} -> 0 | AW4: =IF(クリーチャー_3!S12="－","0",VLOOKUP(クリーチャー_3!S12,$N$6:$R$49,3,FALSE()))+IF(クリーチャー_3!T12="－","0",VLOOKUP(クリーチャー_3!T12,$N$6:$R$49,3,FALSE()))+IF(クリーチャー_3!U12="－","0",VLOOKUP(クリーチャー_3!U12,$N$6:$R$49,3,FALSE()))+IF(クリーチャー_3!S13="－","0",VLOOKUP(クリーチャー_3!S13,$N$6:$R$49,3,FALSE()))+IF(クリーチャー_3!T13="－","0",VLOOKUP(クリーチャー_3!T13,$N$6:$R$49,3,FALSE()))+IF(クリーチャー_3!U13="－","0",VLOOKUP(クリーチャー_3!U13,$N$6:$R$49,3,FALSE())) -> 0 | AX4: =IF(クリーチャー_3!S12="－","0",VLOOKUP(クリーチャー_3!S12,$N$6:$R$49,4,FALSE()))+IF(クリーチャー_3!T12="－","0",VLOOKUP(クリーチャー_3!T12,$N$6:$R$49,4,FALSE()))+IF(クリーチャー_3!U12="－","0",VLOOKUP(クリーチャー_3!U12,$N$6:$R$49,4,FALSE()))+IF(クリーチャー_3!S13="－","0",VLOOKUP(クリーチャー_3!S13,$N$6:$R$49,4,FALSE()))+IF(クリーチャー_3!T13="－","0",VLOOKUP(クリーチャー_3!T13,$N$6:$R$49,4,FALSE()))+IF(クリーチャー_3!U13="－","0",VLOOKUP(クリーチャー_3!U13,$N$6:$R$49,4,FALSE())) -> 0 | AY4: =COUNTIFS(クリーチャー_3!S12:U13,"強化*") -> 0 | AZ4: =COUNTIFS(クリーチャー_3!S12:U13,"減衰*") -> 0
B5: SE | C5: =IF(応用技!H12="－","0",VLOOKUP(応用技!H12,$J$15:$L$27,2,FALSE())) +IF(応用技!I12="－","0",VLOOKUP(応用技!I12,$J$15:$L$27,2,FALSE())) +IF(応用技!J12="－","0",VLOOKUP(応用技!J12,$J$15:$L$27,2,FALSE())) +IF(応用技!H13="－","0",VLOOKUP(応用技!H13,$J$15:$L$27,2,FALSE())) +IF(応用技!I13="－","0",VLOOKUP(応用技!I13,$J$15:$L$27,2,FALSE())) +IF(応用技!J13="－","0",VLOOKUP(応用技!J13,$J$15:$L$27,2,FALSE())) -> 0 | D5: =IF(応用技!H12="－","0",VLOOKUP(応用技!H12,$J$15:$L$27,3,FALSE())) +IF(応用技!I12="－","0",VLOOKUP(応用技!I12,$J$15:$L$27,3,FALSE())) +IF(応用技!J12="－","0",VLOOKUP(応用技!J12,$J$15:$L$27,3,FALSE())) +IF(応用技!H13="－","0",VLOOKUP(応用技!H13,$J$15:$L$27,3,FALSE())) +IF(応用技!I13="－","0",VLOOKUP(応用技!I13,$J$15:$L$27,3,FALSE())) +IF(応用技!J13="－","0",VLOOKUP(応用技!J13,$J$15:$L$27,3,FALSE())) -> 0 | J5: 名称 | K5: 消費 | L5: スペック | N5: 名称 | O5: 消費 | P5: スペック | Q5: 圧迫 | R5: 特殊 | V5: 名称 | W5: 消費 | X5: スペック | Z5: 名称 | AA5: 消費 | AB5: スペック | AC5: 圧迫 | AD5: 特殊 | AG5: SE | AH5: =IF(クリーチャー!V12="－","0",VLOOKUP(クリーチャー!V12,$J$15:$L$27,2,FALSE()))+IF(クリーチャー!W12="－","0",VLOOKUP(クリーチャー!W12,$J$15:$L$27,2,FALSE()))+IF(クリーチャー!X12="－","0",VLOOKUP(クリーチャー!X12,$J$15:$L$27,2,FALSE()))+IF(クリーチャー!V13="－","0",VLOOKUP(クリーチャー!V13,$J$15:$L$27,2,FALSE()))+IF(クリーチャー!W13="－","0",VLOOKUP(クリーチャー!W13,$J$15:$L$27,2,FALSE()))+IF(クリーチャー!X13="－","0",VLOOKUP(クリーチャー!X13,$J$15:$L$27,2,FALSE())) -> 0 | AI5: =IF(クリーチャー!V12="－","0",VLOOKUP(クリーチャー!V12,$J$15:$L$27,3,FALSE()))+IF(クリーチャー!W12="－","0",VLOOKUP(クリーチャー!W12,$J$15:$L$27,3,FALSE()))+IF(クリーチャー!X12="－","0",VLOOKUP(クリーチャー!X12,$J$15:$L$27,3,FALSE()))+IF(クリーチャー!V13="－","0",VLOOKUP(クリーチャー!V13,$J$15:$L$27,3,FALSE()))+IF(クリーチャー!W13="－","0",VLOOKUP(クリーチャー!W13,$J$15:$L$27,3,FALSE()))+IF(クリーチャー!X13="－","0",VLOOKUP(クリーチャー!X13,$J$15:$L$27,3,FALSE())) -> 0 | AN5: SE | AO5: =IF(クリーチャー_2!V12="－","0",VLOOKUP(クリーチャー_2!V12,$J$15:$L$27,2,FALSE()))+IF(クリーチャー_2!W12="－","0",VLOOKUP(クリーチャー_2!W12,$J$15:$L$27,2,FALSE()))+IF(クリーチャー_2!X12="－","0",VLOOKUP(クリーチャー_2!X12,$J$15:$L$27,2,FALSE()))+IF(クリーチャー_2!V13="－","0",VLOOKUP(クリーチャー_2!V13,$J$15:$L$27,2,FALSE()))+IF(クリーチャー_2!W13="－","0",VLOOKUP(クリーチャー_2!W13,$J$15:$L$27,2,FALSE()))+IF(クリーチャー_2!X13="－","0",VLOOKUP(クリーチャー_2!X13,$J$15:$L$27,2,FALSE())) -> 0 | AP5: =IF(クリーチャー_2!V12="－","0",VLOOKUP(クリーチャー_2!V12,$J$15:$L$27,3,FALSE()))+IF(クリーチャー_2!W12="－","0",VLOOKUP(クリーチャー_2!W12,$J$15:$L$27,3,FALSE()))+IF(クリーチャー_2!X12="－","0",VLOOKUP(クリーチャー_2!X12,$J$15:$L$27,3,FALSE()))+IF(クリーチャー_2!V13="－","0",VLOOKUP(クリーチャー_2!V13,$J$15:$L$27,3,FALSE()))+IF(クリーチャー_2!W13="－","0",VLOOKUP(クリーチャー_2!W13,$J$15:$L$27,3,FALSE()))+IF(クリーチャー_2!X13="－","0",VLOOKUP(クリーチャー_2!X13,$J$15:$L$27,3,FALSE())) -> 0 | AU5: SE | AV5: =IF(クリーチャー_3!V12="－","0",VLOOKUP(クリーチャー_3!V12,$J$15:$L$27,2,FALSE()))+IF(クリーチャー_3!W12="－","0",VLOOKUP(クリーチャー_3!W12,$J$15:$L$27,2,FALSE()))+IF(クリーチャー_3!X12="－","0",VLOOKUP(クリーチャー_3!X12,$J$15:$L$27,2,FALSE()))+IF(クリーチャー_3!V13="－","0",VLOOKUP(クリーチャー_3!V13,$J$15:$L$27,2,FALSE()))+IF(クリーチャー_3!W13="－","0",VLOOKUP(クリーチャー_3!W13,$J$15:$L$27,2,FALSE()))+IF(クリーチャー_3!X13="－","0",VLOOKUP(クリーチャー_3!X13,$J$15:$L$27,2,FALSE())) -> 0 | AW5: =IF(クリーチャー_3!V12="－","0",VLOOKUP(クリーチャー_3!V12,$J$15:$L$27,3,FALSE()))+IF(クリーチャー_3!W12="－","0",VLOOKUP(クリーチャー_3!W12,$J$15:$L$27,3,FALSE()))+IF(クリーチャー_3!X12="－","0",VLOOKUP(クリーチャー_3!X12,$J$15:$L$27,3,FALSE()))+IF(クリーチャー_3!V13="－","0",VLOOKUP(クリーチャー_3!V13,$J$15:$L$27,3,FALSE()))+IF(クリーチャー_3!W13="－","0",VLOOKUP(クリーチャー_3!W13,$J$15:$L$27,3,FALSE()))+IF(クリーチャー_3!X13="－","0",VLOOKUP(クリーチャー_3!X13,$J$15:$L$27,3,FALSE())) -> 0
B6: 合計 | C6: {=_xlfn.IFS(COUNTIF(応用技!E12:G13,"創造")>=1,SUM(C3:C5)+1&"～"&SUM(C3:C5)+10, COUNTIF(応用技!E12:G13,"限定*")>=1,"※", COUNTIF(応用技!E12:G13,"影響無効")>=1,"※",TRUE(),SUM(C3:C5))} -> 0 | D6: =SUM(D3:D5) -> 0 | E6: =SUM(E3:E5) -> 0 | J6: 攻撃発動 | K6: 1 | L6: 1 | N6: 強化【行】 | O6: 0 | P6: 1 | R6: 強化系 | V6: 攻撃発動 | W6: 1 | X6: 1 | Z6: 強化【行】 | AA6: 0 | AB6: 1 | AD6: 強化系 | AG6: 合計 | AH6: {=_xlfn.IFS(COUNTIF(クリーチャー!S12:U13,"創造")>=1,SUM(AH3:AH5)+1&"～"&SUM(AH3:AH5)+10,COUNTIF(クリーチャー!S12:U13,"限定*")>=1,"※",COUNTIF(クリーチャー!S12:U13,"影響無効")>=1,"※",TRUE(),SUM(AH3:AH5))} -> 0 | AI6: =SUM(AI3:AI5) -> 0 | AJ6: =SUM(AJ3:AJ5) -> 0 | AN6: 合計 | AO6: {=_xlfn.IFS(COUNTIF(クリーチャー_2!S12:U13,"創造")>=1,SUM(AO3:AO5)+1&"～"&SUM(AO3:AO5)+10,COUNTIF(クリーチャー_2!S12:U13,"限定*")>=1,"※",COUNTIF(クリーチャー_2!S12:U13,"影響無効")>=1,"※",TRUE(),SUM(AO3:AO5))} -> 0 | AP6: =SUM(AP3:AP5) -> 0 | AQ6: =SUM(AQ3:AQ5) -> 0 | AU6: 合計 | AV6: {=_xlfn.IFS(COUNTIF(クリーチャー_3!S12:U13,"創造")>=1,SUM(AV3:AV5)+1&"～"&SUM(AV3:AV5)+10,COUNTIF(クリーチャー_3!S12:U13,"限定*")>=1,"※",COUNTIF(クリーチャー_3!S12:U13,"影響無効")>=1,"※",TRUE(),SUM(AV3:AV5))} -> 0 | AW6: =SUM(AW3:AW5) -> 0 | AX6: =SUM(AX3:AX5) -> 0
J7: 精神発動 | K7: 1 | L7: 0 | N7: 強化【攻】 | O7: 0 | P7: 1 | R7: 強化系 | V7: 精神発動 | W7: 1 | X7: 0 | Z7: 強化【攻】 | AA7: 0 | AB7: 1 | AD7: 強化系
B8: 技１（蟹） | C8: 消費 | D8: スペック | E8: 圧迫 | F8: 強化変数 | G8: 減衰変数 | J8: 防御発動 | K8: 0 | L8: 1 | N8: 強化【防】 | O8: 0 | P8: 1 | R8: 強化系 | V8: 防御発動 | W8: 0 | X8: 1 | Z8: 強化【防】 | AA8: 0 | AB8: 1 | AD8: 強化系 | AG8: 技１（蟹） | AH8: 消費 | AI8: スペック | AJ8: 圧迫 | AK8: 強化変数 | AL8: 減衰変数 | AN8: 技１（蟹） | AO8: 消費 | AP8: スペック | AQ8: 圧迫 | AR8: 強化変数 | AS8: 減衰変数 | AU8: 技１（蟹） | AV8: 消費 | AW8: スペック | AX8: 圧迫 | AY8: 強化変数 | AZ8: 減衰変数
B9: 発動系統 | C9: =IF(応用技!B12="－","0",VLOOKUP(応用技!B12,計算用!$V$6:$X$11,2,FALSE())) +IF(応用技!C12="－","0",VLOOKUP(応用技!C12,計算用!$V$6:$X$11,2,FALSE())) +IF(応用技!D12="－","0",VLOOKUP(応用技!D12,計算用!$V$6:$X$11,2,FALSE())) +COUNTIF(応用技!B12:D12,"防御発動")^2 -> 0 | D9: =IF(応用技!B12="－","0",VLOOKUP(応用技!B12,$J$6:$L$11,3,FALSE())) +IF(応用技!C12="－","0",VLOOKUP(応用技!C12,$J$6:$L$11,3,FALSE())) +IF(応用技!D12="－","0",VLOOKUP(応用技!D12,$J$6:$L$11,3,FALSE())) -> 0 | J9: 付加発動 | K9: 0 | L9: 1 | N9: 強化【抵】 | O9: 0 | P9: 1 | R9: 強化系 | V9: 付加発動 | W9: 0 | X9: 1 | Z9: 強化【抵】 | AA9: 0 | AB9: 1 | AD9: 強化系 | AG9: 発動系統 | AH9: =IF(クリーチャー!P12="－","0",VLOOKUP(クリーチャー!P12,計算用!$V$6:$X$11,2,FALSE()))+IF(クリーチャー!Q12="－","0",VLOOKUP(クリーチャー!Q12,計算用!$V$6:$X$11,2,FALSE()))+IF(クリーチャー!R12="－","0",VLOOKUP(クリーチャー!R12,計算用!$V$6:$X$11,2,FALSE()))+COUNTIF(クリーチャー!P12:R12,"防御発動")^2 -> 0 | AI9: =IF(クリーチャー!P12="－","0",VLOOKUP(クリーチャー!P12,$J$6:$L$11,3,FALSE()))+IF(クリーチャー!Q12="－","0",VLOOKUP(クリーチャー!Q12,$J$6:$L$11,3,FALSE()))+IF(クリーチャー!R12="－","0",VLOOKUP(クリーチャー!R12,$J$6:$L$11,3,FALSE())) -> 0 | AN9: 発動系統 | AO9: =IF(クリーチャー_2!P12="－","0",VLOOKUP(クリーチャー_2!P12,計算用!$V$6:$X$11,2,FALSE()))+IF(クリーチャー_2!Q12="－","0",VLOOKUP(クリーチャー_2!Q12,計算用!$V$6:$X$11,2,FALSE()))+IF(クリーチャー_2!R12="－","0",VLOOKUP(クリーチャー_2!R12,計算用!$V$6:$X$11,2,FALSE())) -> 0 | AP9: =IF(クリーチャー_2!P12="－","0",VLOOKUP(クリーチャー_2!P12,$J$6:$L$11,3,FALSE()))+IF(クリーチャー_2!Q12="－","0",VLOOKUP(クリーチャー_2!Q12,$J$6:$L$11,3,FALSE()))+IF(クリーチャー_2!R12="－","0",VLOOKUP(クリーチャー_2!R12,$J$6:$L$11,3,FALSE())) -> 0 | AU9: 発動系統 | AV9: =IF(クリーチャー_3!P12="－","0",VLOOKUP(クリーチャー_3!P12,計算用!$V$6:$X$11,2,FALSE()))+IF(クリーチャー_3!Q12="－","0",VLOOKUP(クリーチャー_3!Q12,計算用!$V$6:$X$11,2,FALSE()))+IF(クリーチャー_3!R12="－","0",VLOOKUP(クリーチャー_3!R12,計算用!$V$6:$X$11,2,FALSE()))+COUNTIF(クリーチャー_3!P12:R12,"防御発動")^2 -> 0 | AW9: =IF(クリーチャー_3!P12="－","0",VLOOKUP(クリーチャー_3!P12,$J$6:$L$11,3,FALSE()))+IF(クリーチャー_3!Q12="－","0",VLOOKUP(クリーチャー_3!Q12,$J$6:$L$11,3,FALSE()))+IF(クリーチャー_3!R12="－","0",VLOOKUP(クリーチャー_3!R12,$J$6:$L$11,3,FALSE())) -> 0
B10: 付加効果 | C10: {=IF(応用技!E12="－","0",VLOOKUP(応用技!E12,$Z$6:$AD$57,2,FALSE())) +IF(応用技!F12="－","0",VLOOKUP(応用技!F12,$Z$6:$AD$57,2,FALSE())) +IF(応用技!G12="－","0",VLOOKUP(応用技!G12,$Z$6:$AD$57,2,FALSE())) +IF(応用技!E13="－","0",VLOOKUP(応用技!E13,$Z$6:$AD$57,2,FALSE())) +IF(応用技!F13="－","0",VLOOKUP(応用技!F13,$Z$6:$AD$57,2,FALSE())) +IF(応用技!G13="－","0",VLOOKUP(応用技!G13,$Z$6:$AD$57,2,FALSE())) +_xlfn.IFS(F10>=2,1+2*(F10-1),F10=1,1,F10=0,0)+_xlfn.IFS(G10>=2,1+2*(G10-1),G10=1,1,G10=0,0)} -> 0 | D10: =IF(応用技!E12="－","0",VLOOKUP(応用技!E12,$Z$6:$AD$57,3,FALSE())) +IF(応用技!F12="－","0",VLOOKUP(応用技!F12,$Z$6:$AD$57,3,FALSE())) +IF(応用技!G12="－","0",VLOOKUP(応用技!G12,$Z$6:$AD$57,3,FALSE())) +IF(応用技!E13="－","0",VLOOKUP(応用技!E13,$Z$6:$AD$57,3,FALSE())) +IF(応用技!F13="－","0",VLOOKUP(応用技!F13,$Z$6:$AD$57,3,FALSE())) +IF(応用技!G13="－","0",VLOOKUP(応用技!G13,$Z$6:$AD$57,3,FALSE())) -> 0 | E10: =IF(応用技!E12="－","0",VLOOKUP(応用技!E12,$Z$6:$AD$57,4,FALSE())) +IF(応用技!F12="－","0",VLOOKUP(応用技!F12,$Z$6:$AD$57,4,FALSE())) +IF(応用技!G12="－","0",VLOOKUP(応用技!G12,$Z$6:$AD$57,4,FALSE())) +IF(応用技!E13="－","0",VLOOKUP(応用技!E13,$Z$6:$AD$57,4,FALSE())) +IF(応用技!F13="－","0",VLOOKUP(応用技!F13,$Z$6:$AD$57,4,FALSE())) +IF(応用技!G13="－","0",VLOOKUP(応用技!G13,$Z$6:$AD$57,4,FALSE())) -> 0 | F10: =COUNTIFS(応用技!E12:G13,"強化*") -> 0 | G10: =COUNTIFS(応用技!E12:G13,"減衰*") -> 0 | J10: 行為発動 | K10: 1 | L10: 1 | N10: 強化【命】 | O10: 0 | P10: 1 | R10: 強化系 | V10: 行為発動 | W10: 1 | X10: 1 | Z10: 強化【命】 | AA10: 0 | AB10: 1 | AD10: 強化系 | AG10: 付加効果 | AH10: {=IF(クリーチャー!S12="－","0",VLOOKUP(クリーチャー!S12,$Z$6:$AD$57,2,FALSE()))+IF(クリーチャー!T12="－","0",VLOOKUP(クリーチャー!T12,Z6:$AD$57,2,FALSE()))+IF(クリーチャー!U12="－","0",VLOOKUP(クリーチャー!U12,$Z$6:$AD$57,2,FALSE()))+IF(クリーチャー!S13="－","0",VLOOKUP(クリーチャー!S13,$Z$6:$AD$57,2,FALSE()))+IF(クリーチャー!T13="－","0",VLOOKUP(クリーチャー!T13,$Z$6:$AD$57,2,FALSE()))+IF(クリーチャー!U13="－","0",VLOOKUP(クリーチャー!U13,$Z$6:$AD$57,2,FALSE()))+_xlfn.IFS(AK10>=2,1+2*(AK10-1),AK10=1,1,AK10=0,0)+_xlfn.IFS(AL10>=2,1+2*(AL10-1),AL10=1,1,AL10=0,0)} -> 0 | AI10: =IF(クリーチャー!S12="－","0",VLOOKUP(クリーチャー!S12,$Z$6:$AD$57,3,FALSE()))+IF(クリーチャー!T12="－","0",VLOOKUP(クリーチャー!T12,$Z$6:$AD$57,3,FALSE()))+IF(クリーチャー!U12="－","0",VLOOKUP(クリーチャー!U12,$Z$6:$AD$57,3,FALSE()))+IF(クリーチャー!S13="－","0",VLOOKUP(クリーチャー!S13,$Z$6:$AD$57,3,FALSE()))+IF(クリーチャー!T13="－","0",VLOOKUP(クリーチャー!T13,$Z$6:$AD$57,3,FALSE()))+IF(クリーチャー!U13="－","0",VLOOKUP(クリーチャー!U13,$Z$6:$AD$57,3,FALSE())) -> 0 | AJ10: =IF(クリーチャー!S12="－","0",VLOOKUP(クリーチャー!S12,$Z$6:$AD$57,4,FALSE())) +IF(クリーチャー!T12="－","0",VLOOKUP(クリーチャー!T12,$Z$6:$AD$57,4,FALSE())) +IF(クリーチャー!U12="－","0",VLOOKUP(クリーチャー!U12,$Z$6:$AD$57,4,FALSE())) +IF(クリーチャー!S13="－","0",VLOOKUP(クリーチャー!S13,$Z$6:$AD$57,4,FALSE())) +IF(クリーチャー!T13="－","0",VLOOKUP(クリーチャー!T13,$Z$6:$AD$57,4,FALSE())) +IF(クリーチャー!U13="－","0",VLOOKUP(クリーチャー!U13,$Z$6:$AD$57,4,FALSE())) -> 0 | AK10: =COUNTIFS(クリーチャー!S12:U13,"強化*") -> 0 | AL10: =COUNTIFS(クリーチャー!S12:U13,"減衰*") -> 0 | AN10: 付加効果 | AO10: {=IF(クリーチャー_2!S12="－","0",VLOOKUP(クリーチャー_2!S12,$Z$6:$AD$57,2,FALSE()))+IF(クリーチャー_2!T12="－","0",VLOOKUP(クリーチャー_2!T12,Z6:$AD$57,2,FALSE()))+IF(クリーチャー_2!U12="－","0",VLOOKUP(クリーチャー_2!U12,$Z$6:$AD$57,2,FALSE()))+IF(クリーチャー_2!S13="－","0",VLOOKUP(クリーチャー_2!S13,$Z$6:$AD$57,2,FALSE()))+IF(クリーチャー_2!T13="－","0",VLOOKUP(クリーチャー_2!T13,$Z$6:$AD$57,2,FALSE()))+IF(クリーチャー_2!U13="－","0",VLOOKUP(クリーチャー_2!U13,$Z$6:$AD$57,2,FALSE()))+_xlfn.IFS(AR10>=2,1+2*(AR10-1),AR10=1,1,AR10=0,0)+_xlfn.IFS(AS10>=2,1+2*(AS10-1),AS10=1,1,AS10=0,0)} -> 0 | AP10: =IF(クリーチャー_2!S12="－","0",VLOOKUP(クリーチャー_2!S12,$Z$6:$AD$57,3,FALSE()))+IF(クリーチャー_2!T12="－","0",VLOOKUP(クリーチャー_2!T12,$Z$6:$AD$57,3,FALSE()))+IF(クリーチャー_2!U12="－","0",VLOOKUP(クリーチャー_2!U12,$Z$6:$AD$57,3,FALSE()))+IF(クリーチャー_2!S13="－","0",VLOOKUP(クリーチャー_2!S13,$Z$6:$AD$57,3,FALSE()))+IF(クリーチャー_2!T13="－","0",VLOOKUP(クリーチャー_2!T13,$Z$6:$AD$57,3,FALSE()))+IF(クリーチャー_2!U13="－","0",VLOOKUP(クリーチャー_2!U13,$Z$6:$AD$57,3,FALSE())) -> 0 | AQ10: =IF(クリーチャー_2!S12="－","0",VLOOKUP(クリーチャー_2!S12,$Z$6:$AD$57,4,FALSE()))+IF(クリーチャー_2!T12="－","0",VLOOKUP(クリーチャー_2!T12,$Z$6:$AD$57,4,FALSE()))+IF(クリーチャー_2!U12="－","0",VLOOKUP(クリーチャー_2!U12,$Z$6:$AD$57,4,FALSE()))+IF(クリーチャー_2!S13="－","0",VLOOKUP(クリーチャー_2!S13,$Z$6:$AD$57,4,FALSE()))+IF(クリーチャー_2!T13="－","0",VLOOKUP(クリーチャー_2!T13,$Z$6:$AD$57,4,FALSE()))+IF(クリーチャー_2!U13="－","0",VLOOKUP(クリーチャー_2!U13,$Z$6:$AD$57,4,FALSE())) -> 0 | AR10: =COUNTIFS(クリーチャー_2!S12:U13,"強化*") -> 0 | AS10: =COUNTIFS(クリーチャー_2!S12:U13,"減衰*") -> 0 | AU10: 付加効果 | AV10: {=IF(クリーチャー_3!S12="－","0",VLOOKUP(クリーチャー_3!S12,$Z$6:$AD$57,2,FALSE()))+IF(クリーチャー_3!T12="－","0",VLOOKUP(クリーチャー_3!T12,Z6:$AD$57,2,FALSE()))+IF(クリーチャー_3!U12="－","0",VLOOKUP(クリーチャー_3!U12,$Z$6:$AD$57,2,FALSE()))+IF(クリーチャー_3!S13="－","0",VLOOKUP(クリーチャー_3!S13,$Z$6:$AD$57,2,FALSE()))+IF(クリーチャー_3!T13="－","0",VLOOKUP(クリーチャー_3!T13,$Z$6:$AD$57,2,FALSE()))+IF(クリーチャー_3!U13="－","0",VLOOKUP(クリーチャー_3!U13,$Z$6:$AD$57,2,FALSE()))+_xlfn.IFS(AY10>=2,1+2*(AY10-1),AY10=1,1,AY10=0,0)+_xlfn.IFS(AZ10>=2,1+2*(AZ10-1),AZ10=1,1,AZ10=0,0)} -> 0 | AW10: =IF(クリーチャー_3!S12="－","0",VLOOKUP(クリーチャー_3!S12,$Z$6:$AD$57,3,FALSE()))+IF(クリーチャー_3!T12="－","0",VLOOKUP(クリーチャー_3!T12,$Z$6:$AD$57,3,FALSE()))+IF(クリーチャー_3!U12="－","0",VLOOKUP(クリーチャー_3!U12,$Z$6:$AD$57,3,FALSE()))+IF(クリーチャー_3!S13="－","0",VLOOKUP(クリーチャー_3!S13,$Z$6:$AD$57,3,FALSE()))+IF(クリーチャー_3!T13="－","0",VLOOKUP(クリーチャー_3!T13,$Z$6:$AD$57,3,FALSE()))+IF(クリーチャー_3!U13="－","0",VLOOKUP(クリーチャー_3!U13,$Z$6:$AD$57,3,FALSE())) -> 0 | AX10: =IF(クリーチャー_3!S12="－","0",VLOOKUP(クリーチャー_3!S12,$Z$6:$AD$57,4,FALSE()))+IF(クリーチャー_3!T12="－","0",VLOOKUP(クリーチャー_3!T12,$Z$6:$AD$57,4,FALSE()))+IF(クリーチャー_3!U12="－","0",VLOOKUP(クリーチャー_3!U12,$Z$6:$AD$57,4,FALSE()))+IF(クリーチャー_3!S13="－","0",VLOOKUP(クリーチャー_3!S13,$Z$6:$AD$57,4,FALSE()))+IF(クリーチャー_3!T13="－","0",VLOOKUP(クリーチャー_3!T13,$Z$6:$AD$57,4,FALSE()))+IF(クリーチャー_3!U13="－","0",VLOOKUP(クリーチャー_3!U13,$Z$6:$AD$57,4,FALSE())) -> 0 | AY10: =COUNTIFS(クリーチャー_3!S12:U13,"強化*") -> 0 | AZ10: =COUNTIFS(クリーチャー_3!S12:U13,"減衰*") -> 0
B11: SE | C11: =IF(応用技!H12="－","0",VLOOKUP(応用技!H12,$V$15:$X$28,2,FALSE())) +IF(応用技!I12="－","0",VLOOKUP(応用技!I12,$V$15:$X$28,2,FALSE())) +IF(応用技!J12="－","0",VLOOKUP(応用技!J12,$V$15:$X$28,2,FALSE())) +IF(応用技!H13="－","0",VLOOKUP(応用技!H13,$V$15:$X$28,2,FALSE())) +IF(応用技!I13="－","0",VLOOKUP(応用技!I13,$V$15:$X$28,2,FALSE())) +IF(応用技!J13="－","0",VLOOKUP(応用技!J13,$V$15:$X$28,2,FALSE())) -> 0 | D11: =IF(応用技!H12="－","0",VLOOKUP(応用技!H12,$V$15:$X$28,3,FALSE())) +IF(応用技!I12="－","0",VLOOKUP(応用技!I12,$V$15:$X$28,3,FALSE())) +IF(応用技!J12="－","0",VLOOKUP(応用技!J12,$V$15:$X$28,3,FALSE())) +IF(応用技!H13="－","0",VLOOKUP(応用技!H13,$V$15:$X$28,3,FALSE())) +IF(応用技!I13="－","0",VLOOKUP(応用技!I13,$V$15:$X$28,3,FALSE())) +IF(応用技!J13="－","0",VLOOKUP(応用技!J13,$V$15:$X$28,3,FALSE())) -> 0 | J11: ＡＥ【重撃】 | K11: 1 | L11: 0 | N11: 強化【回】 | O11: 0 | P11: 1 | R11: 強化系 | V11: ＡＥ【重撃】 | W11: 1 | X11: 0 | Z11: 強化【回】 | AA11: 0 | AB11: 1 | AD11: 強化系 | AG11: SE | AH11: =IF(クリーチャー!V12="－","0",VLOOKUP(クリーチャー!V12,$V$15:$X$28,2,FALSE()))+IF(クリーチャー!W12="－","0",VLOOKUP(クリーチャー!W12,$V$15:$X$28,2,FALSE()))+IF(クリーチャー!X12="－","0",VLOOKUP(クリーチャー!X12,$V$15:$X$28,2,FALSE()))+IF(クリーチャー!V13="－","0",VLOOKUP(クリーチャー!V13,$V$15:$X$28,2,FALSE()))+IF(クリーチャー!W13="－","0",VLOOKUP(クリーチャー!W13,$V$15:$X$28,2,FALSE()))+IF(クリーチャー!X13="－","0",VLOOKUP(クリーチャー!X13,$V$15:$X$28,2,FALSE())) -> 0 | AI11: =IF(クリーチャー!V12="－","0",VLOOKUP(クリーチャー!V12,$V$15:$X$28,3,FALSE()))+IF(クリーチャー!W12="－","0",VLOOKUP(クリーチャー!W12,$V$15:$X$28,3,FALSE()))+IF(クリーチャー!X12="－","0",VLOOKUP(クリーチャー!X12,$V$15:$X$28,3,FALSE()))+IF(クリーチャー!V13="－","0",VLOOKUP(クリーチャー!V13,$V$15:$X$28,3,FALSE()))+IF(クリーチャー!W13="－","0",VLOOKUP(クリーチャー!W13,$V$15:$X$28,3,FALSE()))+IF(クリーチャー!X13="－","0",VLOOKUP(クリーチャー!X13,$V$15:$X$28,3,FALSE())) -> 0 | AN11: SE | AO11: =IF(クリーチャー_2!V12="－","0",VLOOKUP(クリーチャー_2!V12,$V$15:$X$28,2,FALSE()))+IF(クリーチャー_2!W12="－","0",VLOOKUP(クリーチャー_2!W12,$V$15:$X$28,2,FALSE()))+IF(クリーチャー_2!X12="－","0",VLOOKUP(クリーチャー_2!X12,$V$15:$X$28,2,FALSE()))+IF(クリーチャー_2!V13="－","0",VLOOKUP(クリーチャー_2!V13,$V$15:$X$28,2,FALSE()))+IF(クリーチャー_2!W13="－","0",VLOOKUP(クリーチャー_2!W13,$V$15:$X$28,2,FALSE()))+IF(クリーチャー_2!X13="－","0",VLOOKUP(クリーチャー_2!X13,$V$15:$X$28,2,FALSE())) -> 0 | AP11: =IF(クリーチャー_2!V12="－","0",VLOOKUP(クリーチャー_2!V12,$V$15:$X$28,3,FALSE()))+IF(クリーチャー_2!W12="－","0",VLOOKUP(クリーチャー_2!W12,$V$15:$X$28,3,FALSE()))+IF(クリーチャー_2!X12="－","0",VLOOKUP(クリーチャー_2!X12,$V$15:$X$28,3,FALSE()))+IF(クリーチャー_2!V13="－","0",VLOOKUP(クリーチャー_2!V13,$V$15:$X$28,3,FALSE()))+IF(クリーチャー_2!W13="－","0",VLOOKUP(クリーチャー_2!W13,$V$15:$X$28,3,FALSE()))+IF(クリーチャー_2!X13="－","0",VLOOKUP(クリーチャー_2!X13,$V$15:$X$28,3,FALSE())) -> 0 | AU11: SE | AV11: =IF(クリーチャー_3!V12="－","0",VLOOKUP(クリーチャー_3!V12,$V$15:$X$28,2,FALSE()))+IF(クリーチャー_3!W12="－","0",VLOOKUP(クリーチャー_3!W12,$V$15:$X$28,2,FALSE()))+IF(クリーチャー_3!X12="－","0",VLOOKUP(クリーチャー_3!X12,$V$15:$X$28,2,FALSE()))+IF(クリーチャー_3!V13="－","0",VLOOKUP(クリーチャー_3!V13,$V$15:$X$28,2,FALSE()))+IF(クリーチャー_3!W13="－","0",VLOOKUP(クリーチャー_3!W13,$V$15:$X$28,2,FALSE()))+IF(クリーチャー_3!X13="－","0",VLOOKUP(クリーチャー_3!X13,$V$15:$X$28,2,FALSE())) -> 0 | AW11: =IF(クリーチャー_3!V12="－","0",VLOOKUP(クリーチャー_3!V12,$V$15:$X$28,3,FALSE()))+IF(クリーチャー_3!W12="－","0",VLOOKUP(クリーチャー_3!W12,$V$15:$X$28,3,FALSE()))+IF(クリーチャー_3!X12="－","0",VLOOKUP(クリーチャー_3!X12,$V$15:$X$28,3,FALSE()))+IF(クリーチャー_3!V13="－","0",VLOOKUP(クリーチャー_3!V13,$V$15:$X$28,3,FALSE()))+IF(クリーチャー_3!W13="－","0",VLOOKUP(クリーチャー_3!W13,$V$15:$X$28,3,FALSE()))+IF(クリーチャー_3!X13="－","0",VLOOKUP(クリーチャー_3!X13,$V$15:$X$28,3,FALSE())) -> 0
B12: 合計 | C12: {=_xlfn.IFS(COUNTIF(応用技!E12:G13,"創造")>=1, SUM(C9:C11)+1&"～"&SUM(C9:C11)+10, COUNTIF(応用技!E12:G13,"限定*")>=1,"※", COUNTIF(応用技!E12:G13,"影響無効")>=1,"※",TRUE(),SUM(C9:C11))} -> 0 | D12: =SUM(D9:D11) -> 0 | E12: =SUM(E9:E11) -> 0 | N12: 強化【技】 | O12: 0 | P12: 1 | R12: 強化系 | Z12: 強化【技】 | AA12: 0 | AB12: 1 | AD12: 強化系 | AG12: 合計 | AH12: {=_xlfn.IFS(COUNTIF(クリーチャー!S12:U13,"創造")>=1,SUM(AH9:AH11)+1&"～"&SUM(AH9:AH11)+10,COUNTIF(クリーチャー!S12:U13,"限定*")>=1,"※",COUNTIF(クリーチャー!S12:U13,"影響無効")>=1,"※",TRUE(),SUM(AH9:AH11))} -> 0 | AI12: =SUM(AI9:AI11) -> 0 | AJ12: =SUM(AJ9:AJ11) -> 0 | AN12: 合計 | AO12: {=_xlfn.IFS(COUNTIF(クリーチャー_2!S12:U13,"創造")>=1,SUM(AO9:AO11)+1&"～"&SUM(AO9:AO11)+10,COUNTIF(クリーチャー_2!S12:U13,"限定*")>=1,"※",COUNTIF(クリーチャー_2!S12:U13,"影響無効")>=1,"※",TRUE(),SUM(AO9:AO11))} -> 0 | AP12: =SUM(AP9:AP11) -> 0 | AQ12: =SUM(AQ9:AQ11) -> 0 | AU12: 合計 | AV12: {=_xlfn.IFS(COUNTIF(クリーチャー_3!S12:U13,"創造")>=1,SUM(AV9:AV11)+1&"～"&SUM(AV9:AV11)+10,COUNTIF(クリーチャー_3!S12:U13,"限定*")>=1,"※",COUNTIF(クリーチャー_3!S12:U13,"影響無効")>=1,"※",TRUE(),SUM(AV9:AV11))} -> 0 | AW12: =SUM(AW9:AW11) -> 0 | AX12: =SUM(AX9:AX11) -> 0
J13: SE | N13: 強化【解】 | O13: 0 | P13: 1 | R13: 強化系 | V13: SE | Z13: 強化【解】 | AA13: 0 | AB13: 1 | AD13: 強化系
B14: 技2 | C14: 消費 | D14: スペック | E14: 圧迫 | F14: 強化変数 | G14: 減衰変数 | J14: 名称 | K14: 消費 | L14: スペック | N14: 減衰【行】 | O14: 0 | P14: 1 | R14: 減衰系 | V14: 名称 | W14: 消費 | X14: スペック | Z14: 減衰【行】 | AA14: 0 | AB14: 1 | AD14: 減衰系 | AG14: 技2 | AH14: 消費 | AI14: スペック | AJ14: 圧迫 | AK14: 強化変数 | AL14: 減衰変数 | AN14: 技2 | AO14: 消費 | AP14: スペック | AQ14: 圧迫 | AR14: 強化変数 | AS14: 減衰変数 | AU14: 技2 | AV14: 消費 | AW14: スペック | AX14: 圧迫 | AY14: 強化変数 | AZ14: 減衰変数
B15: 発動系統 | C15: =IF(応用技!B23="－","0",VLOOKUP(応用技!B23,計算用!$J$6:$L$11,2,FALSE()))+IF(応用技!C23="－","0",VLOOKUP(応用技!C23,計算用!$J$6:$L$11,2,FALSE()))+IF(応用技!D23="－","0",VLOOKUP(応用技!D23,計算用!$J$6:$L$11,2,FALSE()))+COUNTIF(応用技!B23:D23,"防御発動")^2 -> 0 | D15: =IF(応用技!B23="－","0",VLOOKUP(応用技!B23,$J$6:$L$11,3,FALSE()))+IF(応用技!C23="－","0",VLOOKUP(応用技!C23,$J$6:$L$11,3,FALSE()))+IF(応用技!D23="－","0",VLOOKUP(応用技!D23,$J$6:$L$11,3,FALSE())) -> 0 | J15: ペネトレイション | K15: 3 | L15: 1 | N15: 減衰【攻】 | O15: 0 | P15: 1 | R15: 減衰系 | V15: ペネトレイション | W15: 3 | X15: 1 | Z15: 減衰【攻】 | AA15: 0 | AB15: 1 | AD15: 減衰系 | AG15: 発動系統 | AH15: =IF(クリーチャー!P23="－","0",VLOOKUP(クリーチャー!P23,計算用!$J$6:$L$11,2,FALSE()))+IF(クリーチャー!Q23="－","0",VLOOKUP(クリーチャー!Q23,計算用!$J$6:$L$11,2,FALSE()))+IF(クリーチャー!R23="－","0",VLOOKUP(クリーチャー!R23,計算用!$J$6:$L$11,2,FALSE()))+COUNTIF(クリーチャー!P23:R23,"防御発動")^2 -> 0 | AI15: =IF(クリーチャー!P23="－","0",VLOOKUP(クリーチャー!P23,$J$6:$L$11,3,FALSE()))+IF(クリーチャー!Q23="－","0",VLOOKUP(クリーチャー!Q23,$J$6:$L$11,3,FALSE()))+IF(クリーチャー!R23="－","0",VLOOKUP(クリーチャー!R23,$J$6:$L$11,3,FALSE())) -> 0 | AN15: 発動系統 | AO15: =IF(クリーチャー_2!P23="－","0",VLOOKUP(クリーチャー_2!P23,計算用!$J$6:$L$11,2,FALSE()))+IF(クリーチャー_2!Q23="－","0",VLOOKUP(クリーチャー_2!Q23,計算用!$J$6:$L$11,2,FALSE()))+IF(クリーチャー_2!R23="－","0",VLOOKUP(クリーチャー_2!R23,計算用!$J$6:$L$11,2,FALSE()))+COUNTIF(クリーチャー_2!P23:R23,"防御発動")^2 -> 0 | AP15: =IF(クリーチャー_2!P23="－","0",VLOOKUP(クリーチャー_2!P23,$J$6:$L$11,3,FALSE()))+IF(クリーチャー_2!Q23="－","0",VLOOKUP(クリーチャー_2!Q23,$J$6:$L$11,3,FALSE()))+IF(クリーチャー_2!R23="－","0",VLOOKUP(クリーチャー_2!R23,$J$6:$L$11,3,FALSE())) -> 0 | AU15: 発動系統 | AV15: =IF(クリーチャー_3!P23="－","0",VLOOKUP(クリーチャー_3!P23,計算用!$J$6:$L$11,2,FALSE()))+IF(クリーチャー_3!Q23="－","0",VLOOKUP(クリーチャー_3!Q23,計算用!$J$6:$L$11,2,FALSE()))+IF(クリーチャー_3!R23="－","0",VLOOKUP(クリーチャー_3!R23,計算用!$J$6:$L$11,2,FALSE()))+COUNTIF(クリーチャー_3!P23:R23,"防御発動")^2 -> 0 | AW15: =IF(クリーチャー_3!P23="－","0",VLOOKUP(クリーチャー_3!P23,$J$6:$L$11,3,FALSE()))+IF(クリーチャー_3!Q23="－","0",VLOOKUP(クリーチャー_3!Q23,$J$6:$L$11,3,FALSE()))+IF(クリーチャー_3!R23="－","0",VLOOKUP(クリーチャー_3!R23,$J$6:$L$11,3,FALSE())) -> 0
B16: 付加効果 | C16: {=IF(応用技!E23="－","0",VLOOKUP(応用技!E23,$N$6:$R$49,2,FALSE()))+IF(応用技!F23="－","0",VLOOKUP(応用技!F23,N6:$R$49,2,FALSE()))+IF(応用技!G23="－","0",VLOOKUP(応用技!G23,$N$6:$R$49,2,FALSE()))+IF(応用技!E24="－","0",VLOOKUP(応用技!E24,$N$6:$R$49,2,FALSE()))+IF(応用技!F24="－","0",VLOOKUP(応用技!F24,$N$6:$R$49,2,FALSE()))+IF(応用技!G24="－","0",VLOOKUP(応用技!G24,$N$6:$R$49,2,FALSE()))+_xlfn.IFS(F16>=2,1+2*(F16-1),F16=1,1,F16=0,0)+_xlfn.IFS(G16>=2,1+2*(G16-1),G16=1,1,G16=0,0)} -> 0 | D16: =IF(応用技!E23="－","0",VLOOKUP(応用技!E23,$N$6:$R$49,3,FALSE()))+IF(応用技!F23="－","0",VLOOKUP(応用技!F23,$N$6:$R$49,3,FALSE()))+IF(応用技!G23="－","0",VLOOKUP(応用技!G23,$N$6:$R$49,3,FALSE()))+IF(応用技!E24="－","0",VLOOKUP(応用技!E24,$N$6:$R$49,3,FALSE()))+IF(応用技!F24="－","0",VLOOKUP(応用技!F24,$N$6:$R$49,3,FALSE()))+IF(応用技!G24="－","0",VLOOKUP(応用技!G24,$N$6:$R$49,3,FALSE())) -> 0 | E16: =IF(応用技!E23="－","0",VLOOKUP(応用技!E23,$N$6:$R$49,4,FALSE()))+IF(応用技!F23="－","0",VLOOKUP(応用技!F23,$N$6:$R$49,4,FALSE()))+IF(応用技!G23="－","0",VLOOKUP(応用技!G23,$N$6:$R$49,4,FALSE()))+IF(応用技!E24="－","0",VLOOKUP(応用技!E24,$N$6:$R$49,4,FALSE()))+IF(応用技!F24="－","0",VLOOKUP(応用技!F24,$N$6:$R$49,4,FALSE()))+IF(応用技!G24="－","0",VLOOKUP(応用技!G24,$N$6:$R$49,4,FALSE())) -> 0 | F16: =COUNTIFS(応用技!E23:G24,"強化*") -> 0 | G16: =COUNTIFS(応用技!E23:G24,"減衰*") -> 0 | J16: オールレンジ | K16: 3 | L16: 1 | N16: 減衰【防】 | O16: 0 | P16: 1 | R16: 減衰系 | V16: オールレンジ | W16: 3 | X16: 1 | Z16: 減衰【防】 | AA16: 0 | AB16: 1 | AD16: 減衰系 | AG16: 付加効果 | AH16: {=IF(クリーチャー!S23="－","0",VLOOKUP(クリーチャー!S23,$N$6:$R$49,2,FALSE()))+IF(クリーチャー!T23="－","0",VLOOKUP(クリーチャー!T23,N6:$R$49,2,FALSE()))+IF(クリーチャー!U23="－","0",VLOOKUP(クリーチャー!U23,$N$6:$R$49,2,FALSE()))+IF(クリーチャー!S24="－","0",VLOOKUP(クリーチャー!S24,$N$6:$R$49,2,FALSE()))+IF(クリーチャー!T24="－","0",VLOOKUP(クリーチャー!T24,$N$6:$R$49,2,FALSE()))+IF(クリーチャー!U24="－","0",VLOOKUP(クリーチャー!U24,$N$6:$R$49,2,FALSE()))+_xlfn.IFS(AK16>=2,1+2*(AK16-1),AK16=1,1,AK16=0,0)+_xlfn.IFS(AL16>=2,1+2*(AL16-1),AL16=1,1,AL16=0,0)} -> 0 | AI16: =IF(クリーチャー!S23="－","0",VLOOKUP(クリーチャー!S23,$N$6:$R$49,3,FALSE()))+IF(クリーチャー!T23="－","0",VLOOKUP(クリーチャー!T23,$N$6:$R$49,3,FALSE()))+IF(クリーチャー!U23="－","0",VLOOKUP(クリーチャー!U23,$N$6:$R$49,3,FALSE()))+IF(クリーチャー!S24="－","0",VLOOKUP(クリーチャー!S24,$N$6:$R$49,3,FALSE()))+IF(クリーチャー!T24="－","0",VLOOKUP(クリーチャー!T24,$N$6:$R$49,3,FALSE()))+IF(クリーチャー!U24="－","0",VLOOKUP(クリーチャー!U24,$N$6:$R$49,3,FALSE())) -> 0 | AJ16: =IF(クリーチャー!S23="－","0",VLOOKUP(クリーチャー!S23,$N$6:$R$49,4,FALSE()))+IF(クリーチャー!T23="－","0",VLOOKUP(クリーチャー!T23,$N$6:$R$49,4,FALSE()))+IF(クリーチャー!U23="－","0",VLOOKUP(クリーチャー!U23,$N$6:$R$49,4,FALSE()))+IF(クリーチャー!S24="－","0",VLOOKUP(クリーチャー!S24,$N$6:$R$49,4,FALSE()))+IF(クリーチャー!T24="－","0",VLOOKUP(クリーチャー!T24,$N$6:$R$49,4,FALSE()))+IF(クリーチャー!U24="－","0",VLOOKUP(クリーチャー!U24,$N$6:$R$49,4,FALSE())) -> 0 | AK16: =COUNTIFS(クリーチャー!S23:U24,"強化*") -> 0 | AL16: =COUNTIFS(クリーチャー!S23:U24,"減衰*") -> 0 | AN16: 付加効果 | AO16: {=IF(クリーチャー_2!S23="－","0",VLOOKUP(クリーチャー_2!S23,$N$6:$R$49,2,FALSE()))+IF(クリーチャー_2!T23="－","0",VLOOKUP(クリーチャー_2!T23,$N$6:$R$49,2,FALSE()))+IF(クリーチャー_2!U23="－","0",VLOOKUP(クリーチャー_2!U23,$N$6:$R$49,2,FALSE()))+IF(クリーチャー_2!S24="－","0",VLOOKUP(クリーチャー_2!S24,$N$6:$R$49,2,FALSE()))+IF(クリーチャー_2!T24="－","0",VLOOKUP(クリーチャー_2!T24,$N$6:$R$49,2,FALSE()))+IF(クリーチャー_2!U24="－","0",VLOOKUP(クリーチャー_2!U24,$N$6:$R$49,2,FALSE()))+_xlfn.IFS(AR16>=2,1+2*(AR16-1),AR16=1,1,AR16=0,0)+_xlfn.IFS(AS16>=2,1+2*(AS16-1),AS16=1,1,AS16=0,0)} -> 0 | AP16: =IF(クリーチャー_2!S23="－","0",VLOOKUP(クリーチャー_2!S23,$N$6:$R$49,3,FALSE()))+IF(クリーチャー_2!T23="－","0",VLOOKUP(クリーチャー_2!T23,$N$6:$R$49,3,FALSE()))+IF(クリーチャー_2!U23="－","0",VLOOKUP(クリーチャー_2!U23,$N$6:$R$49,3,FALSE()))+IF(クリーチャー_2!S24="－","0",VLOOKUP(クリーチャー_2!S24,$N$6:$R$49,3,FALSE()))+IF(クリーチャー_2!T24="－","0",VLOOKUP(クリーチャー_2!T24,$N$6:$R$49,3,FALSE()))+IF(クリーチャー_2!U24="－","0",VLOOKUP(クリーチャー_2!U24,$N$6:$R$49,3,FALSE())) -> 0 | AQ16: =IF(クリーチャー_2!S23="－","0",VLOOKUP(クリーチャー_2!S23,$N$6:$R$49,4,FALSE()))+IF(クリーチャー_2!T23="－","0",VLOOKUP(クリーチャー_2!T23,$N$6:$R$49,4,FALSE()))+IF(クリーチャー_2!U23="－","0",VLOOKUP(クリーチャー_2!U23,$N$6:$R$49,4,FALSE()))+IF(クリーチャー_2!S24="－","0",VLOOKUP(クリーチャー_2!S24,$N$6:$R$49,4,FALSE()))+IF(クリーチャー_2!T24="－","0",VLOOKUP(クリーチャー_2!T24,$N$6:$R$49,4,FALSE()))+IF(クリーチャー_2!U24="－","0",VLOOKUP(クリーチャー_2!U24,$N$6:$R$49,4,FALSE())) -> 0 | AR16: =COUNTIFS(クリーチャー_2!S23:U24,"強化*") -> 0 | AS16: =COUNTIFS(クリーチャー_2!S23:U24,"減衰*") -> 0 | AU16: 付加効果 | AV16: {=IF(クリーチャー_3!S23="－","0",VLOOKUP(クリーチャー_3!S23,$N$6:$R$49,2,FALSE()))+IF(クリーチャー_3!T23="－","0",VLOOKUP(クリーチャー_3!T23,N6:$R$49,2,FALSE()))+IF(クリーチャー_3!U23="－","0",VLOOKUP(クリーチャー_3!U23,$N$6:$R$49,2,FALSE()))+IF(クリーチャー_3!S24="－","0",VLOOKUP(クリーチャー_3!S24,$N$6:$R$49,2,FALSE()))+IF(クリーチャー_3!T24="－","0",VLOOKUP(クリーチャー_3!T24,$N$6:$R$49,2,FALSE()))+IF(クリーチャー_3!U24="－","0",VLOOKUP(クリーチャー_3!U24,$N$6:$R$49,2,FALSE()))+_xlfn.IFS(AY16>=2,1+2*(AY16-1),AY16=1,1,AY16=0,0)+_xlfn.IFS(AZ16>=2,1+2*(AZ16-1),AZ16=1,1,AZ16=0,0)} -> 0 | AW16: =IF(クリーチャー_3!S23="－","0",VLOOKUP(クリーチャー_3!S23,$N$6:$R$49,3,FALSE()))+IF(クリーチャー_3!T23="－","0",VLOOKUP(クリーチャー_3!T23,$N$6:$R$49,3,FALSE()))+IF(クリーチャー_3!U23="－","0",VLOOKUP(クリーチャー_3!U23,$N$6:$R$49,3,FALSE()))+IF(クリーチャー_3!S24="－","0",VLOOKUP(クリーチャー_3!S24,$N$6:$R$49,3,FALSE()))+IF(クリーチャー_3!T24="－","0",VLOOKUP(クリーチャー_3!T24,$N$6:$R$49,3,FALSE()))+IF(クリーチャー_3!U24="－","0",VLOOKUP(クリーチャー_3!U24,$N$6:$R$49,3,FALSE())) -> 0 | AX16: =IF(クリーチャー_3!S23="－","0",VLOOKUP(クリーチャー_3!S23,$N$6:$R$49,4,FALSE()))+IF(クリーチャー_3!T23="－","0",VLOOKUP(クリーチャー_3!T23,$N$6:$R$49,4,FALSE()))+IF(クリーチャー_3!U23="－","0",VLOOKUP(クリーチャー_3!U23,$N$6:$R$49,4,FALSE()))+IF(クリーチャー_3!S24="－","0",VLOOKUP(クリーチャー_3!S24,$N$6:$R$49,4,FALSE()))+IF(クリーチャー_3!T24="－","0",VLOOKUP(クリーチャー_3!T24,$N$6:$R$49,4,FALSE()))+IF(クリーチャー_3!U24="－","0",VLOOKUP(クリーチャー_3!U24,$N$6:$R$49,4,FALSE())) -> 0 | AY16: =COUNTIFS(クリーチャー_3!S23:U24,"強化*") -> 0 | AZ16: =COUNTIFS(クリーチャー_3!S23:U24,"減衰*") -> 0
B17: SE | C17: =IF(応用技!H23="－","0",VLOOKUP(応用技!H23,$J$15:$L$27,2,FALSE()))+IF(応用技!I23="－","0",VLOOKUP(応用技!I23,$J$15:$L$27,2,FALSE()))+IF(応用技!J23="－","0",VLOOKUP(応用技!J23,$J$15:$L$27,2,FALSE()))+IF(応用技!H24="－","0",VLOOKUP(応用技!H24,$J$15:$L$27,2,FALSE()))+IF(応用技!I24="－","0",VLOOKUP(応用技!I24,$J$15:$L$27,2,FALSE()))+IF(応用技!J24="－","0",VLOOKUP(応用技!J24,$J$15:$L$27,2,FALSE())) -> 0 | D17: =IF(応用技!H23="－","0",VLOOKUP(応用技!H23,$J$15:$L$27,3,FALSE()))+IF(応用技!I23="－","0",VLOOKUP(応用技!I23,$J$15:$L$27,3,FALSE()))+IF(応用技!J23="－","0",VLOOKUP(応用技!J23,$J$15:$L$27,3,FALSE()))+IF(応用技!H24="－","0",VLOOKUP(応用技!H24,$J$15:$L$27,3,FALSE()))+IF(応用技!I24="－","0",VLOOKUP(応用技!I24,$J$15:$L$27,3,FALSE()))+IF(応用技!J24="－","0",VLOOKUP(応用技!J24,$J$15:$L$27,3,FALSE())) -> 0 | J17: テリトリー | K17: 3 | L17: 1 | N17: 減衰【抵】 | O17: 0 | P17: 1 | R17: 減衰系 | V17: テリトリー | W17: 3 | X17: 1 | Z17: 減衰【抵】 | AA17: 0 | AB17: 1 | AD17: 減衰系 | AG17: SE | AH17: =IF(クリーチャー!V23="－","0",VLOOKUP(クリーチャー!V23,$J$15:$L$27,2,FALSE()))+IF(クリーチャー!W23="－","0",VLOOKUP(クリーチャー!W23,$J$15:$L$27,2,FALSE()))+IF(クリーチャー!X23="－","0",VLOOKUP(クリーチャー!X23,$J$15:$L$27,2,FALSE()))+IF(クリーチャー!V24="－","0",VLOOKUP(クリーチャー!V24,$J$15:$L$27,2,FALSE()))+IF(クリーチャー!W24="－","0",VLOOKUP(クリーチャー!W24,$J$15:$L$27,2,FALSE()))+IF(クリーチャー!X24="－","0",VLOOKUP(クリーチャー!X24,$J$15:$L$27,2,FALSE())) -> 0 | AI17: =IF(クリーチャー!V23="－","0",VLOOKUP(クリーチャー!V23,$J$15:$L$27,3,FALSE()))+IF(クリーチャー!W23="－","0",VLOOKUP(クリーチャー!W23,$J$15:$L$27,3,FALSE()))+IF(クリーチャー!X23="－","0",VLOOKUP(クリーチャー!X23,$J$15:$L$27,3,FALSE()))+IF(クリーチャー!V24="－","0",VLOOKUP(クリーチャー!V24,$J$15:$L$27,3,FALSE()))+IF(クリーチャー!W24="－","0",VLOOKUP(クリーチャー!W24,$J$15:$L$27,3,FALSE()))+IF(クリーチャー!X24="－","0",VLOOKUP(クリーチャー!X24,$J$15:$L$27,3,FALSE())) -> 0 | AN17: SE | AO17: =IF(クリーチャー_2!V23="－","0",VLOOKUP(クリーチャー_2!V23,$J$15:$L$27,2,FALSE()))+IF(クリーチャー_2!W23="－","0",VLOOKUP(クリーチャー_2!W23,$J$15:$L$27,2,FALSE()))+IF(クリーチャー_2!X23="－","0",VLOOKUP(クリーチャー_2!X23,$J$15:$L$27,2,FALSE()))+IF(クリーチャー_2!V24="－","0",VLOOKUP(クリーチャー_2!V24,$J$15:$L$27,2,FALSE()))+IF(クリーチャー_2!W24="－","0",VLOOKUP(クリーチャー_2!W24,$J$15:$L$27,2,FALSE()))+IF(クリーチャー_2!X24="－","0",VLOOKUP(クリーチャー_2!X24,$J$15:$L$27,2,FALSE())) -> 0 | AP17: =IF(クリーチャー_2!V23="－","0",VLOOKUP(クリーチャー_2!V23,$J$15:$L$27,3,FALSE()))+IF(クリーチャー_2!W23="－","0",VLOOKUP(クリーチャー_2!W23,$J$15:$L$27,3,FALSE()))+IF(クリーチャー_2!X23="－","0",VLOOKUP(クリーチャー_2!X23,$J$15:$L$27,3,FALSE()))+IF(クリーチャー_2!V24="－","0",VLOOKUP(クリーチャー_2!V24,$J$15:$L$27,3,FALSE()))+IF(クリーチャー_2!W24="－","0",VLOOKUP(クリーチャー_2!W24,$J$15:$L$27,3,FALSE()))+IF(クリーチャー_2!X24="－","0",VLOOKUP(クリーチャー_2!X24,$J$15:$L$27,3,FALSE())) -> 0 | AU17: SE | AV17: =IF(クリーチャー_3!V23="－","0",VLOOKUP(クリーチャー_3!V23,$J$15:$L$27,2,FALSE()))+IF(クリーチャー_3!W23="－","0",VLOOKUP(クリーチャー_3!W23,$J$15:$L$27,2,FALSE()))+IF(クリーチャー_3!X23="－","0",VLOOKUP(クリーチャー_3!X23,$J$15:$L$27,2,FALSE()))+IF(クリーチャー_3!V24="－","0",VLOOKUP(クリーチャー_3!V24,$J$15:$L$27,2,FALSE()))+IF(クリーチャー_3!W24="－","0",VLOOKUP(クリーチャー_3!W24,$J$15:$L$27,2,FALSE()))+IF(クリーチャー_3!X24="－","0",VLOOKUP(クリーチャー_3!X24,$J$15:$L$27,2,FALSE())) -> 0 | AW17: =IF(クリーチャー_3!V23="－","0",VLOOKUP(クリーチャー_3!V23,$J$15:$L$27,3,FALSE()))+IF(クリーチャー_3!W23="－","0",VLOOKUP(クリーチャー_3!W23,$J$15:$L$27,3,FALSE()))+IF(クリーチャー_3!X23="－","0",VLOOKUP(クリーチャー_3!X23,$J$15:$L$27,3,FALSE()))+IF(クリーチャー_3!V24="－","0",VLOOKUP(クリーチャー_3!V24,$J$15:$L$27,3,FALSE()))+IF(クリーチャー_3!W24="－","0",VLOOKUP(クリーチャー_3!W24,$J$15:$L$27,3,FALSE()))+IF(クリーチャー_3!X24="－","0",VLOOKUP(クリーチャー_3!X24,$J$15:$L$27,3,FALSE())) -> 0
B18: 合計 | C18: {=_xlfn.IFS(COUNTIF(応用技!E23:G24,"創造")>=1,SUM(C15:C17)+1&"～"&SUM(C15:C17)+10,COUNTIF(応用技!E23:G24,"限定*")>=1,"※",COUNTIF(応用技!E23:G24,"影響無効")>=1,"※",TRUE(),SUM(C15:C17))} -> 0 | D18: =SUM(D15:D17) -> 0 | E18: =SUM(E15:E17) -> 0 | J18: コンティニュー | K18: 2 | L18: 1 | N18: 減衰【命】 | O18: 0 | P18: 1 | R18: 減衰系 | V18: コンティニュー | W18: 2 | X18: 1 | Z18: 減衰【命】 | AA18: 0 | AB18: 1 | AD18: 減衰系 | AG18: 合計 | AH18: {=_xlfn.IFS(COUNTIF(クリーチャー!S23:U24,"創造")>=1,SUM(AH15:AH17)+1&"～"&SUM(AH15:AH17)+10,COUNTIF(クリーチャー!S23:U24,"限定*")>=1,"※",COUNTIF(クリーチャー!S23:U24,"影響無効")>=1,"※",TRUE(),SUM(AH15:AH17))} -> 0 | AI18: =SUM(AI15:AI17) -> 0 | AJ18: =SUM(AJ15:AJ17) -> 0 | AN18: 合計 | AO18: {=_xlfn.IFS(COUNTIF(クリーチャー_2!S23:U24,"創造")>=1,SUM(AO15:AO17)+1&"～"&SUM(AO15:AO17)+10,COUNTIF(クリーチャー_2!S23:U24,"限定*")>=1,"※",COUNTIF(クリーチャー_2!S23:U24,"影響無効")>=1,"※",TRUE(),SUM(AO15:AO17))} -> 0 | AP18: =SUM(AP15:AP17) -> 0 | AQ18: =SUM(AQ15:AQ17) -> 0 | AU18: 合計 | AV18: {=_xlfn.IFS(COUNTIF(クリーチャー_3!S23:U24,"創造")>=1,SUM(AV15:AV17)+1&"～"&SUM(AV15:AV17)+10,COUNTIF(クリーチャー_3!S23:U24,"限定*")>=1,"※",COUNTIF(クリーチャー_3!S23:U24,"影響無効")>=1,"※",TRUE(),SUM(AV15:AV17))} -> 0 | AW18: =SUM(AW15:AW17) -> 0 | AX18: =SUM(AX15:AX17) -> 0
J19: ドレイン | K19: 2 | L19: 1 | N19: 減衰【回】 | O19: 0 | P19: 1 | R19: 減衰系 | V19: ドレイン | W19: 2 | X19: 1 | Z19: 減衰【回】 | AA19: 0 | AB19: 1 | AD19: 減衰系
